Workbook

Sheet README
A1: monday.com Operating Plan, Q3 2026-Q4 2027 (Phase 3b) - DRAFT FOR OWNER REVIEW, NOT FROZEN
A3: Management question | B3: If growth decelerates faster than guided after the July 2026 restructuring, how should management adjust hiring and operating spend to protect margin and cash generation without damaging long-term growth?
A4: Information cutoff | B4: October 28, 2026. Inputs: monday_sourcebook.xlsx (Row IDs), monday_analysis.xlsx (cells), locked Q3 call monday_q3_call.xlsx (release q3-2026-call-locked; cells), monday_driver_audit.xlsx (evidence). None is modified.
A5: Labels | B5: Sourced = blue copy with Row ID/reference; Derived = black formula; Assumed = orange on light-orange fill (Assumptions sheet and Management_Response elasticities). Column B of every model table states the label of the row.
A6: Base is not guidance | B6: Base is a BEAT-ADJUSTED central estimate, not guidance: FY2026 Base revenue and non-GAAP operating income sit above the top of the guided ranges (see Scenarios, As guided). Adjusted FCF is held at the guide midpoint on the guide basis.
A7: Cash questions (resolved) | B7: Adjusted FCF as defined by the company has no severance add-back; the FY2026 FCF outlook excludes restructuring (6-K Jul 22, 2026). The plan deducts severance once, separately (no double count), and shows reported-basis FCF as a memo. The H1 2026 cash bridge (Cash_Bridge) explains the earlier -$67M: mostly a transfer into marketable securities. Ending cash is labeled BEFORE UNMODELED ITEMS (new buybacks, M&A beyond run-rate, FX) and is not a headline figure.
A8: Cases | B8: Base = central estimate (Q3 2026 = locked call MID). Downside = faster deceleration (2.6 vs 1.3 pp/yr) with opex DOLLARS held at Base before any response. Sensitivity = Base with Q3 2026 at the locked call LOW. Management response is modeled on the Downside.
A9: Not modeled as separate drivers | B9: Restructuring SAVINGS: no savings amount, exit timing or headcount base is disclosed, so savings are expressed only through the opex-ratio assumptions (P4-P6) and the locked Q3 call. INTEREST INCOME: financial income, net ($17.3M in H1 2026 per the interim MD&A) is received through operating cash flow, so it is already inside adjusted FCF and the guide-anchored conversion (P7); it is not added again.
A10: Headcount | B10: No implied-headcount memo (ruling 4). Hiring decisions are stated in dollars. Fact: 3,155 employees at Dec 31, 2025 (AN-0051) and a ~20% workforce reduction announced July 22, 2026; no quarterly path is modeled.
A11: Status | B11: DRAFT. Not frozen, tagged or released. Review gates are reported in Checks.
A12: Sheets | B12: README, Definitions, Historical_Drivers, Cash_Bridge, Assumptions, Revenue_Build, Opex, PnL, Cash_FCF, Scenarios, Management_Response, Recommendation, Backtest, Trigger_History, Method_Changes, Checks, Scorecard.

Sheet Definitions
A1: Definitions (company definitions per source-book Definitions sheet; plan conventions)
A3: Non-GAAP operating income | B3: GAAP operating income excluding SBC, restructuring (from Q2 2026) and the 2024 foundation contribution (company definition). Plan: gross profit (non-GAAP) - R&D - S&M - G&A (non-GAAP).
A4: Adjusted FCF | B4: Company definition (verbatim in Cash_Bridge): OCF - PP&E - capitalized software + HQ build-out add-back; no add-back for restructuring or severance. Guide basis = excluding restructuring (6-K Jul 22, 2026). Reported basis = guide basis less severance paid. Plan: Q3/Q4 2026 tied to the FY2026 guide (low confidence); 2027 = op. income x annual conversion (P7).
A5: Breakeven revenue loss | B5: FY2027 revenue loss at which the gross profit lost (loss x Downside gross margin) equals the operating income a lever saves. One-year view only.
A6: Forecast band | B6: Base quarterly revenue x (1 +/- backtest error at that horizon). Horizons 5-6 (Q3-Q4 2027) are beyond the tested horizon; the h4 error is used as a floor.
A7: False alarm (trigger history) | B7: A trigger firing after which YoY revenue growth over the next 4 quarters slowed no faster than the Base pace (4 x P1 Base).
A8: Sequential growth | B8: Quarter revenue / prior quarter revenue - 1.
A9: Annual deceleration (P1) | B9: Reduction, in percentage points, of a quarter's sequential growth vs the same quarter one year earlier.
A10: NDR | B10: Company definition (source book); measurement basis not disclosed. INDICATOR ONLY in this plan.
A11: Cash + marketable securities | B11: Balance-sheet cash and cash equivalents plus marketable securities; restricted cash excluded.
A12: Sign convention | B12: Expenses positive in opex lines and subtracted in operating income; cash outflows negative in Cash_FCF (severance, buybacks).
A13: Growth cost (elasticity) | B13: ASSUMED annualized revenue lost per $1 of quarterly spend cut, starting the following quarter and cumulative. Not observable in public data.

Sheet Historical_Drivers
A1: Historical drivers (Sourced copies from monday_sourcebook.xlsx; Row ID row beneath each value row)
A2: USD thousands unless stated. Blue = Sourced; grey row below = source-book Row IDs.
A4: Metric | B4: Label | C4: Q1 2023 | D4: Q2 2023 | E4: Q3 2023 | F4: Q4 2023 | G4: Q1 2024 | H4: Q2 2024 | I4: Q3 2024 | J4: Q4 2024 | K4: Q1 2025 | L4: Q2 2025 | M4: Q3 2025 | N4: Q4 2025 | O4: Q1 2026 | P4: Q2 2026
A6: Revenue | B6: Sourced | C6: 162256 | D6: 175679 | E6: 189190 | F6: 202570 | G6: 216913 | H6: 236106 | I6: 251000 | J6: 267976 | K6: 282250 | L6: 299014 | M6: 316855 | N6: 333878 | O6: 351265 | P6: 364621
A7: Row ID | B7: Row ID | C7: QA-0015 | D7: QA-0016 | E7: QA-0018 | F7: QA-0020 | G7: QA-0022 | H7: QA-0023 | I7: QA-0025 | J7: QA-0027 | K7: QA-0029 | L7: QA-0030 | M7: QA-0032 | N7: QA-0034 | O7: QA-0036 | P7: QA-0037
A8: Gross profit (non-GAAP) | B8: Sourced | C8: 146719 | D8: 158008 | E8: 168866 | F8: 181764 | G8: 194703 | H8: 214215 | I8: 226909 | J8: 239080 | K8: 254579 | L8: 270113 | M8: 284031 | N8: 298736 | O8: 314190 | P8: 324222
A9: Row ID | B9: Row ID | C9: QA-0489 | D9: QA-0490 | E9: QA-0492 | F9: QA-0494 | G9: QA-0496 | H9: QA-0497 | I9: QA-0499 | J9: QA-0501 | K9: QA-0503 | L9: QA-0504 | M9: QA-0506 | N9: QA-0508 | O9: QA-0510 | P9: QA-0511
A10: R&D (non-GAAP) | B10: Sourced | C10: 28519 | D10: 27908 | E10: 28051 | F10: 33285 | G10: 34797 | H10: 36878 | I10: 42973 | J10: 48066 | K10: 53844 | L10: 59233 | M10: 57772 | N10: 67700 | O10: 78413 | P10: 83003
A11: Row ID | B11: Row ID | C11: QA-0565 | D11: QA-0566 | E11: QA-0568 | F11: QA-0570 | G11: QA-0572 | H11: QA-0573 | I11: QA-0575 | J11: QA-0577 | K11: QA-0579 | L11: QA-0580 | M11: QA-0582 | N11: QA-0584 | O11: QA-0586 | P11: QA-0587
A12: S&M (non-GAAP) | B12: Sourced | C12: 102652 | D12: 98831 | E12: 101504 | F12: 110020 | G12: 120806 | H12: 120738 | I12: 130339 | J12: 127791 | K12: 135882 | L12: 139223 | M12: 151804 | N12: 159858 | O12: 158181 | P12: 149444
A13: Row ID | B13: Row ID | C13: QA-0603 | D13: QA-0604 | E13: QA-0606 | F13: QA-0608 | G13: QA-0610 | H13: QA-0611 | I13: QA-0613 | J13: QA-0615 | K13: QA-0617 | L13: QA-0618 | M13: QA-0620 | N13: QA-0622 | O13: QA-0624 | P13: QA-0625
A14: G&A (non-GAAP) | B14: Sourced | C14: 15841 | D14: 14652 | E14: 15234 | F14: 17259 | G14: 17579 | H14: 18182 | I14: 21417 | J14: 22958 | K14: 24099 | L14: 26563 | M14: 26971 | N14: 29247 | O14: 28559 | P14: 30665
A15: Row ID | B15: Row ID | C15: QA-0641 | D15: QA-0642 | E15: QA-0644 | F15: QA-0646 | G15: QA-0648 | H15: QA-0649 | I15: QA-0651 | J15: QA-0653 | K15: QA-0655 | L15: QA-0656 | M15: QA-0658 | N15: QA-0660 | O15: QA-0662 | P15: QA-0663
A16: Operating income (non-GAAP) | B16: Sourced | C16: -293 | D16: 16617 | E16: 24077 | F16: 21200 | G16: 21521 | H16: 38417 | I16: 32180 | J16: 40265 | K16: 40754 | L16: 45094 | M16: 47484 | N16: 41931 | O16: 49037 | P16: 61110
A17: Row ID | B17: Row ID | C17: QA-0679 | D17: QA-0680 | E17: QA-0682 | F17: QA-0684 | G17: QA-0686 | H17: QA-0687 | I17: QA-0689 | J17: QA-0691 | K17: QA-0693 | L17: QA-0694 | M17: QA-0696 | N17: QA-0698 | O17: QA-0700 | P17: QA-0701
A18: Operating income (GAAP) | B18: Sourced | C18: -22752 | D18: -12167 | E18: -2521 | F18: -1145 | G18: -5022 | H18: 1794 | I18: -27402 | J18: 9596 | K18: 9796 | L18: -11551 | M18: -2378 | N18: 2385 | O18: 19754 | P18: -1544
A19: Row ID | B19: Row ID | C19: QA-0321 | D19: QA-0322 | E19: QA-0324 | F19: QA-0326 | G19: QA-0328 | H19: QA-0329 | I19: QA-0331 | J19: QA-0333 | K19: QA-0335 | L19: QA-0336 | M19: QA-0338 | N19: QA-0340 | O19: QA-0342 | P19: QA-0343
A20: SBC total | B20: Sourced | C20: 22459 | D20: 28784 | E20: 26598 | F20: 22345 | G20: 26543 | H20: 36623 | I20: 35374 | J20: 30669 | K20: 30958 | L20: 56645 | M20: 49862 | N20: 39546 | O20: 29283 | P20: 41218
A21: Row ID | B21: Row ID | C21: QA-0847 | D21: QA-0848 | E21: QA-0850 | F21: QA-0852 | G21: QA-0854 | H21: QA-0855 | I21: QA-0857 | J21: QA-0859 | K21: QA-0861 | L21: QA-0862 | M21: QA-0864 | N21: QA-0866 | O21: QA-0868 | P21: QA-0869
A22: Restructuring charges (GAAP line) | B22: Sourced | C22: Not disclosed | D22: Not disclosed | E22: Not disclosed | F22: Not disclosed | G22: Not disclosed | H22: Not disclosed | I22: Not disclosed | J22: Not disclosed | K22: Not disclosed | L22: Not disclosed | M22: Not disclosed | N22: Not disclosed | O22: Not disclosed | P22: 21436
A23: Row ID | B23: Row ID | P23: QA-0267
A24: Adjusted FCF / FCF | B24: Sourced | C24: 38682 | D24: 45932 | E24: 64890 | F24: 55441 | G24: 89894 | H24: 50821 | I24: 82412 | J24: 72703 | K24: 109532 | L24: 64093 | M24: 92301 | N24: 56734 | O24: 102778 | P24: 52344
A25: Row ID | B25: Row ID | C25: QA-1081 | D25: QA-1082 | E25: QA-1084 | F25: QA-1086 | G25: QA-1088 | H25: QA-1089 | I25: QA-1091 | J25: QA-1093 | K25: QA-1095 | L25: QA-1096 | M25: QA-1098 | N25: QA-1100 | O25: QA-1102 | P25: QA-1103
A26: Cash and cash equivalents | B26: Sourced | C26: 935565 | D26: 989377 | E26: 1054270 | F26: 1116128 | G26: 1224544 | H26: 1290242 | I26: 1337155 | J26: 1411602 | K26: 1527605 | L26: 1590515 | M26: 1527246 | N26: 1503149 | O26: 997135 | P26: 853402
A27: Row ID | B27: Row ID | C27: QA-1220 | D27: QA-1221 | E27: QA-1222 | F27: QA-1223 | G27: QA-1224 | H27: QA-1225 | I27: QA-1226 | J27: QA-1227 | K27: QA-1228 | L27: QA-1229 | M27: QA-1230 | N27: QA-1231 | O27: QA-1232 | P27: QA-1233
A28: Marketable securities | B28: Sourced | C28: Not disclosed | D28: Not disclosed | E28: Not disclosed | F28: Not disclosed | G28: Not disclosed | H28: Not disclosed | I28: 50667 | J28: 50004 | K28: 60730 | L28: 60102 | M28: 211740 | N28: 162308 | O28: 215141 | P28: 219353
A29: Row ID | B29: Row ID | I29: QA-1237 | J29: QA-1238 | K29: QA-1239 | L29: QA-1240 | M29: QA-1241 | N29: QA-1242 | O29: QA-1243 | P29: QA-1244
A30: NDR all customers | B30: Sourced | F30: 1.1 | G30: 1.1 | H30: 1.1 | I30: 1.11 | J30: 1.12 | K30: 1.12 | L30: 1.11 | M30: 1.11 | N30: 1.1 | O30: 1.1 | P30: 1.09
A31: Row ID | B31: Row ID | F31: QA-1310 | G31: QA-1311 | H31: QA-1312 | I31: QA-1313 | J31: QA-1314 | K31: QA-1315 | L31: QA-1316 | M31: QA-1317 | N31: QA-1318 | O31: QA-1319 | P31: QA-1320
A32: Customers >$50k ARR | B32: Sourced | C32: 1683 | D32: 1892 | E32: 2077 | F32: 2295 | G32: 2491 | H32: 2713 | I32: 2907 | J32: 3201 | K32: 3444 | L32: 3702 | M32: 3993 | N32: 4281 | O32: 4547 | P32: 4834
A33: Row ID | B33: Row ID | C33: QA-1413 | D33: QA-1414 | E33: QA-1415 | F33: QA-1416 | G33: QA-1417 | H33: QA-1418 | I33: QA-1419 | J33: QA-1420 | K33: QA-1421 | L33: QA-1422 | M33: QA-1423 | N33: QA-1424 | O33: QA-1425 | P33: QA-1426
A34: Derived history
A35: Revenue sequential growth | B35: Derived | D35: =D6/C6-1 -> 0.082727295 | E35: =E6/D6-1 -> 0.076907314 | F35: =F6/E6-1 -> 0.070722554 | G35: =G6/F6-1 -> 0.070805154 | H35: =H6/G6-1 -> 0.088482479 | I35: =I6/H6-1 -> 0.063081836 | J35: =J6/I6-1 -> 0.067633466 | K35: =K6/J6-1 -> 0.053265964 | ... P35: =P6/O6-1 -> 0.038022576
A36: Gross margin (non-GAAP) | B36: Derived | C36: =C8/C6 -> 0.90424391 | D36: =D8/D6 -> 0.89941313 | E36: =E8/E6 -> 0.8925736 | F36: =F8/F6 -> 0.89728983 | G36: =G8/G6 -> 0.89760872 | H36: =H8/H6 -> 0.90728317 | I36: =I8/I6 -> 0.90401992 | J36: =J8/J6 -> 0.89216945 | ... P36: =P8/P6 -> 0.88920276
A37: Operating margin (non-GAAP) | B37: Derived | C37: =C16/C6 -> -0.0018057884 | D37: =D16/D6 -> 0.094587287 | E37: =E16/E6 -> 0.1272636 | F37: =F16/F6 -> 0.10465518 | G37: =G16/G6 -> 0.099214893 | H37: =H16/H6 -> 0.16271082 | I37: =I16/I6 -> 0.12820717 | J37: =J16/J6 -> 0.15025599 | ... P37: =P16/P6 -> 0.16759868
A38: Cash + marketable securities | B38: Derived | C38: =IF(ISNUMBER(C28),C26+C28,"n/a") -> n/a | D38: =IF(ISNUMBER(D28),D26+D28,"n/a") -> n/a | E38: =IF(ISNUMBER(E28),E26+E28,"n/a") -> n/a | F38: =IF(ISNUMBER(F28),F26+F28,"n/a") -> n/a | G38: =IF(ISNUMBER(G28),G26+G28,"n/a") -> n/a | H38: =IF(ISNUMBER(H28),H26+H28,"n/a") -> n/a | I38: =IF(ISNUMBER(I28),I26+I28,"n/a") -> 1387822 | J38: =IF(ISNUMBER(J28),J26+J28,"n/a") -> 1461606 | ... P38: =IF(ISNUMBER(P28),P26+P28,"n/a") -> 1072755
A40: Point inputs (Sourced)
A41: Input | B41: Label | C41: Value | D41: Reference | E41: Unit
A42: FY 2026 Adjusted free cash flow guidance low | B42: Sourced | C42: 280 | D42: GH-0098:low | E42: USD m
A43: FY 2026 Adjusted free cash flow guidance high | B43: Sourced | C43: 290 | D43: GH-0098:high | E43: USD m
...

Sheet Cash_Bridge
A1: Cash questions resolved from primary sources: adjusted FCF definition, severance treatment, H1 2026 cash bridge
A2: USD thousands unless stated. Quotes are verbatim from SEC filings (Source IDs as in the source book Sources sheet).
A4: A. Quotes
A5: ER-2026Q2 (6-K Ex. 99.1, Aug 10, 2026), Non-GAAP Financial Measures | B5: "adjusted free cash flow, which is defined as free cash flow plus costs associated with the build-out of our corporate headquarters, and adjusted free cash flow margin. Certain of these non-GAAP financial measures exclude share-based compensation and restructuring costs."
A6: H1MDA-2026 (6-K Ex. 99.3) and 20F-FY2025 Item 5 | B6: "We define adjusted free cash flow as net cash provided by operating activities, less cash used for purchases of property and equipment and capitalized software development costs, plus costs associated with the build-out [and expansion] of our corporate headquarters."
A7: 6K-20260722-RESTR (6-K, Jul 22, 2026) | B7: "Full-year 2026 projections for Non-GAAP Operating Margin and Adjusted Free Cash Flow Margin continue to incorporate an estimated adverse foreign currency exchange impact of approximately 100 to 200 basis points and exclude any estimated restructuring charges from the Plan."
A8: 6K-20260722-RESTR | B8: "...approximately $30 - $35 million of future net charges related to severance payments, employee benefits, and related costs..."
A9: H1MDA-2026 | B9: "...the related severance and employee costs are expected to be recognized in subsequent periods as employees are notified." "...a portion of up to approximately $5 million potentially recognized in the first quarter of 2027..."
A11: B. Reconciliation of net cash provided by operating activities to adjusted free cash flow (ER-2026Q2)
A12: Line | B12: Q2 2026 | C12: Row ID | D12: 6M 2026 | E12: Row ID | F12: Label
A13: Net cash provided by operating activities | B13: 55354 | C13: QA-0965 | D13: 160041 | E13: QA-0966 | F13: Sourced
A14: Purchase of property and equipment | B14: -3790 | C14: QA-1003 | D14: -6237 | E14: QA-1004 | F14: Sourced
A15: Capitalized software development costs | B15: -1106 | C15: QA-1041 | D15: -1590 | E15: QA-1042 | F15: Sourced
A16: Purchase of PP&E related to build-out of corporate headquarters (add-back) | B16: 1886 | C16: QA-1065 | D16: 2908 | E16: QA-1066 | F16: Sourced
A17: Line for restructuring / severance payments in the reconciliation | B17: NONE | D17: NONE | F17: Sourced (absence)
A18: Adjusted free cash flow (Derived = sum of lines above) | B18: =SUM(B13:B16) -> 52344 | D18: =SUM(D13:D16) -> 155122 | F18: Derived
A19: Adjusted free cash flow as reported | B19: 52344 | C19: QA-1103 | D19: 155122 | E19: QA-1104 | F19: Sourced
A21: C. Answer
A22: (1) The company definition of adjusted FCF does NOT exclude restructuring or severance payments: severance is paid through operating cash flow and the reconciliation has no add-back for it (only the HQ build-out). Reported adjusted FCF in H2 2026 will therefore be reduced by severance paid.
A23: (2) The FY2026 adjusted FCF outlook EXCLUDES restructuring: the Jul 22, 2026 6-K states the FY2026 adjusted FCF margin projection excludes any estimated restructuring charges from the Plan; the Aug 10 dollar guide ($280-290M, margin 19%-20%) is the same margin and does not restate a change.
A24: (3) Decision: the plan ties guide-basis adjusted FCF to the guide and deducts severance cash ONCE, as a separate line. This is NOT a double count. Reported-basis adjusted FCF (guide basis less severance) is shown as a memo line in Cash_FCF. Residual uncertainty: the Aug 10 release does not repeat the exclusion wording, and up to ~$5M of charges may fall in Q1 2027.
A26: D. Bridge of cash + marketable securities, Dec 31, 2025 -> Jun 30, 2026 (USD k)
A27: Item | B27: H1 2026 | C27: Reference | D27: Note | E27: Class | F27: Label
A28: Opening cash + marketable securities, Dec 31, 2025 | B28: =Historical_Drivers!$N$38 -> 1665457 | C28: Historical_Drivers (QA-1231 + QA-1242) | E28: balance | F28: Derived
A29: Adjusted free cash flow | B29: =Historical_Drivers!$C$59 -> 155122 | C29: QA-1104 | D29: Includes interest income (financial income, net $17.3M H1 2026 per H1MDA-2026 is inside operating cash flow) and FX effects on operating items | E29: FCF | F29: Derived (link)
A30: Less: HQ build-out add-back (cash was spent) | B30: =-D16 -> -2908 | C30: QA-1066 | D30: One-off renovation of vacated Israel office | E30: other: one-off | F30: Derived (link)
A31: Share repurchases | B31: -734971 | C31: QA-1202 | D31: $870M authorization fully used | E31: buyback | F31: Sourced
A32: Acquisition of a business operation (OneAI) | B32: -13200 | C32: H1FS-2026 cash flow statement (6-K Ex. 99.2, acc. 0001178913-26-003971) | D32: Not in source book; primary source | E32: other: one-off | F32: Sourced
A33: Purchase of securities of privately held companies (monday ventures) | B33: -6000 | C33: H1FS-2026 cash flow statement (6-K Ex. 99.2, acc. 0001178913-26-003971) | D33: $50M corporate venture fund | E33: other: recurring | F33: Sourced
A34: Investment in affiliated company (monday ventures) | B34: -4332 | C34: H1FS-2026 cash flow statement (6-K Ex. 99.2, acc. 0001178913-26-003971) | E34: other: recurring | F34: Sourced
A35: Proceeds from exercise of share options and ESPP | B35: 15369 | C35: H1FS-2026 cash flow statement (6-K Ex. 99.2, acc. 0001178913-26-003971) | E35: other: recurring | F35: Sourced
A36: Repayment of tax advance relating to exercises of share options and RSUs, net (taxes on equity awards) | B36: -1829 | C36: H1FS-2026 cash flow statement (6-K Ex. 99.2, acc. 0001178913-26-003971) | E36: other: recurring | F36: Sourced
A37: Accretion of discount on marketable securities (non-cash increase in securities) | B37: 1693 | C37: H1FS-2026 cash flow statement (6-K Ex. 99.2, acc. 0001178913-26-003971) | D37: Deducted in operating cash flow; adds to securities balance | E37: other: recurring | F37: Sourced
A38: Effect of exchange rates on cash (separate line) | B38: 0 | C38: H1FS-2026 cash flow statement (6-K Ex. 99.2, acc. 0001178913-26-003971) | D38: No separate FX line in the statement; FX is inside operating items | E38: FX | F38: Sourced
A39: Fair-value changes and other (Derived residual) | B39: =B40-B28-SUM(B29:B38) -> -1646 | C39: balance less items | E39: other: residual | F39: Derived
A40: Closing cash + marketable securities, Jun 30, 2026 | B40: =Historical_Drivers!$P$38 -> 1072755 | C40: Historical_Drivers (QA-1233 + QA-1244) | E40: balance | F40: Derived
A42: Total other cash flows H1 2026 (all items except FCF and buybacks) | B42: =SUM(B30:B39)-B31 -> -12853 | F42: Derived
A43: Run-rate per quarter (USD m) -> Assumptions P12 | B43: =B42/2/1000 -> -6.4265 | F43: Derived
A44: Sensitivity: run-rate excluding one-offs (OneAI, HQ) (USD m / quarter) | B44: =(B42-B32-B30)/2/1000 -> 1.6275 | F44: Derived
A46: E. Why the analysis workbook showed about -$67M (cash and equivalents only)
...

Sheet Assumptions
A1: Assumptions (owner-approved rulings of Oct 28, 2026; orange = Assumed, black = Derived)
A2: Each parameter: Base and Downside value, current level, forecast path, rationale, evidence IDs, sensitivity.
A4: ID | B4: Parameter | C4: Base | D4: Downside | E4: Unit | F4: Current level | G4: Forecast path | H4: Rationale | I4: Evidence IDs | J4: Sensitivity | K4: Label
A5: P1 | B5: Annual deceleration of same-quarter sequential revenue growth | C5: 1.3 | D5: 2.6 | E5: pp / year | F5: Avg QoQ fell ~1.6 pp 2024->2025 and ~1.1 pp H1 2025->H1 2026 | G5: 2027 quarter seq growth = same quarter 2026 seq - P1 | H5: Method B (ruling 1); Downside = faster deceleration (ruling 2). | I5: Historical_Drivers revenue rows; monday_driver_audit.xlsx Revenue_Backtest | J5: Downside (+1.3 pp/yr) lowers FY2027 revenue by $79.7M and op. income by $79.0M (opex dollars held). | K5: Assumed
A6: P2 | B6: Q4 2026 sequential revenue growth | C6: =((Historical_Drivers!$C$46+Historical_Drivers!$C$47)/2*1000-Historical_Drivers!$C$58-(Historical_Drivers!$C$50+Historical_Drivers!$C$51)/2*1000)/((Historical_Drivers!$C$50+Historical_Drivers!$C$51)/2*1000)-1 -> 0.043669377 | D6: =C6-(D5-C5)/100 -> 0.030669377 | E6: % | F6: Q2 2026 seq 3.8%; Q3 2026 call seq ~3.8% | G6: Base: guidance-implied Q4/Q3 step; Downside: Base - (P1 Downside - P1 Base) | H6: FY guide covers Q4 implicitly (FY mid - H1 actual - Q3 guide mid). | I6: GH-0100, GH-0102, QA H1 2026 revenue | J6: +/-0.5 pp = about +/-$1.9M Q4 2026 revenue and about +/-$8.5M FY2027 revenue (Q4 is the 2027 base). | K6: Derived
A7: P3 | B7: Non-GAAP gross margin change per quarter | C7: -0.1 | D7: -0.25 | E7: pp / quarter | F7: Q2 2026 88.9% | G7: Q3 2026 = Q2 + Base step (both cases, so Q3 matches the call); later quarters + case step | H7: Company expects a modest mid-term decline from AI compute (FY2025 20-F). | I7: Historical_Drivers GP rows; source-book Definitions | J7: Downside step (-0.25 vs -0.10 pp/q) lowers FY2027 op. income by $8.5M (rate effect in Scenarios bridge). | K7: Assumed
A8: P4 | B8: R&D % of revenue: 2027 change vs Q3 2026 (Base only; Downside holds Base dollars) | C8: -0.5 | E8: pp | F8: Q2 2026 22.8% | G8: Q3 2026 from the locked call; Q4 2026 held; 2027 = Q3 + P4 | H8: Restructuring (~20% workforce) net of continued hiring in strategic areas. | I8: Historical_Drivers R&D rows; audit Proposed_Assumptions | J8: each 1 pp = about $17.1M of FY2027 op. income. | K8: Assumed
A9: P5 | B9: S&M % of revenue: 2027 change vs Q3 2026 (Base only) | C9: -0.5 | E9: pp | F9: Q2 2026 41.0% (post-commission-change basis) | G9: as P4 | H9: Ratios use only post-2025 commission-change quarters. | I9: Historical_Drivers S&M rows (2025-2026); AN-0348..AN-0350 | J9: each 1 pp = about $17.1M of FY2027 op. income. | K9: Assumed
A10: P6 | B10: G&A % of revenue: 2027 change vs Q3 2026 (Base only) | C10: -0.2 | E10: pp | F10: Q2 2026 8.4% | G10: as P4 | H10: Stable 8.1%-8.9%. | I10: Historical_Drivers G&A rows | J10: each 1 pp = about $17.1M of FY2027 op. income. | K10: Assumed
A11: P7 | B11: 2027 adjusted FCF / non-GAAP operating income (annual conversion) | C11: 1.23 | D11: 1 | E11: x | F11: FY2026 guide-implied 285/232 = 1.23x; Q2 2026 0.86x | G11: 2027 FCF = 2027 op. income x P7, phased by 2023-2025 quarterly shares | H11: Ruling 3: anchored to the FY2026 guide; historical 2-4x ratios no longer representative. | I11: GH-0098, GH-0099; analysis Cash_Conversion!C41:F41 | J11: FY2027 Base FCF range: $404.0M at 1.23x, $371.4M at 1.13x, $328.5M at 1.00x (Cash_FCF). | K11: Assumed
A12: P8 | B12: Severance cash, H2 2026 (split evenly Q3/Q4), outside adjusted FCF | C12: 32.5 | D12: 35 | E12: USD m | F12: ~$30-35M severance-related estimate (6-K Jul 22, 2026) | G12: -P8/2 in Q3 and Q4 2026 | H12: UNRESOLVED whether the FY FCF guide includes it; modeled as a separate cash item (adjusted FCF tied to the guide is assumed to exclude it). | I12: Annual restructuring rows (6K-20260722-RESTR) | J12: Guide excludes restructuring (6-K Jul 22, 2026): severance is deducted once; +/-$2.5M changes 2026 cash by -/+$2.5M. | K12: Assumed
A13: P9 | B13: SBC % of revenue (GAAP bridge) | C13: 0.105 | D13: 0.105 | E13: share | F13: Q2 2026 11.3% | G13: flat | H13: Recent quarters ~8%-12%. | I13: Historical_Drivers SBC rows | J13: +/-1 pp = about +/-$17.1M FY2027 GAAP op. income (no non-GAAP or cash effect). | K13: Assumed
A14: P10 | B14: Restructuring charges (GAAP, net), H2 2026, split evenly Q3/Q4 | C14: 50 | D14: 50 | E14: USD m | F14: Plan estimate ~$45-55M net (incl. ~$15M SBC credit) | G14: Q3, Q4 2026 = P10/2; 2027 = 0 | H14: Midpoint of the disclosed range; excluded from non-GAAP. | I14: Annual restructuring rows (6K-20260722-RESTR) | J14: +/-$5M changes FY2026 GAAP op. income by -/+$5M (no non-GAAP effect; cash portion is P8). | K14: Assumed
A15: P11 | B15: Share repurchases per quarter | C15: 0 | D15: 0 | E15: USD m | F15: $870M authorization fully used by Q2 2026 | G15: none | H15: FLAG: no new program disclosed. | I15: QA repurchase rows (ER-2026Q2) | J15: A new program reduces cash one-for-one. | K15: Assumed
A16: P12 | B16: Other cash flows per quarter (acquisitions, venture investments, option proceeds, tax advances, securities accretion / fair value) | C16: =Cash_Bridge!$B$43 -> -6.4265 | D16: =Cash_Bridge!$B$43 -> -6.4265 | E16: USD m | F16: H1 2026: -$12.9M in total (Cash_Bridge) | G16: H1 2026 quarterly run-rate held flat Q3 2026-Q4 2027 | H16: ASSUMED persistence of the H1 2026 run-rate from the primary-source cash bridge. Interest income is NOT separate: it is inside operating cash flow and therefore inside adjusted FCF. | I16: H1FS-2026 cash flow statement; QA-1202, QA-1231..1233, QA-1242..1244; Cash_Bridge | J16: Excluding one-offs (OneAI, HQ) the run-rate is $1.6M/quarter instead of $-6.4M: about $48.3M more cash by end 2027. | K16: Derived (Assumed persistence)
A17: P13 | B17: NDR indicator (NOT a driver): change per quarter after Q3 2026 | C17: -0.25 | D17: =(D18-Historical_Drivers!$C$56)*100/5 -> -0.7 | E17: pp / quarter | F17: Q2 2026 109%; locked Q3 call MID 108.5% | G17: Base: Q3 call MID then -0.25 pp/q; Downside: linear to 105% by Q4 2027 | H17: Ruling 1-2: narrative indicator only; never used in any calculation. | I17: QA NDR rows; locked call NDR!D37 | J17: n/a (no model effect) | K17: Assumed
A18: P15 | B18: NDR indicator Downside endpoint, Q4 2027 (NOT a driver) | D18: 1.05 | E18: share | F18: Q2 2026 109% | G18: Downside NDR reaches this level by Q4 2027 | H18: Ruling 2: weakening toward ~105%, documented indicator only. | I18: Owner ruling; QA NDR rows | J18: n/a (no model effect) | K18: Assumed
A19: P14 | B19: Net adds of customers >$50k ARR per quarter (indicator and trigger): Base = last-8 median, Downside = last-8 minimum | C19: =MEDIAN(Trigger_History!$H$20:$H$27) -> 276.5 | D19: =MIN(Trigger_History!$H$20:$H$27) -> 194 | E19: customers | F19: Last-8 median 276.5, min 194 | G19: Q3 call MID then + P14 per quarter | H19: Evidence-supported trigger metric; indicator only. | I19: QA-1405..QA-1426; Trigger_History | J19: n/a (no model effect) | K19: Derived
A20: P16 | B20: Trigger fire-rate tolerance: a trigger firing in more than this share of evaluable quarters is flagged as firing too often | C20: 0.25 | E20: share | F20: n/a | G20: Applied in Trigger_History | H20: A trigger meant to signal a regime change should be rare; one quarter in four is the tolerance. | I20: Trigger_History | J20: At 15% or 35% the flags in Trigger_History change only if a fire rate lies between. | K20: Assumed
B22: Management-response levers (applied to the Downside from the response start quarter L0; see Management_Response)
A23: L0 | B23: Response start quarter in 2027 (1 = Q1 ... 4 = Q4): earliest action consistent with the two-consecutive-quarter trigger rule | C23: 2 | E23: quarter | F23: n/a | G23: Levers active from this quarter through Q4 2027 | H23: T2 (beat) can first fire on Q3+Q4 2026 actuals; Q4 2026 is reported in Feb 2027 (Q1 2027), so savings can start in Q2 2027 at the earliest. T1 cannot fire before Q4 2026+Q1 2027 (reported May 2027), i.e. action from Q3 2027. | I23: Reporting calendar in Sources (Q4 results in February, Q1 in May); Recommendation triggers | J23: Start Q3 2027 instead of Q2: FY2027 saving falls by about one third (3 to 2 active quarters). | K23: Assumed
A24: L1 | B24: Lever 1: cut R&D + G&A dollars vs Downside (slow hiring / opex growth) | C24: 0.05 | E24: share | F24: n/a | G24: From L0 to Q4 2027 | H24: Moderate slowdown equivalent to pausing net hiring growth; size is a choice, not a forecast. | I24: Opex rows | J24: Each 1% = about $5M of full-year 2027 op. income. | K24: Assumed
A25: L2 | B25: Lever 2: cut S&M dollars vs Downside | C25: 0.1 | E25: share | F25: n/a | G25: From L0 to Q4 2027 | H25: Largest discretionary line (advertising, partner commissions). | I25: Opex rows | J25: Each 1% = about $6.5M of 2027 op. income before growth cost. | K25: Assumed
A26: E1 | B26: ILLUSTRATIVE ONLY - growth cost: annualized revenue lost per $1 of quarterly S&M cut (not used for the recommendation; see breakeven) | C26: 0.3 | E26: x | F26: NOT observable in the data | G26: starts the quarter after the cut, cumulative | H26: ASSUMED RANGE 0 / 0.3 / 0.6: the public data cannot prove the growth cost of cutting spend. | I26: none (no evidence exists) | J26: See Management_Response low/mid/high columns. | K26: Assumed
A27: E2 | B27: ILLUSTRATIVE ONLY - growth cost: annualized revenue lost per $1 of quarterly R&D+G&A cut | C27: 0.1 | E27: x | F27: NOT observable in the data | G27: as E1 | H27: ASSUMED RANGE 0 / 0.1 / 0.2; effects of R&D cuts mostly fall beyond 2027. | I27: none (no evidence exists) | J27: See Management_Response. | K27: Assumed

Sheet Revenue_Build
A1: Revenue build (Method B: guidance for the quarters it covers, then sequential-deceleration trend)
A2: USD millions. Q1-Q2 2026 actual; Q3 2026 = locked call; Q4 2026 = guidance-implied step; 2027 = same-quarter 2026 sequential growth less the annual deceleration.
A4: BASE
A5: Line | B5: Label | C5: Q1 2026A | D5: Q2 2026A | E5: Q3 2026 | F5: Q4 2026 | G5: Q1 2027 | H5: Q2 2027 | I5: Q3 2027 | J5: Q4 2027 | K5: FY2026 | L5: FY2027 | M5: Note
A6: Sequential revenue growth | B6: Derived (Assumed P1/P2) | C6: =Historical_Drivers!$O$35 -> 0.052075908 | D6: =Historical_Drivers!$P$35 -> 0.038022576 | E6: =E7/D7-1 -> 0.037741815 | F6: =Assumptions!$C$6 -> 0.043669377 | G6: =C6-Assumptions!$C$5/100 -> 0.039075908 | H6: =D6-Assumptions!$C$5/100 -> 0.025022576 | I6: =E6-Assumptions!$C$5/100 -> 0.024741815 | J6: =F6-Assumptions!$C$5/100 -> 0.030669377
A7: Revenue | B7: Sourced (Q1-Q3) / Derived | C7: =Historical_Drivers!$O$6/1000 -> 351.265 | D7: =Historical_Drivers!$P$6/1000 -> 364.621 | E7: =Historical_Drivers!$C$52 -> 378.38246 | F7: =E7*(1+F6) -> 394.90618 | G7: =F7*(1+G6) -> 410.3375 | H7: =G7*(1+H6) -> 420.6052 | I7: =H7*(1+I6) -> 431.01174 | J7: =I7*(1+J6) -> 444.2306 | K7: =SUM(C7:F7) -> 1489.1746 | L7: =SUM(G7:J7) -> 1706.185 | M7: Q3 2026 = locked call MID
A8: Revenue YoY growth | B8: Derived | C8: =C7*1000/Historical_Drivers!$K$6-1 -> 0.24451727 | D8: =D7*1000/Historical_Drivers!$L$6-1 -> 0.21941113 | E8: =E7*1000/Historical_Drivers!$M$6-1 -> 0.19418175 | F8: =F7*1000/Historical_Drivers!$N$6-1 -> 0.18278588 | G8: =G7/C7-1 -> 0.16817076 | H8: =H7/D7-1 -> 0.15354081 | I8: =I7/E7-1 -> 0.13909017 | J8: =J7/F7-1 -> 0.12490161 | K8: =K7/Historical_Drivers!$C$70-1 -> 0.20874859 | L8: =L7/K7-1 -> 0.14572529
A9: FY2026 revenue minus FY guide midpoint (USD m) | B9: Derived | K9: =K7-(Historical_Drivers!$C$46+Historical_Drivers!$C$47)/2 -> 19.174643
A10: NDR all customers - INDICATOR ONLY (not used in any calculation) | B10: Derived (Assumed P13) | D10: =Historical_Drivers!$P$30 -> 1.09 | E10: =Historical_Drivers!$C$56 -> 1.085 | F10: =E10+Assumptions!$C$17/100 -> 1.0825 | G10: =F10+Assumptions!$C$17/100 -> 1.08 | H10: =G10+Assumptions!$C$17/100 -> 1.0775 | I10: =H10+Assumptions!$C$17/100 -> 1.075 | J10: =I10+Assumptions!$C$17/100 -> 1.0725 | M10: Narrative indicator per ruling 1
A11: Customers >$50k ARR - INDICATOR (trigger metric) | B11: Derived (Assumed P14) | D11: =Historical_Drivers!$P$32 -> 4834 | E11: =Historical_Drivers!$C$57 -> 5110.5 | F11: =E11+Assumptions!$C$19 -> 5387 | G11: =F11+Assumptions!$C$19 -> 5663.5 | H11: =G11+Assumptions!$C$19 -> 5940 | I11: =H11+Assumptions!$C$19 -> 6216.5 | J11: =I11+Assumptions!$C$19 -> 6493
A13: DOWNSIDE (before management response)
A14: Line | B14: Label | C14: Q1 2026A | D14: Q2 2026A | E14: Q3 2026 | F14: Q4 2026 | G14: Q1 2027 | H14: Q2 2027 | I14: Q3 2027 | J14: Q4 2027 | K14: FY2026 | L14: FY2027 | M14: Note
A15: Sequential revenue growth | B15: Derived (Assumed P1/P2) | C15: =Historical_Drivers!$O$35 -> 0.052075908 | D15: =Historical_Drivers!$P$35 -> 0.038022576 | E15: =E16/D16-1 -> 0.037741815 | F15: =Assumptions!$D$6 -> 0.030669377 | G15: =C15-Assumptions!$D$5/100 -> 0.026075908 | H15: =D15-Assumptions!$D$5/100 -> 0.012022576 | I15: =E15-Assumptions!$D$5/100 -> 0.011741815 | J15: =F15-Assumptions!$D$5/100 -> 0.0046693767
A16: Revenue | B16: Sourced (Q1-Q3) / Derived | C16: =Historical_Drivers!$O$6/1000 -> 351.265 | D16: =Historical_Drivers!$P$6/1000 -> 364.621 | E16: =Historical_Drivers!$C$52 -> 378.38246 | F16: =E16*(1+F15) -> 389.98721 | G16: =F16*(1+G15) -> 400.15648 | H16: =G16*(1+H15) -> 404.96739 | I16: =H16*(1+I15) -> 409.72245 | J16: =I16*(1+J15) -> 411.6356 | K16: =SUM(C16:F16) -> 1484.2557 | L16: =SUM(G16:J16) -> 1626.4819 | M16: Q3 2026 = locked call MID
A17: Revenue YoY growth | B17: Derived | C17: =C16*1000/Historical_Drivers!$K$6-1 -> 0.24451727 | D17: =D16*1000/Historical_Drivers!$L$6-1 -> 0.21941113 | E17: =E16*1000/Historical_Drivers!$M$6-1 -> 0.19418175 | F17: =F16*1000/Historical_Drivers!$N$6-1 -> 0.16805304 | G17: =G16/C16-1 -> 0.13918689 | H17: =H16/D16-1 -> 0.11065296 | I17: =I16/E16-1 -> 0.082826219 | J17: =J16/F16-1 -> 0.055510494 | K17: =K16/Historical_Drivers!$C$70-1 -> 0.20475591 | L17: =L16/K16-1 -> 0.095823282
A18: FY2026 revenue minus FY guide midpoint (USD m) | B18: Derived | K18: =K16-(Historical_Drivers!$C$46+Historical_Drivers!$C$47)/2 -> 14.255671
A19: NDR all customers - INDICATOR ONLY (not used in any calculation) | B19: Derived (Assumed P13) | D19: =Historical_Drivers!$P$30 -> 1.09 | E19: =Historical_Drivers!$C$56 -> 1.085 | F19: =E19+Assumptions!$D$17/100 -> 1.078 | G19: =F19+Assumptions!$D$17/100 -> 1.071 | H19: =G19+Assumptions!$D$17/100 -> 1.064 | I19: =H19+Assumptions!$D$17/100 -> 1.057 | J19: =I19+Assumptions!$D$17/100 -> 1.05 | M19: Narrative indicator per ruling 1
A20: Customers >$50k ARR - INDICATOR (trigger metric) | B20: Derived (Assumed P14) | D20: =Historical_Drivers!$P$32 -> 4834 | E20: =Historical_Drivers!$C$57 -> 5110.5 | F20: =E20+Assumptions!$D$19 -> 5304.5 | G20: =F20+Assumptions!$D$19 -> 5498.5 | H20: =G20+Assumptions!$D$19 -> 5692.5 | I20: =H20+Assumptions!$D$19 -> 5886.5 | J20: =I20+Assumptions!$D$19 -> 6080.5
A22: SENSITIVITY: Base with Q3 2026 at the locked call LOW
A23: Line | B23: Label | C23: Q1 2026A | D23: Q2 2026A | E23: Q3 2026 | F23: Q4 2026 | G23: Q1 2027 | H23: Q2 2027 | I23: Q3 2027 | J23: Q4 2027 | K23: FY2026 | L23: FY2027 | M23: Note
A24: Sequential revenue growth | B24: Derived (Assumed P1/P2) | C24: =Historical_Drivers!$O$35 -> 0.052075908 | D24: =Historical_Drivers!$P$35 -> 0.038022576 | E24: =E25/D25-1 -> 0.027014544 | F24: =Assumptions!$C$6 -> 0.043669377 | G24: =C24-Assumptions!$C$5/100 -> 0.039075908 | H24: =D24-Assumptions!$C$5/100 -> 0.025022576 | I24: =E24-Assumptions!$C$5/100 -> 0.014014544 | J24: =F24-Assumptions!$C$5/100 -> 0.030669377
A25: Revenue | B25: Sourced (Q1-Q3) / Derived | C25: =Historical_Drivers!$O$6/1000 -> 351.265 | D25: =Historical_Drivers!$P$6/1000 -> 364.621 | E25: =Historical_Drivers!$C$53 -> 374.47107 | F25: =E25*(1+F24) -> 390.82399 | G25: =F25*(1+G24) -> 406.09579 | H25: =G25*(1+H24) -> 416.25735 | I25: =H25*(1+I24) -> 422.09101 | J25: =I25*(1+J24) -> 435.03628 | K25: =SUM(C25:F25) -> 1481.1811 | L25: =SUM(G25:J25) -> 1679.4804 | M25: Q3 2026 = locked call LOW
A26: Revenue YoY growth | B26: Derived | C26: =C25*1000/Historical_Drivers!$K$6-1 -> 0.24451727 | D26: =D25*1000/Historical_Drivers!$L$6-1 -> 0.21941113 | E26: =E25*1000/Historical_Drivers!$M$6-1 -> 0.18183734 | F26: =F25*1000/Historical_Drivers!$N$6-1 -> 0.17055927 | G26: =G25/C25-1 -> 0.15609523 | H26: =H25/D25-1 -> 0.14161651 | I26: =I25/E25-1 -> 0.12716587 | J26: =J25/F25-1 -> 0.11312583 | K26: =K25/Historical_Drivers!$C$70-1 -> 0.20226028 | L26: =L25/K25-1 -> 0.13387923
A27: FY2026 revenue minus FY guide midpoint (USD m) | B27: Derived | K27: =K25-(Historical_Drivers!$C$46+Historical_Drivers!$C$47)/2 -> 11.181058
A28: NDR all customers - INDICATOR ONLY (not used in any calculation) | B28: Derived (Assumed P13) | D28: =Historical_Drivers!$P$30 -> 1.09 | E28: =Historical_Drivers!$C$56 -> 1.085 | F28: =E28+Assumptions!$C$17/100 -> 1.0825 | G28: =F28+Assumptions!$C$17/100 -> 1.08 | H28: =G28+Assumptions!$C$17/100 -> 1.0775 | I28: =H28+Assumptions!$C$17/100 -> 1.075 | J28: =I28+Assumptions!$C$17/100 -> 1.0725 | M28: Narrative indicator per ruling 1
A29: Customers >$50k ARR - INDICATOR (trigger metric) | B29: Derived (Assumed P14) | D29: =Historical_Drivers!$P$32 -> 4834 | E29: =Historical_Drivers!$C$57 -> 5110.5 | F29: =E29+Assumptions!$C$19 -> 5387 | G29: =F29+Assumptions!$C$19 -> 5663.5 | H29: =G29+Assumptions!$C$19 -> 5940 | I29: =H29+Assumptions!$C$19 -> 6216.5 | J29: =I29+Assumptions!$C$19 -> 6493
A31: FORECAST BAND around Base revenue from backtest errors by horizon (origin = Q2 2026 actual)
A32: Line | B32: Label | C32: Q1 2026A | D32: Q2 2026A | E32: Q3 2026 | F32: Q4 2026 | G32: Q1 2027 | H32: Q2 2027 | I32: Q3 2027 | J32: Q4 2027 | K32: FY2026 | L32: FY2027 | M32: Note
A33: Horizon (quarters ahead of the last actual) | B33: Derived | E33: =COLUMN()-COLUMN($D$1) -> 1 | F33: =COLUMN()-COLUMN($D$1) -> 2 | G33: =COLUMN()-COLUMN($D$1) -> 3 | H33: =COLUMN()-COLUMN($D$1) -> 4 | I33: =COLUMN()-COLUMN($D$1) -> 5 | J33: =COLUMN()-COLUMN($D$1) -> 6
A34: Within tested horizon (1-4)? | B34: Text | E34: tested | F34: tested | G34: tested | H34: tested | I34: BEYOND | J34: BEYOND | M34: Q3 2027 (h5) and Q4 2027 (h6) lie BEYOND the tested horizon: h4 error used as a floor; true band is wider
A35: Backtest mean absolute error used | B35: Derived (link to Backtest) | E35: =Backtest!C75 -> 0.01035725 | F35: =Backtest!C76 -> 0.010650591 | G35: =Backtest!C77 -> 0.02385355 | H35: =Backtest!C78 -> 0.041292045 | I35: =Backtest!C78 -> 0.041292045 | J35: =Backtest!C78 -> 0.041292045
A36: Backtest max absolute error used | B36: Derived (link to Backtest) | E36: =Backtest!E75 -> 0.014664184 | F36: =Backtest!E76 -> 0.032417487 | G36: =Backtest!E77 -> 0.059032954 | H36: =Backtest!E78 -> 0.096390451 | I36: =Backtest!E78 -> 0.096390451 | J36: =Backtest!E78 -> 0.096390451
A37: Memo: backtest bias at that horizon | B37: Derived (link to Backtest) | E37: =Backtest!D75 -> 0.0073551849 | F37: =Backtest!D76 -> 0.0071444617 | G37: =Backtest!D77 -> -0.00056598665 | H37: =Backtest!D78 -> -0.017596508 | I37: =Backtest!D78 -> -0.017596508 | J37: =Backtest!D78 -> -0.017596508
A38: Band low (mean abs. error) | B38: Derived | C38: =Revenue_Build!C7 -> 351.265 | D38: =Revenue_Build!D7 -> 364.621 | E38: =Revenue_Build!E7*(1-E35) -> 374.46346 | F38: =Revenue_Build!F7*(1-F35) -> 390.7002 | G38: =Revenue_Build!G7*(1-G35) -> 400.5495 | H38: =Revenue_Build!H7*(1-H35) -> 403.23755 | I38: =Revenue_Build!I7*(1-I35) -> 413.21438 | J38: =Revenue_Build!J7*(1-J35) -> 425.88741 | K38: =SUM(C38:F38) -> 1481.0497 | L38: =SUM(G38:J38) -> 1642.8888 | M38: FY = sum of quarter bands (errors compound along the path, so they are treated as fully correlated)
A39: Band high (mean abs. error) | B39: Derived | C39: =Revenue_Build!C7 -> 351.265 | D39: =Revenue_Build!D7 -> 364.621 | E39: =Revenue_Build!E7*(1+E35) -> 382.30146 | F39: =Revenue_Build!F7*(1+F35) -> 399.11217 | G39: =Revenue_Build!G7*(1+G35) -> 420.12551 | H39: =Revenue_Build!H7*(1+H35) -> 437.97285 | I39: =Revenue_Build!I7*(1+I35) -> 448.8091 | J39: =Revenue_Build!J7*(1+J35) -> 462.57379 | K39: =SUM(C39:F39) -> 1497.2996 | L39: =SUM(G39:J39) -> 1769.4812 | M39: FY = sum of quarter bands (errors compound along the path, so they are treated as fully correlated)
A40: Band low (max abs. error) | B40: Derived | C40: =Revenue_Build!C7 -> 351.265 | D40: =Revenue_Build!D7 -> 364.621 | E40: =Revenue_Build!E7*(1-E36) -> 372.83379 | F40: =Revenue_Build!F7*(1-F36) -> 382.10432 | G40: =Revenue_Build!G7*(1-G36) -> 386.11407 | H40: =Revenue_Build!H7*(1-H36) -> 380.06288 | I40: =Revenue_Build!I7*(1-I36) -> 389.46632 | J40: =Revenue_Build!J7*(1-J36) -> 401.41101 | K40: =SUM(C40:F40) -> 1470.8241 | L40: =SUM(G40:J40) -> 1557.0543 | M40: FY = sum of quarter bands (errors compound along the path, so they are treated as fully correlated)
A41: Band high (max abs. error) | B41: Derived | C41: =Revenue_Build!C7 -> 351.265 | D41: =Revenue_Build!D7 -> 364.621 | E41: =Revenue_Build!E7*(1+E36) -> 383.93113 | F41: =Revenue_Build!F7*(1+F36) -> 407.70805 | G41: =Revenue_Build!G7*(1+G36) -> 434.56094 | H41: =Revenue_Build!H7*(1+H36) -> 461.14753 | I41: =Revenue_Build!I7*(1+I36) -> 472.55716 | J41: =Revenue_Build!J7*(1+J36) -> 487.05019 | K41: =SUM(C41:F41) -> 1507.5252 | L41: =SUM(G41:J41) -> 1855.3158 | M41: FY = sum of quarter bands (errors compound along the path, so they are treated as fully correlated)
A42: Base - Downside FY2027 revenue gap, % of Base | B42: Derived | L42: =(Revenue_Build!L7-Revenue_Build!L16)/Revenue_Build!L7 -> 0.046714233
A43: Gap / average 4-quarter-ahead backtest miss (x) | B43: Derived | L43: =L42/Backtest!C78 -> 1.1313131 | M43: Below ~1.0x the Downside is within normal 4-quarter forecast error
A45: VARIANT (not used in the plan): BASE with 2027 deceleration applied to a SMOOTHED base (average sequential growth of the last 4 quarters, Q1-Q4 2026)
...

Sheet Opex
A1: Non-GAAP gross margin and operating expenses
A2: USD millions. Base ratios; Downside holds Base opex DOLLARS (before any management response).
A4: BASE
A5: Line | B5: Label | C5: Q1 2026A | D5: Q2 2026A | E5: Q3 2026 | F5: Q4 2026 | G5: Q1 2027 | H5: Q2 2027 | I5: Q3 2027 | J5: Q4 2027 | K5: FY2026 | L5: FY2027 | M5: Note
A6: Gross margin (non-GAAP) | B6: Derived (Assumed P3) | C6: =Historical_Drivers!$O$36 -> 0.89445291 | D6: =Historical_Drivers!$P$36 -> 0.88920276 | E6: =D6+Assumptions!$C$7/100 -> 0.88820276 | F6: =E6+Assumptions!$C$7/100 -> 0.88720276 | G6: =F6+Assumptions!$C$7/100 -> 0.88620276 | H6: =G6+Assumptions!$C$7/100 -> 0.88520276 | I6: =H6+Assumptions!$C$7/100 -> 0.88420276 | J6: =I6+Assumptions!$C$7/100 -> 0.88320276
A7: Gross profit (non-GAAP) | B7: Sourced / Derived | C7: =Historical_Drivers!$O$8/1000 -> 314.19 | D7: =Historical_Drivers!$P$8/1000 -> 324.222 | E7: =Revenue_Build!E7*E6 -> 336.08034 | F7: =Revenue_Build!F7*F6 -> 350.36186 | G7: =Revenue_Build!G7*G6 -> 363.64223 | H7: =Revenue_Build!H7*H6 -> 372.32089 | I7: =Revenue_Build!I7*I6 -> 381.10177 | J7: =Revenue_Build!J7*J6 -> 392.34569 | K7: =SUM(C7:F7) -> 1324.8542 | L7: =SUM(G7:J7) -> 1509.4106
A8: Q3 2026 total opex implied by the locked call (GP - call op. income) | B8: Derived | E8: =E7-Historical_Drivers!$C$54 -> 266.44334
A9: R&D % of revenue (non-GAAP) | B9: Derived (Assumed P4-P6) | C9: =C10/Revenue_Build!C7 -> 0.22323032 | D9: =D10/Revenue_Build!D7 -> 0.22764185 | E9: =E10/Revenue_Build!E7 -> 0.22214013 | F9: =E9 -> 0.22214013 | G9: =$E9+Assumptions!$C$8/100 -> 0.21714013 | H9: =$E9+Assumptions!$C$8/100 -> 0.21714013 | I9: =$E9+Assumptions!$C$8/100 -> 0.21714013 | J9: =$E9+Assumptions!$C$8/100 -> 0.21714013 | K9: =K10/Revenue_Build!K7 -> 0.22374437 | L9: =L10/Revenue_Build!L7 -> 0.21714013
A10: R&D (non-GAAP) | B10: Sourced / Derived | C10: =Historical_Drivers!$O$10/1000 -> 78.413 | D10: =Historical_Drivers!$P$10/1000 -> 83.003 | E10: =E8*Historical_Drivers!$P$10/(Historical_Drivers!$P$10+Historical_Drivers!$P$12+Historical_Drivers!$P$14) -> 84.053927 | F10: =F9*Revenue_Build!F7 -> 87.72451 | G10: =G9*Revenue_Build!G7 -> 89.100737 | H10: =H9*Revenue_Build!H7 -> 91.330267 | I10: =I9*Revenue_Build!I7 -> 93.589944 | J10: =J9*Revenue_Build!J7 -> 96.460289 | K10: =SUM(C10:F10) -> 333.19444 | L10: =SUM(G10:J10) -> 370.48124
A11: S&M % of revenue (non-GAAP) | B11: Derived (Assumed P4-P6) | C11: =C12/Revenue_Build!C7 -> 0.45031814 | D11: =D12/Revenue_Build!D7 -> 0.4098612 | E11: =E12/Revenue_Build!E7 -> 0.39995553 | F11: =E11 -> 0.39995553 | G11: =$E11+Assumptions!$C$9/100 -> 0.39495553 | H11: =$E11+Assumptions!$C$9/100 -> 0.39495553 | I11: =$E11+Assumptions!$C$9/100 -> 0.39495553 | J11: =$E11+Assumptions!$C$9/100 -> 0.39495553 | K11: =K12/Revenue_Build!K7 -> 0.41426039 | L11: =L12/Revenue_Build!L7 -> 0.39495553
A12: S&M (non-GAAP) | B12: Sourced / Derived | C12: =Historical_Drivers!$O$12/1000 -> 158.181 | D12: =Historical_Drivers!$P$12/1000 -> 149.444 | E12: =E8*Historical_Drivers!$P$12/(Historical_Drivers!$P$10+Historical_Drivers!$P$12+Historical_Drivers!$P$14) -> 151.33616 | F12: =F11*Revenue_Build!F7 -> 157.94491 | G12: =G11*Revenue_Build!G7 -> 162.06507 | H12: =H11*Revenue_Build!H7 -> 166.12035 | I12: =I11*Revenue_Build!I7 -> 170.23047 | J12: =J11*Revenue_Build!J7 -> 175.45133 | K12: =SUM(C12:F12) -> 616.90607 | L12: =SUM(G12:J12) -> 673.86722
A13: G&A % of revenue (non-GAAP) | B13: Derived (Assumed P4-P6) | C13: =C14/Revenue_Build!C7 -> 0.08130329 | D13: =D14/Revenue_Build!D7 -> 0.084101025 | E13: =E14/Revenue_Build!E7 -> 0.082068443 | F13: =E13 -> 0.082068443 | G13: =$E13+Assumptions!$C$10/100 -> 0.080068443 | H13: =$E13+Assumptions!$C$10/100 -> 0.080068443 | I13: =$E13+Assumptions!$C$10/100 -> 0.080068443 | J13: =$E13+Assumptions!$C$10/100 -> 0.080068443 | K13: =K14/Revenue_Build!K7 -> 0.082385633 | L13: =L14/Revenue_Build!L7 -> 0.080068443
A14: G&A (non-GAAP) | B14: Sourced / Derived | C14: =Historical_Drivers!$O$14/1000 -> 28.559 | D14: =Historical_Drivers!$P$14/1000 -> 30.665 | E14: =E8*Historical_Drivers!$P$14/(Historical_Drivers!$P$10+Historical_Drivers!$P$12+Historical_Drivers!$P$14) -> 31.053259 | F14: =F13*Revenue_Build!F7 -> 32.409336 | G14: =G13*Revenue_Build!G7 -> 32.855085 | H14: =H13*Revenue_Build!H7 -> 33.677204 | I14: =I13*Revenue_Build!I7 -> 34.510439 | J14: =J13*Revenue_Build!J7 -> 35.568853 | K14: =SUM(C14:F14) -> 122.68659 | L14: =SUM(G14:J14) -> 136.61158
A15: Total operating expenses (non-GAAP) | B15: Derived | C15: =C10+C12+C14 -> 265.153 | D15: =D10+D12+D14 -> 263.112 | E15: =E10+E12+E14 -> 266.44334 | F15: =F10+F12+F14 -> 278.07876 | G15: =G10+G12+G14 -> 284.02089 | H15: =H10+H12+H14 -> 291.12782 | I15: =I10+I12+I14 -> 298.33085 | J15: =J10+J12+J14 -> 307.48048 | ... L15: =L10+L12+L14 -> 1180.96
A16: Operating income (non-GAAP) | B16: Derived | C16: =C7-C15 -> 49.037 | D16: =D7-D15 -> 61.11 | E16: =E7-E15 -> 69.637 | F16: =F7-F15 -> 72.283098 | G16: =G7-G15 -> 79.621338 | H16: =H7-H15 -> 81.193064 | I16: =I7-I15 -> 82.770916 | J16: =J7-J15 -> 84.865218 | ... L16: =L7-L15 -> 328.45054
A17: Operating margin (non-GAAP) | B17: Derived | C17: =C16/Revenue_Build!C7 -> 0.13960116 | D17: =D16/Revenue_Build!D7 -> 0.16759868 | E17: =E16/Revenue_Build!E7 -> 0.18403866 | F17: =F16/Revenue_Build!F7 -> 0.18303866 | G17: =G16/Revenue_Build!G7 -> 0.19403866 | H17: =H16/Revenue_Build!H7 -> 0.19303866 | I17: =I16/Revenue_Build!I7 -> 0.19203866 | J17: =J16/Revenue_Build!J7 -> 0.19103866 | ... L17: =L16/Revenue_Build!L7 -> 0.19250581
A19: DOWNSIDE (before management response)
A20: Line | B20: Label | C20: Q1 2026A | D20: Q2 2026A | E20: Q3 2026 | F20: Q4 2026 | G20: Q1 2027 | H20: Q2 2027 | I20: Q3 2027 | J20: Q4 2027 | K20: FY2026 | L20: FY2027 | M20: Note
A21: Gross margin (non-GAAP) | B21: Derived (Assumed P3) | C21: =Historical_Drivers!$O$36 -> 0.89445291 | D21: =Historical_Drivers!$P$36 -> 0.88920276 | E21: =D21+Assumptions!$C$7/100 -> 0.88820276 | F21: =E21+Assumptions!$D$7/100 -> 0.88570276 | G21: =F21+Assumptions!$D$7/100 -> 0.88320276 | H21: =G21+Assumptions!$D$7/100 -> 0.88070276 | I21: =H21+Assumptions!$D$7/100 -> 0.87820276 | J21: =I21+Assumptions!$D$7/100 -> 0.87570276
A22: Gross profit (non-GAAP) | B22: Sourced / Derived | C22: =Historical_Drivers!$O$8/1000 -> 314.19 | D22: =Historical_Drivers!$P$8/1000 -> 324.222 | E22: =Revenue_Build!E16*E21 -> 336.08034 | F22: =Revenue_Build!F16*F21 -> 345.41275 | G22: =Revenue_Build!G16*G21 -> 353.41931 | H22: =Revenue_Build!H16*H21 -> 356.6559 | I22: =Revenue_Build!I16*I21 -> 359.81938 | J22: =Revenue_Build!J16*J21 -> 360.47043 | K22: =SUM(C22:F22) -> 1319.9051 | L22: =SUM(G22:J22) -> 1430.365
A23: Q3 2026 total opex implied by the locked call (GP - call op. income) | B23: Derived | E23: =E22-Historical_Drivers!$C$54 -> 266.44334
A24: R&D % of revenue (non-GAAP) | B24: Derived | C24: =C25/Revenue_Build!C16 -> 0.22323032 | D24: =D25/Revenue_Build!D16 -> 0.22764185 | E24: =E25/Revenue_Build!E16 -> 0.22214013 | F24: =F25/Revenue_Build!F16 -> 0.22494202 | G24: =G25/Revenue_Build!G16 -> 0.22266473 | H24: =H25/Revenue_Build!H16 -> 0.22552499 | I24: =I25/Revenue_Build!I16 -> 0.22842279 | J24: =J25/Revenue_Build!J16 -> 0.23433418 | ... L24: =L25/Revenue_Build!L16 -> 0.22778073
A25: R&D (non-GAAP) | B25: Sourced / Derived | C25: =Historical_Drivers!$O$10/1000 -> 78.413 | D25: =Historical_Drivers!$P$10/1000 -> 83.003 | E25: =Opex!E10 -> 84.053927 | F25: =Opex!F10 -> 87.72451 | G25: =Opex!G10 -> 89.100737 | H25: =Opex!H10 -> 91.330267 | I25: =Opex!I10 -> 93.589944 | J25: =Opex!J10 -> 96.460289 | K25: =SUM(C25:F25) -> 333.19444 | L25: =SUM(G25:J25) -> 370.48124
A26: S&M % of revenue (non-GAAP) | B26: Derived | C26: =C27/Revenue_Build!C16 -> 0.45031814 | D26: =D27/Revenue_Build!D16 -> 0.4098612 | E26: =E27/Revenue_Build!E16 -> 0.39995553 | F26: =F27/Revenue_Build!F16 -> 0.40500024 | G26: =G27/Revenue_Build!G16 -> 0.40500423 | H26: =H27/Revenue_Build!H16 -> 0.41020673 | I26: =I27/Revenue_Build!I16 -> 0.41547753 | J26: =J27/Revenue_Build!J16 -> 0.42622974 | ... L26: =L27/Revenue_Build!L16 -> 0.41430969
A27: S&M (non-GAAP) | B27: Sourced / Derived | C27: =Historical_Drivers!$O$12/1000 -> 158.181 | D27: =Historical_Drivers!$P$12/1000 -> 149.444 | E27: =Opex!E12 -> 151.33616 | F27: =Opex!F12 -> 157.94491 | G27: =Opex!G12 -> 162.06507 | H27: =Opex!H12 -> 166.12035 | I27: =Opex!I12 -> 170.23047 | J27: =Opex!J12 -> 175.45133 | K27: =SUM(C27:F27) -> 616.90607 | L27: =SUM(G27:J27) -> 673.86722
A28: G&A % of revenue (non-GAAP) | B28: Derived | C28: =C29/Revenue_Build!C16 -> 0.08130329 | D28: =D29/Revenue_Build!D16 -> 0.084101025 | E28: =E29/Revenue_Build!E16 -> 0.082068443 | F28: =F29/Revenue_Build!F16 -> 0.083103586 | G28: =G29/Revenue_Build!G16 -> 0.082105592 | H28: =H29/Revenue_Build!H16 -> 0.083160285 | I28: =I29/Revenue_Build!I16 -> 0.084228822 | J28: =J29/Revenue_Build!J16 -> 0.086408593 | ... L28: =L29/Revenue_Build!L16 -> 0.083992068
A29: G&A (non-GAAP) | B29: Sourced / Derived | C29: =Historical_Drivers!$O$14/1000 -> 28.559 | D29: =Historical_Drivers!$P$14/1000 -> 30.665 | E29: =Opex!E14 -> 31.053259 | F29: =Opex!F14 -> 32.409336 | G29: =Opex!G14 -> 32.855085 | H29: =Opex!H14 -> 33.677204 | I29: =Opex!I14 -> 34.510439 | J29: =Opex!J14 -> 35.568853 | K29: =SUM(C29:F29) -> 122.68659 | L29: =SUM(G29:J29) -> 136.61158
A30: Total operating expenses (non-GAAP) | B30: Derived | C30: =C25+C27+C29 -> 265.153 | D30: =D25+D27+D29 -> 263.112 | E30: =E25+E27+E29 -> 266.44334 | F30: =F25+F27+F29 -> 278.07876 | G30: =G25+G27+G29 -> 284.02089 | H30: =H25+H27+H29 -> 291.12782 | I30: =I25+I27+I29 -> 298.33085 | J30: =J25+J27+J29 -> 307.48048 | ... L30: =L25+L27+L29 -> 1180.96
A31: Operating income (non-GAAP) | B31: Derived | C31: =C22-C30 -> 49.037 | D31: =D22-D30 -> 61.11 | E31: =E22-E30 -> 69.637 | F31: =F22-F30 -> 67.333992 | G31: =G22-G30 -> 69.398422 | H31: =H22-H30 -> 65.52808 | I31: =I22-I30 -> 61.48853 | J31: =J22-J30 -> 52.989952 | ... L31: =L22-L30 -> 249.40498
A32: Operating margin (non-GAAP) | B32: Derived | C32: =C31/Revenue_Build!C16 -> 0.13960116 | D32: =D31/Revenue_Build!D16 -> 0.16759868 | E32: =E31/Revenue_Build!E16 -> 0.18403866 | F32: =F31/Revenue_Build!F16 -> 0.17265692 | G32: =G31/Revenue_Build!G16 -> 0.17342821 | H32: =H31/Revenue_Build!H16 -> 0.16181075 | I32: =I31/Revenue_Build!I16 -> 0.15007362 | J32: =J31/Revenue_Build!J16 -> 0.12873025 | ... L32: =L31/Revenue_Build!L16 -> 0.15334015
A34: SENSITIVITY: Base with Q3 2026 at the locked call LOW
A35: Line | B35: Label | C35: Q1 2026A | D35: Q2 2026A | E35: Q3 2026 | F35: Q4 2026 | G35: Q1 2027 | H35: Q2 2027 | I35: Q3 2027 | J35: Q4 2027 | K35: FY2026 | L35: FY2027 | M35: Note
A36: Gross margin (non-GAAP) | B36: Derived (Assumed P3) | C36: =Historical_Drivers!$O$36 -> 0.89445291 | D36: =Historical_Drivers!$P$36 -> 0.88920276 | E36: =D36+Assumptions!$C$7/100 -> 0.88820276 | F36: =E36+Assumptions!$C$7/100 -> 0.88720276 | G36: =F36+Assumptions!$C$7/100 -> 0.88620276 | H36: =G36+Assumptions!$C$7/100 -> 0.88520276 | I36: =H36+Assumptions!$C$7/100 -> 0.88420276 | J36: =I36+Assumptions!$C$7/100 -> 0.88320276
A37: Gross profit (non-GAAP) | B37: Sourced / Derived | C37: =Historical_Drivers!$O$8/1000 -> 314.19 | D37: =Historical_Drivers!$P$8/1000 -> 324.222 | E37: =Revenue_Build!E25*E36 -> 332.60624 | F37: =Revenue_Build!F25*F36 -> 346.74012 | G37: =Revenue_Build!G25*G36 -> 359.88321 | H37: =Revenue_Build!H25*H36 -> 368.47216 | I37: =Revenue_Build!I25*I36 -> 373.21404 | J37: =Revenue_Build!J25*J36 -> 384.22524 | K37: =SUM(C37:F37) -> 1317.7584 | L37: =SUM(G37:J37) -> 1485.7946
A38: Q3 2026 total opex implied by the locked call (GP - call op. income) | B38: Derived | E38: =E37-Historical_Drivers!$C$55 -> 269.67524
A39: R&D % of revenue (non-GAAP) | B39: Derived | C39: =C40/Revenue_Build!C25 -> 0.22323032 | D39: =D40/Revenue_Build!D25 -> 0.22764185 | E39: =E40/Revenue_Build!E25 -> 0.22718305 | F39: =Opex!F9 -> 0.22214013 | G39: =Opex!G9 -> 0.21714013 | H39: =Opex!H9 -> 0.21714013 | I39: =Opex!I9 -> 0.21714013 | J39: =Opex!J9 -> 0.21714013 | K39: =K40/Revenue_Build!K25 -> 0.22502797 | L39: =L40/Revenue_Build!L25 -> 0.21714013
A40: R&D (non-GAAP) | B40: Sourced / Derived | C40: =Historical_Drivers!$O$10/1000 -> 78.413 | D40: =Historical_Drivers!$P$10/1000 -> 83.003 | E40: =E38*Historical_Drivers!$P$10/(Historical_Drivers!$P$10+Historical_Drivers!$P$12+Historical_Drivers!$P$14) -> 85.073481 | F40: =F39*Revenue_Build!F25 -> 86.81769 | G40: =G39*Revenue_Build!G25 -> 88.179691 | H40: =H39*Revenue_Build!H25 -> 90.386174 | I40: =I39*Revenue_Build!I25 -> 91.652895 | J40: =J39*Revenue_Build!J25 -> 94.463833 | K40: =SUM(C40:F40) -> 333.30717 | L40: =SUM(G40:J40) -> 364.68259
A41: S&M % of revenue (non-GAAP) | B41: Derived | C41: =C42/Revenue_Build!C25 -> 0.45031814 | D41: =D42/Revenue_Build!D25 -> 0.4098612 | E41: =E42/Revenue_Build!E25 -> 0.40903515 | F41: =Opex!F11 -> 0.39995553 | G41: =Opex!G11 -> 0.39495553 | H41: =Opex!H11 -> 0.39495553 | I41: =Opex!I11 -> 0.39495553 | J41: =Opex!J11 -> 0.39495553 | K41: =K42/Revenue_Build!K25 -> 0.41663309 | L41: =L42/Revenue_Build!L25 -> 0.39495553
A42: S&M (non-GAAP) | B42: Sourced / Derived | C42: =Historical_Drivers!$O$12/1000 -> 158.181 | D42: =Historical_Drivers!$P$12/1000 -> 149.444 | E42: =E38*Historical_Drivers!$P$12/(Historical_Drivers!$P$10+Historical_Drivers!$P$12+Historical_Drivers!$P$14) -> 153.17183 | F42: =F41*Revenue_Build!F25 -> 156.31222 | G42: =G41*Revenue_Build!G25 -> 160.38978 | H42: =H41*Revenue_Build!H25 -> 164.40314 | I42: =I41*Revenue_Build!I25 -> 166.70718 | J42: =J41*Revenue_Build!J25 -> 171.81998 | K42: =SUM(C42:F42) -> 617.10905 | L42: =SUM(G42:J42) -> 663.32009
A43: G&A % of revenue (non-GAAP) | B43: Derived | C43: =C44/Revenue_Build!C25 -> 0.08130329 | D43: =D44/Revenue_Build!D25 -> 0.084101025 | E43: =E44/Revenue_Build!E25 -> 0.083931525 | F43: =Opex!F13 -> 0.082068443 | G43: =Opex!G13 -> 0.080068443 | H43: =Opex!H13 -> 0.080068443 | I43: =Opex!I13 -> 0.080068443 | J43: =Opex!J13 -> 0.080068443 | K43: =K44/Revenue_Build!K25 -> 0.082858367 | L43: =L44/Revenue_Build!L25 -> 0.080068443
...

Sheet PnL
A1: P&L: non-GAAP with GAAP bridge (SBC, restructuring)
A2: USD millions.
A4: BASE
A5: Line | B5: Label | C5: Q1 2026A | D5: Q2 2026A | E5: Q3 2026 | F5: Q4 2026 | G5: Q1 2027 | H5: Q2 2027 | I5: Q3 2027 | J5: Q4 2027 | K5: FY2026 | L5: FY2027 | M5: Note
A6: Revenue | B6: Derived (link) | C6: =Revenue_Build!C7 -> 351.265 | D6: =Revenue_Build!D7 -> 364.621 | E6: =Revenue_Build!E7 -> 378.38246 | F6: =Revenue_Build!F7 -> 394.90618 | G6: =Revenue_Build!G7 -> 410.3375 | H6: =Revenue_Build!H7 -> 420.6052 | I6: =Revenue_Build!I7 -> 431.01174 | J6: =Revenue_Build!J7 -> 444.2306 | ... L6: =Revenue_Build!L7 -> 1706.185
A7: Gross profit (non-GAAP) | B7: Derived (link) | C7: =Opex!C7 -> 314.19 | D7: =Opex!D7 -> 324.222 | E7: =Opex!E7 -> 336.08034 | F7: =Opex!F7 -> 350.36186 | G7: =Opex!G7 -> 363.64223 | H7: =Opex!H7 -> 372.32089 | I7: =Opex!I7 -> 381.10177 | J7: =Opex!J7 -> 392.34569 | ... L7: =Opex!L7 -> 1509.4106
A8: R&D (non-GAAP) | B8: Derived (link) | C8: =Opex!C10 -> 78.413 | D8: =Opex!D10 -> 83.003 | E8: =Opex!E10 -> 84.053927 | F8: =Opex!F10 -> 87.72451 | G8: =Opex!G10 -> 89.100737 | H8: =Opex!H10 -> 91.330267 | I8: =Opex!I10 -> 93.589944 | J8: =Opex!J10 -> 96.460289 | ... L8: =Opex!L10 -> 370.48124
A9: S&M (non-GAAP) | B9: Derived (link) | C9: =Opex!C12 -> 158.181 | D9: =Opex!D12 -> 149.444 | E9: =Opex!E12 -> 151.33616 | F9: =Opex!F12 -> 157.94491 | G9: =Opex!G12 -> 162.06507 | H9: =Opex!H12 -> 166.12035 | I9: =Opex!I12 -> 170.23047 | J9: =Opex!J12 -> 175.45133 | ... L9: =Opex!L12 -> 673.86722
A10: G&A (non-GAAP) | B10: Derived (link) | C10: =Opex!C14 -> 28.559 | D10: =Opex!D14 -> 30.665 | E10: =Opex!E14 -> 31.053259 | F10: =Opex!F14 -> 32.409336 | G10: =Opex!G14 -> 32.855085 | H10: =Opex!H14 -> 33.677204 | I10: =Opex!I14 -> 34.510439 | J10: =Opex!J14 -> 35.568853 | ... L10: =Opex!L14 -> 136.61158
A11: Operating income (non-GAAP) | B11: Derived (link) | C11: =Opex!C16 -> 49.037 | D11: =Opex!D16 -> 61.11 | E11: =Opex!E16 -> 69.637 | F11: =Opex!F16 -> 72.283098 | G11: =Opex!G16 -> 79.621338 | H11: =Opex!H16 -> 81.193064 | I11: =Opex!I16 -> 82.770916 | J11: =Opex!J16 -> 84.865218 | ... L11: =Opex!L16 -> 328.45054
A12: Operating margin (non-GAAP) | B12: Derived | C12: =C11/C6 -> 0.13960116 | D12: =D11/D6 -> 0.16759868 | E12: =E11/E6 -> 0.18403866 | F12: =F11/F6 -> 0.18303866 | G12: =G11/G6 -> 0.19403866 | H12: =H11/H6 -> 0.19303866 | I12: =I11/I6 -> 0.19203866 | J12: =J11/J6 -> 0.19103866 | ... L12: =L11/L6 -> 0.19250581
A13: Less: share-based compensation | B13: Sourced / Derived (Assumed P9) | C13: =Historical_Drivers!$O$20/1000 -> 29.283 | D13: =Historical_Drivers!$P$20/1000 -> 41.218 | E13: =Assumptions!$C$13*E6 -> 39.730158 | F13: =Assumptions!$C$13*F6 -> 41.465149 | G13: =Assumptions!$C$13*G6 -> 43.085438 | H13: =Assumptions!$C$13*H6 -> 44.163546 | I13: =Assumptions!$C$13*I6 -> 45.256233 | J13: =Assumptions!$C$13*J6 -> 46.644213 | K13: =SUM(C13:F13) -> 151.69631 | L13: =SUM(G13:J13) -> 179.14943
A14: Less: restructuring charges (GAAP) | B14: Sourced / Derived (Assumed P10) | C14: =(Historical_Drivers!$C$60-Historical_Drivers!$P$22)/1000 -> 0 | D14: =Historical_Drivers!$P$22/1000 -> 21.436 | E14: =Assumptions!$C$14/2 -> 25 | F14: =Assumptions!$C$14/2 -> 25 | G14: =0*1 -> 0 | H14: =0*1 -> 0 | I14: =0*1 -> 0 | J14: =0*1 -> 0 | K14: =SUM(C14:F14) -> 71.436 | L14: =SUM(G14:J14) -> 0 | M14: Q1 2026 = H1 less Q2 (Derived; line first reported Q2 2026); Q2 2026: Israel office impairment; H2 2026: plan estimate midpoint
