Workbook

Sheet README
A1: monday.com - Phase 3a Driver Evidence Audit (no operating model)
A3: Purpose | B3: Assess which planning drivers the public evidence supports, backtest the two candidate revenue methods, and PROPOSE assumption paths (Q3 2026-Q4 2027, Base and Downside) for owner approval. No operating model is built.
A4: Information cutoff | B4: October 28, 2026. Inputs come only from monday_sourcebook.xlsx (Row IDs) and the locked Q3 call (monday_q3_call.xlsx, release q3-2026-call-locked); none of those workbooks is modified.
A5: Labels | B5: Sourced = blue copy with Row ID/cell reference; Derived = black formula; Assumed = orange (proposals only, on Proposed_Assumptions). Header row 2 of each table states the label of every cell in that column.
A6: Status of proposals | B6: PROPOSED, NOT FINAL. They require owner approval before the Phase 3 model is built.
A7: Sheets | B7: Driver_Map, Revenue_Backtest, Proposed_Assumptions, Series (copied inputs and derived helper columns), Checks.

Sheet Driver_Map
A1: Driver map: what history exists for each planning driver, comparability, and whether it can support a forecast
A3: Driver | B3: Historical series available (Series sheet column / source) | C3: Quarters with data | D3: First / last quarter | E3: Comparability problems | F3: Verdict | G3: Reason | H3: Evidence row IDs (examples)
A4: Text | B4: Text | C4: Derived (COUNT) | D4: Text | E4: Text | F4: Assessment (text) | G4: Text | H4: Text
A5: Revenue growth | B5: Revenue (Series col for Revenue); guidance low/high | C5: =COUNT(Series!B6:B27) -> 22 | D5: Q1 2021 / Q2 2026 | E5: None material for revenue itself; FX impact disclosed only for some quarters; 2021 YoY not computable (2020 not in source book). | F5: Supported | G5: 22 quarters of revenue plus 20 guidance vintages; backtest shows guidance-anchored and trend methods within ~1% MAPE. | H5: QA-0001..QA-0037; GH revenue rows
A6: Net dollar retention (all customers) | B6: NDR all customers, exact values only | C6: =COUNT(Series!V6:V27) -> 11 | D6: Q4 2023 / Q2 2026 | E6: Floors ("over X%") before Q4 2023 excluded; measurement basis (point vs trailing 12-month) not stated; 2024-H1 2025 pricing adjustments flattered NDR; ARR-based, not revenue-based. | F6: Partially supported | G6: Only 11 exact quarters; basis unresolved; method A (NDR-based revenue) is biased high in the backtest. Usable as a scenario driver and cross-check, not as the revenue engine. | H6: QA KPI NDR rows; source-book Definitions
A7: Customer counts and net adds (>$50k, >$100k) | B7: Customers >$50k and >$100k ARR; net adds derived | C7: =COUNT(Series!X6:X27) -> 22 | D7: Q1 2021 / Q2 2026 (>$100k from Q4 2022) | E7: Point-in-time counts; nominal USD thresholds (FX and pricing move customers across); no gross adds or churn. | F7: Supported | G7: >$50k disclosed every quarter (22); net adds derivable; descriptive driver for a customer cross-check only. | H7: QA KPI customer rows
A8: cRPO / RPO | B8: RPO (from Sept 2024) and cRPO (from Dec 2024), release values | C8: =COUNT(Series!AD6:AD27) -> 6 | D8: Q4 2024 / Q2 2026 (gap at Q3 2025) | E8: Not disclosed before 2024 (ASC 606 expedient); June 2025 RPO recast without explanation; no Q3 cRPO observation. | F8: Not supported | G8: Six cRPO points with a gap and a recast; too sparse for a driver. Cross-check only. | H8: QA RPO/cRPO rows; source-book D4/R2
A9: Gross margin (non-GAAP) | B9: Gross profit (non-GAAP) / revenue | C9: =COUNT(Series!D6:D27) -> 22 | D9: Q1 2021 / Q2 2026 | E9: Company expects a modest mid-term decline from AI compute costs (FY2025 20-F); no product split. | F9: Supported | G9: 22 quarters in a narrow band (88.8%-90.7%); trend and company statement give a direction. | H9: QA gross profit rows; source-book Definitions (cost of revenue)
A10: R&D % of revenue (non-GAAP) | B10: R&D (non-GAAP) / revenue | C10: =COUNT(Series!F6:F27) -> 22 | D10: Q1 2021 / Q2 2026 | E10: Rising since 2025 (AI investment); restructuring from July 2026 will change the run-rate; quarter-specific savings not disclosed. | F10: Supported | G10: 22 comparable quarters; the post-restructuring level is an assumption. | H10: QA R&D non-GAAP rows
A11: S&M % of revenue (non-GAAP) | B11: S&M (non-GAAP) / revenue; post-commission-change quarters only (Q1 2025 onward) | C11: =COUNT(Series!H22:H27) -> 6 | D11: Q1 2025 / Q2 2026 | E11: FY2025 commission model change (commissions ~5% -> ~2% of revenue, more capitalized): pre-2025 quarters not comparable; restructuring affects go-to-market. | F11: Partially supported | G11: Only 6 comparable quarters. | H11: QA S&M non-GAAP rows; AN-0348..AN-0350; AN-2430
A12: G&A % of revenue (non-GAAP) | B12: G&A (non-GAAP) / revenue | C12: =COUNT(Series!J6:J27) -> 22 | D12: Q1 2021 / Q2 2026 | E12: Foundation charitable contribution excluded from non-GAAP in Q3 2024 (handled by the company reconciliation). | F12: Supported | G12: Stable 8.1%-8.9% over the last 8 quarters. | H12: QA G&A non-GAAP rows
A13: FCF conversion (adj. FCF / non-GAAP op. income) | B13: Adjusted FCF / FCF and non-GAAP operating income | C13: =COUNT(Series!P6:P27) -> 22 | D13: Q1 2021 / Q2 2026 (ratio meaningful from Q4 2022) | E13: FCF label and add-back scope changed (2021-22, 2023-24, 2025+); ratio fell from 2.0-4.2x (2023-24) to 0.86x (Q2 2026); drivers (interest income, commission capitalization, working capital) not itemized. | F13: Partially supported | G13: Seasonality exists but the level has shifted; historical ratios do not explain the FY2026 guide (which implies ~1.2x). | H13: QA FCF and op. income rows; GH-0098, GH-0099
A14: SBC (GAAP bridge) | B14: SBC total (non-GAAP reconciliation) / revenue | C14: =COUNT(Series!N6:N27) -> 22 | D14: Q1 2021 / Q2 2026 | E14: July 2026 plan expects ~$15M non-cash SBC credits; foundation share grants (2024) shown separately. | F14: Supported | G14: 22 quarters; ratio range is wide but stable in recent quarters. | H14: QA SBC rows; 6K-20260722-RESTR (Annual)
A15: Restructuring savings | B15: None disclosed in USD; only ~20% workforce reduction and charge estimates | C15: n/a | D15: July 22, 2026 6-K | E15: No savings amount, no headcount base at July 2026, no timing of exits. | F15: Not supported | G15: Savings can only be inferred indirectly from the FY margin guide raise (~13% -> ~15% -> ~16%); any figure is an assumption. | H15: GH-0095..GH-0099; Annual restructuring rows (6K-20260722-RESTR)
A16: Severance cash | B16: Estimate range only: ~$30-35M severance/benefits (not labelled cash) | C16: n/a | D16: July 22, 2026 6-K | E16: Whether included in the FY adjusted FCF guide is not stated. | F16: Partially supported | G16: Range disclosed; timing and cash nature assumed. | H16: Annual restructuring rows (6K-20260722-RESTR)
A17: Cash balance | B17: Cash and equivalents; marketable securities | C17: =COUNT(Series!R6:R27) -> 22 | D17: Q1 2021 / Q2 2026 (securities from Q4 2023) | E17: Buyback authorization ($870M) fully used by Q2 2026; no new program disclosed. | F17: Supported | G17: Point-in-time balances every quarter. | H17: QA cash and securities rows
A18: Interest income | B18: Not carried in the source book (financial income appears only inside net income) | C18: n/a | D18: n/a | E18: Financial income is in the release income statements but was not extracted as a source-book row. | F18: Not supported | G18: Cannot be projected from the source book without extending it (a Phase 0 change). | H18: n/a
A19: Headcount (memo for hiring decision) | B19: Year-end employees only (20-F); ~20% reduction (July 2026) | C19: n/a | D19: FY2021-FY2025 year-end | E19: No quarterly headcount; no department split by quarter; reduction base unknown. | F19: Not supported | G19: Implied headcount must use an Assumed fully loaded cost per head. | H19: Annual employee rows (20F-FY2021..FY2025)

Sheet Revenue_Backtest
A1: Revenue backtest: rolling one-step-ahead forecasts, last 8 quarters (Q3 2024-Q2 2026), using only data available after the prior quarter's release
A2: Method A: forecast YoY growth = (NDR at t - 1) + mean residual of the last up-to-4 quarters with an EXACT NDR (residual = YoY growth - (NDR - 1)); forecast = same quarter last year x (1 + forecast YoY). Method B-guide: next-quarter guidance midpoint x (1 + median % beat of the 8 prior quarters). Method B-trend (no guidance): latest quarter revenue x (1 + latest QoQ growth + average quarterly change in QoQ growth over the prior 4 quarters).
A4: Forecast quarter | B4: Actual revenue (USD m) | C4: A forecast | D4: A error (USD m) | E4: A error % | F4: B-guide forecast | G4: B-guide error (USD m) | H4: B-guide error % | I4: B-trend forecast | J4: B-trend error (USD m) | K4: B-trend error % | L4: Data used for A (available at t) | M4: Data used for B-guide | N4: Data used for B-trend
A5: Text / label | B5: Derived (Series /1000) | C5: Derived | D5: Derived | E5: Derived | F5: Derived | G5: Derived | H5: Derived | I5: Derived | J5: Derived | K5: Derived | L5: Text | M5: Text | N5: Text
A6: Q3 2024 | B6: =Series!B20/1000 -> 251 | C6: =Series!B16/1000*(1+(Series!V19-1)+AVERAGE(Series!AK16:AK19)) -> 254.2712 | D6: =C6-B6 -> 3.2711978 | E6: =C6/B6-1 -> 0.01303266 | F6: =Series!AL20*(1+MEDIAN(Series!AM12:AM19)) -> 254.68071 | G6: =F6-B6 -> 3.6807101 | H6: =F6/B6-1 -> 0.014664184 | I6: =Series!B19/1000*(1+Series!AJ19+(Series!AJ19-Series!AJ15)/4) -> 257.33695 | J6: =I6-B6 -> 6.3369526 | K6: =I6/B6-1 -> 0.025246823 | L6: Revenue Q3 2023 (same quarter last year); NDR Q2 2024; residuals for Q4 2023, Q1 2024, Q2 2024 (3 quarters with exact NDR; floors excluded). | M6: Guidance for Q3 2024 (issued with the Q2 2024 release); % beats Q3 2022-Q2 2024 (8 quarters). | N6: Revenue Q2 2024; QoQ growth Q2 2024 and Q2 2023.
A7: Q4 2024 | B7: =Series!B21/1000 -> 267.976 | C7: =Series!B17/1000*(1+(Series!V20-1)+AVERAGE(Series!AK17:AK20)) -> 272.89754 | D7: =C7-B7 -> 4.921545 | E7: =C7/B7-1 -> 0.018365619 | F7: =Series!AL21*(1+MEDIAN(Series!AM13:AM20)) -> 271.09636 | G7: =F7-B7 -> 3.1203594 | H7: =F7/B7-1 -> 0.011644175 | I7: =Series!B20/1000*(1+Series!AJ20+(Series!AJ20-Series!AJ16)/4) -> 265.96599 | J7: =I7-B7 -> -2.0100079 | K7: =I7/B7-1 -> -0.007500701 | L7: Revenue Q4 2023 (same quarter last year); NDR Q3 2024; residuals for Q4 2023, Q1 2024, Q2 2024, Q3 2024 (4 quarters with exact NDR; floors excluded). | M7: Guidance for Q4 2024 (issued with the Q3 2024 release); % beats Q4 2022-Q3 2024 (8 quarters). | N7: Revenue Q3 2024; QoQ growth Q3 2024 and Q3 2023.
A8: Q1 2025 | B8: =Series!B22/1000 -> 282.25 | C8: =Series!B18/1000*(1+(Series!V21-1)+AVERAGE(Series!AK18:AK21)) -> 291.77015 | D8: =C8-B8 -> 9.5201492 | E8: =C8/B8-1 -> 0.033729492 | F8: =Series!AL22*(1+MEDIAN(Series!AM14:AM21)) -> 285.09441 | G8: =F8-B8 -> 2.8444079 | H8: =F8/B8-1 -> 0.010077619 | I8: =Series!B21/1000*(1+Series!AJ21+(Series!AJ21-Series!AJ17)/4) -> 285.8932 | J8: =I8-B8 -> 3.6431954 | K8: =I8/B8-1 -> 0.01290769 | L8: Revenue Q1 2024 (same quarter last year); NDR Q4 2024; residuals for Q1 2024, Q2 2024, Q3 2024, Q4 2024 (4 quarters with exact NDR; floors excluded). | M8: Guidance for Q1 2025 (issued with the Q4 2024 release); % beats Q1 2023-Q4 2024 (8 quarters). | N8: Revenue Q4 2024; QoQ growth Q4 2024 and Q4 2023.
A9: Q2 2025 | B9: =Series!B23/1000 -> 299.014 | C9: =Series!B19/1000*(1+(Series!V22-1)+AVERAGE(Series!AK19:AK22)) -> 314.30225 | D9: =C9-B9 -> 15.288246 | E9: =C9/B9-1 -> 0.051128863 | F9: =Series!AL23*(1+MEDIAN(Series!AM15:AM22)) -> 302.35062 | G9: =F9-B9 -> 3.3366179 | H9: =F9/B9-1 -> 0.011158735 | I9: =Series!B22/1000*(1+Series!AJ22+(Series!AJ22-Series!AJ18)/4) -> 296.04671 | J9: =I9-B9 -> -2.9672907 | K9: =I9/B9-1 -> -0.0099235845 | L9: Revenue Q2 2024 (same quarter last year); NDR Q1 2025; residuals for Q2 2024, Q3 2024, Q4 2024, Q1 2025 (4 quarters with exact NDR; floors excluded). | M9: Guidance for Q2 2025 (issued with the Q1 2025 release); % beats Q2 2023-Q1 2025 (8 quarters). | N9: Revenue Q1 2025; QoQ growth Q1 2025 and Q1 2024.
A10: Q3 2025 | B10: =Series!B24/1000 -> 316.855 | C10: =Series!B20/1000*(1+(Series!V23-1)+AVERAGE(Series!AK20:AK23)) -> 326.12695 | D10: =C10-B10 -> 9.2719454 | E10: =C10/B10-1 -> 0.029262424 | F10: =Series!AL24*(1+MEDIAN(Series!AM16:AM23)) -> 320.58032 | G10: =F10-B10 -> 3.7253246 | H10: =F10/B10-1 -> 0.011757191 | I10: =Series!B23/1000*(1+Series!AJ23+(Series!AJ23-Series!AJ19)/4) -> 314.59923 | J10: =I10-B10 -> -2.2557705 | K10: =I10/B10-1 -> -0.0071192517 | L10: Revenue Q3 2024 (same quarter last year); NDR Q2 2025; residuals for Q3 2024, Q4 2024, Q1 2025, Q2 2025 (4 quarters with exact NDR; floors excluded). | M10: Guidance for Q3 2025 (issued with the Q2 2025 release); % beats Q3 2023-Q2 2025 (8 quarters). | N10: Revenue Q2 2025; QoQ growth Q2 2025 and Q2 2024.
A11: Q4 2025 | B11: =Series!B25/1000 -> 333.878 | C11: =Series!B21/1000*(1+(Series!V24-1)+AVERAGE(Series!AK21:AK24)) -> 343.87378 | D11: =C11-B11 -> 9.9957757 | E11: =C11/B11-1 -> 0.029938408 | F11: =Series!AL25*(1+MEDIAN(Series!AM17:AM24)) -> 337.73357 | G11: =F11-B11 -> 3.8555691 | H11: =F11/B11-1 -> 0.011547838 | I11: =Series!B24/1000*(1+Series!AJ24+(Series!AJ24-Series!AJ20)/4) -> 335.48993 | J11: =I11-B11 -> 1.6119299 | K11: =I11/B11-1 -> 0.0048279008 | L11: Revenue Q4 2024 (same quarter last year); NDR Q3 2025; residuals for Q4 2024, Q1 2025, Q2 2025, Q3 2025 (4 quarters with exact NDR; floors excluded). | M11: Guidance for Q4 2025 (issued with the Q3 2025 release); % beats Q4 2023-Q3 2025 (8 quarters). | N11: Revenue Q3 2025; QoQ growth Q3 2025 and Q3 2024.
A12: Q1 2026 | B12: =Series!B26/1000 -> 351.265 | C12: =Series!B22/1000*(1+(Series!V25-1)+AVERAGE(Series!AK22:AK25)) -> 355.34909 | D12: =C12-B12 -> 4.0840881 | E12: =C12/B12-1 -> 0.011626801 | F12: =Series!AL26*(1+MEDIAN(Series!AM18:AM25)) -> 347.61966 | G12: =F12-B12 -> -3.6453432 | H12: =F12/B12-1 -> -0.010377758 | I12: =Series!B25/1000*(1+Series!AJ25+(Series!AJ25-Series!AJ21)/4) -> 350.65462 | J12: =I12-B12 -> -0.6103831 | K12: =I12/B12-1 -> -0.0017376713 | L12: Revenue Q1 2025 (same quarter last year); NDR Q4 2025; residuals for Q1 2025, Q2 2025, Q3 2025, Q4 2025 (4 quarters with exact NDR; floors excluded). | M12: Guidance for Q1 2026 (issued with the Q4 2025 release); % beats Q1 2024-Q4 2025 (8 quarters). | N12: Revenue Q4 2025; QoQ growth Q4 2025 and Q4 2024.
A13: Q2 2026 | B13: =Series!B27/1000 -> 364.621 | C13: =Series!B23/1000*(1+(Series!V26-1)+AVERAGE(Series!AK23:AK26)) -> 373.71162 | D13: =C13-B13 -> 9.0906179 | E13: =C13/B13-1 -> 0.02493169 | F13: =Series!AL27*(1+MEDIAN(Series!AM19:AM26)) -> 364.02648 | G13: =F13-B13 -> -0.59451577 | H13: =F13/B13-1 -> -0.0016305034 | I13: =Series!B26/1000*(1+Series!AJ26+(Series!AJ26-Series!AJ22)/4) -> 369.45294 | J13: =I13-B13 -> 4.8319375 | K13: =I13/B13-1 -> 0.013251945 | L13: Revenue Q2 2025 (same quarter last year); NDR Q1 2026; residuals for Q2 2025, Q3 2025, Q4 2025, Q1 2026 (4 quarters with exact NDR; floors excluded). | M13: Guidance for Q2 2026 (issued with the Q1 2026 release); % beats Q2 2024-Q1 2026 (8 quarters). | N13: Revenue Q1 2026; QoQ growth Q1 2026 and Q1 2025.
A15: Summary (Derived)
A16: Statistic | B16: Method A | C16: Method B-guide | D16: Method B-trend
A17: Text | B17: Derived | C17: Derived | D17: Derived
A18: Mean error % (bias; + = forecast too high) | B18: =AVERAGE(E6:E13) -> 0.026501995 | C18: =AVERAGE(H6:H13) -> 0.0073551849 | D18: =AVERAGE(K6:K13) -> 0.0037441438
A19: Mean absolute error % | B19: =SUMPRODUCT(ABS(E6:E13))/COUNT(E6:E13) -> 0.026501995 | C19: =SUMPRODUCT(ABS(H6:H13))/COUNT(H6:H13) -> 0.01035725 | D19: =SUMPRODUCT(ABS(K6:K13))/COUNT(K6:K13) -> 0.010314446
A20: Mean error (USD m) | B20: =AVERAGE(D6:D13) -> 8.1804456 | C20: =AVERAGE(G6:G13) -> 2.0403912 | D20: =AVERAGE(J6:J13) -> 1.0725704
A21: Max absolute error % | B21: =MAX(MAX(E6:E13),-MIN(E6:E13)) -> 0.051128863 | C21: =MAX(MAX(H6:H13),-MIN(H6:H13)) -> 0.014664184 | D21: =MAX(MAX(K6:K13),-MIN(K6:K13)) -> 0.025246823
A22: Quarters forecast too high (of 8) | B22: =COUNTIF(E6:E13,">0") -> 8 | C22: =COUNTIF(H6:H13,">0") -> 6 | D22: =COUNTIF(K6:K13,">0") -> 4
A24: Conclusion
A25: Conclusion: use Method B. Method A (NDR-implied existing-customer growth plus a residual new-customer contribution) over-forecast revenue in all 8 quarters (mean error +2.6%, worst +5.1%): its NDR input is ARR-based, its residual rests on only 3-4 exact-NDR quarters, and the NDR basis (point-in-time vs trailing) is not disclosed. Method B-guide (guidance midpoint plus median prior beat) had a mean absolute error of 1.0% and a max error of 1.5% but a slight upward bias (+0.7%, 6 of 8 too high); Method B-trend (sequential growth with the recent deceleration, no guidance) also had a 1.0% mean absolute error, a smaller bias (+0.4%, 4 of 8 too high) and a larger max error (2.5%). For the plan: anchor quarters covered by guidance to guidance (Q3 2026 is the locked call), and project later quarters with the sequential-deceleration form. Caveat: this is a one-step-ahead test; multi-quarter accuracy (relevant for 2027) is not tested here. NDR remains a cross-check and Downside driver, not the revenue engine.

Sheet Proposed_Assumptions
A1: PROPOSED assumptions for owner approval (Q3 2026-Q4 2027, Base and Downside) - NOT FINAL; no operating model is built here
A2: Orange = Assumed parameter (proposal). Black = Derived from the parameter by formula. Blue = Sourced copy (current level or locked Q3 call). Base is the central estimate; Downside = faster growth slowdown + NDR toward ~105%. | S2: Parameter | T2: Base | U2: Downside | V2: Evidence / rationale
S3: Text | T3: Assumed | U3: Assumed | V3: Text
A4: Driver | B4: Case | C4: Current level | D4: Current: quarter | E4: Current: Row ID / ref | F4: Q3 2026 | G4: Q4 2026 | H4: Q1 2027 | I4: Q2 2027 | J4: Q3 2027 | K4: Q4 2027 | L4: Assumed parameter(s) | M4: Rationale | N4: Evidence row IDs | O4: Sensitivity | P4: Depends on unresolved item | Q4: Row label | S4: Annual deceleration of same-quarter sequential revenue growth (pp) | T4: 1.3 | U4: 2.6 | V4: Average QoQ fell ~1.6 pp from 2024 to 2025 and ~1.1 pp from H1 2025 to H1 2026 (Series QoQ column); Base = ~mean; Downside = double.
A5: Text | B5: Text | C5: Sourced / Derived | D5: Text | E5: Source-book Row ID | F5: Assumed / Derived | G5: Assumed / Derived | H5: Assumed / Derived | I5: Assumed / Derived | J5: Assumed / Derived | K5: Assumed / Derived | L5: Assumed | M5: Text | N5: Text | O5: Text | P5: Text | Q5: Text | S5: Q4 2026 sequential revenue growth | T5: =((T19+T20)/2*1000-T27-(T21+T22)/2*1000)/((T21+T22)/2*1000)-1 -> 0.043669377 | U5: =T5-T4/100 -> 0.030669377 | V5: Base: guidance-implied Q4/Q3 sequential (FY guide mid - H1 actual - Q3 guide mid, vs Q3 guide mid) - Derived; Downside: Base minus 1.3 pp.
A6: Revenue sequential growth | B6: Base | C6: =Series!AJ27 -> 0.038022576 | D6: Q2 2026 | E6: Series QoQ (from QA-0037) | G6: =$T$5 -> 0.043669377 | H6: =Series!AJ26-$T$4/100 -> 0.039075908 | I6: =Series!AJ27-$T$4/100 -> 0.025022576 | J6: =F7*1000/Series!B27-1-$T$4/100 -> 0.024741815 | K6: =G6-$T$4/100 -> 0.030669377 | L6: Annual deceleration parameter; Q4 2026 seq | M6: Method B (supported by the backtest): same-quarter sequential growth of 2026 less an annual deceleration; Q4 2026 anchored to the guidance-implied seasonal step. | N6: Series QoQ column; GH-0100, GH-0102; QA-0036, QA-0037 | O6: +/-0.5 pp annual deceleration changes FY2027 revenue by about -/+ $9M (Derived estimate in the operating model). | Q6: Derived from Assumed parameters | S6: NDR change per quarter after Q3 2026 (pp) | T6: -0.25 | U6: -0.4 | V6: Last-4 average change -0.5 pp included the pricing anniversary; Base halves it; Downside reaches ~105% by Q4 2027 from the Q3 call low (107%).
A7: Revenue (USD m) | B7: Base | C7: =Series!B27/1000 -> 364.621 | D7: Q2 2026 | E7: QA-0037 | F7: 378.38246 | G7: =F7*(1+G6) -> 394.90618 | H7: =G7*(1+H6) -> 410.3375 | I7: =H7*(1+I6) -> 420.6052 | J7: =I7*(1+J6) -> 431.01174 | K7: =J7*(1+K6) -> 444.2306 | L7: Q3 2026 = locked call MID | M7: Q3 2026 is not re-derived: it is the locked call (Base = MID, Downside = LOW). Later quarters compound the sequential path above. | N7: monday_q3_call.xlsx Revenue!D55 | O7: See sequential growth row. | P7: Downside interacts with NDR (not mechanically linked; see Revenue_Backtest). | Q7: Sourced (Q3 call) then Derived | S7: Net adds of customers >$50k per quarter | T7: 276.5 | U7: 194 | V7: Base = median of last 8 quarters (as in the locked call); Downside = minimum of last 8.
A8: Revenue sequential growth | B8: Downside | C8: =Series!AJ27 -> 0.038022576 | D8: Q2 2026 | E8: Series QoQ (from QA-0037) | G8: =$U$5 -> 0.030669377 | H8: =Series!AJ26-$U$4/100 -> 0.026075908 | I8: =Series!AJ27-$U$4/100 -> 0.012022576 | J8: =F9*1000/Series!B27-1-$U$4/100 -> 0.0010145436 | K8: =G8-$U$4/100 -> 0.0046693767 | L8: Annual deceleration parameter; Q4 2026 seq | M8: Method B (supported by the backtest): same-quarter sequential growth of 2026 less an annual deceleration; Q4 2026 anchored to the guidance-implied seasonal step. | N8: Series QoQ column; GH-0100, GH-0102; QA-0036, QA-0037 | O8: +/-0.5 pp annual deceleration changes FY2027 revenue by about -/+ $9M (Derived estimate in the operating model). | Q8: Derived from Assumed parameters | S8: Non-GAAP gross margin change per quarter (pp) | T8: -0.1 | U8: -0.25 | V8: Company expects a modest mid-term decline from AI compute (FY2025 20-F); last 4 quarters 89.6% -> 88.9%.
A9: Revenue (USD m) | B9: Downside | C9: =Series!B27/1000 -> 364.621 | D9: Q2 2026 | E9: QA-0037 | F9: 374.47107 | G9: =F9*(1+G8) -> 385.95586 | H9: =G9*(1+H8) -> 396.02001 | I9: =H9*(1+I8) -> 400.78119 | J9: =I9*(1+J8) -> 401.1878 | K9: =J9*(1+K8) -> 403.0611 | L9: Q3 2026 = locked call LOW | M9: Q3 2026 is not re-derived: it is the locked call (Base = MID, Downside = LOW). Later quarters compound the sequential path above. | N9: monday_q3_call.xlsx Revenue!C55 | O9: See sequential growth row. | P9: Downside interacts with NDR (not mechanically linked; see Revenue_Backtest). | Q9: Sourced (Q3 call) then Derived | S9: R&D % rev change in 2027 vs Q3 2026 implied (pp) | T9: -0.5 | U9: 0 | V9: Restructuring (~20% of workforce) partly offset by "continue hiring in key strategic areas"; Downside: no change in % before management action is modeled (opex $ held, see note).
A10: NDR - all customers | B10: Base | C10: =Series!V27 -> 1.09 | D10: Q2 2026 | E10: QA-1320 | F10: 1.085 | G10: =F10+$T$6/100 -> 1.0825 | H10: =G10+$T$6/100 -> 1.08 | I10: =H10+$T$6/100 -> 1.0775 | J10: =I10+$T$6/100 -> 1.075 | K10: =J10+$T$6/100 -> 1.0725 | L10: NDR step per quarter | M10: Q3 2026 = locked call (Base MID / Downside LOW); then a constant quarterly step. Used for the Downside narrative and as a cross-check; not the revenue engine (method A failed the backtest). | N10: monday_q3_call.xlsx NDR!D37; NDR rows QA (exact since Q4 2023) | O10: +/-0.25 pp per quarter moves Q4 2027 NDR by +/-1.25 pp. | P10: NDR measurement basis (point vs trailing) unresolved. | Q10: Sourced (Q3 call) then Derived | S10: S&M % rev change in 2027 vs Q3 2026 implied (pp) | T10: -0.5 | U10: 0 | V10: Post-commission-change quarters only (Q1 2025-Q2 2026: 48.1% -> 41.0%).
A11: NDR - all customers | B11: Downside | C11: =Series!V27 -> 1.09 | D11: Q2 2026 | E11: QA-1320 | F11: 1.07 | G11: =F11+$U$6/100 -> 1.066 | H11: =G11+$U$6/100 -> 1.062 | I11: =H11+$U$6/100 -> 1.058 | J11: =I11+$U$6/100 -> 1.054 | K11: =J11+$U$6/100 -> 1.05 | L11: NDR step per quarter | M11: Q3 2026 = locked call (Base MID / Downside LOW); then a constant quarterly step. Used for the Downside narrative and as a cross-check; not the revenue engine (method A failed the backtest). | N11: monday_q3_call.xlsx NDR!C37; NDR rows QA (exact since Q4 2023) | O11: +/-0.25 pp per quarter moves Q4 2027 NDR by +/-1.25 pp. | P11: NDR measurement basis (point vs trailing) unresolved. | Q11: Sourced (Q3 call) then Derived | S11: G&A % rev change in 2027 vs Q3 2026 implied (pp) | T11: -0.2 | U11: 0 | V11: G&A stable 8.1%-8.9% over the last 8 quarters.
A12: Customers >$50k ARR | B12: Base | C12: =Series!X27 -> 4834 | D12: Q2 2026 | E12: QA-1426 | F12: 5110.5 | G12: =F12+$T$7 -> 5387 | H12: =G12+$T$7 -> 5663.5 | I12: =H12+$T$7 -> 5940 | J12: =I12+$T$7 -> 6216.5 | K12: =J12+$T$7 -> 6493 | L12: Net adds per quarter | M12: Q3 2026 = locked call; constant net adds thereafter (cross-check driver). | N12: monday_q3_call.xlsx Customers_50K!D35; Series net adds | O12: +/-25 net adds per quarter = +/-125 customers by Q4 2027. | P12: Headcount reduction size (sales capacity). | Q12: Sourced (Q3 call) then Derived | S12: Annual adj. FCF / non-GAAP op. income (2027) | T12: =((T23+T24)/2)/((T25+T26)/2) -> 1.2284483 | U12: 1 | V12: Base: FY2026 guide-implied (FCF guide mid / op. income guide mid) - Derived; Downside: 1.0x.
A13: Customers >$50k ARR | B13: Downside | C13: =Series!X27 -> 4834 | D13: Q2 2026 | E13: QA-1426 | F13: 5028 | G13: =F13+$U$7 -> 5222 | H13: =G13+$U$7 -> 5416 | I13: =H13+$U$7 -> 5610 | J13: =I13+$U$7 -> 5804 | K13: =J13+$U$7 -> 5998 | L13: Net adds per quarter | M13: Q3 2026 = locked call; constant net adds thereafter (cross-check driver). | N13: monday_q3_call.xlsx Customers_50K!C35; Series net adds | O13: +/-25 net adds per quarter = +/-125 customers by Q4 2027. | P13: Headcount reduction size (sales capacity). | Q13: Sourced (Q3 call) then Derived | S13: Severance cash (USD m), H2 2026, split 50/50 Q3/Q4 | T13: 32.5 | U13: 35 | V13: Midpoint / top of the ~$30-35M severance-related estimate (July 22, 2026 6-K); cash nature and timing assumed.
A14: Gross margin (non-GAAP) | B14: Base | C14: =Series!AN27 -> 0.88920276 | D14: Q2 2026 | E14: QA-0511 | F14: =Series!AN27+$T$8/100 -> 0.88820276 | G14: =F14+$T$8/100 -> 0.88720276 | H14: =G14+$T$8/100 -> 0.88620276 | I14: =H14+$T$8/100 -> 0.88520276 | J14: =I14+$T$8/100 -> 0.88420276 | K14: =J14+$T$8/100 -> 0.88320276 | L14: GM step per quarter | M14: Drift down from Q2 2026 (88.9%) per company AI-compute expectation. | N14: Series GM column; source-book Definitions (cost of revenue) | O14: +/-0.1 pp per quarter = about +/-$1M per quarter of gross profit in 2027 per 0.1 pp step. | Q14: Derived from Assumed parameter | S14: SBC % of revenue (GAAP bridge), 2026 H2-2027 | T14: 0.105 | U14: 0.105 | V14: Recent quarters ~8%-12% of revenue; ~$15M SBC credit from the plan not separately modeled in this proposal.
A15: Gross margin (non-GAAP) | B15: Downside | C15: =Series!AN27 -> 0.88920276 | D15: Q2 2026 | E15: QA-0511 | F15: =Series!AN27+$U$8/100 -> 0.88670276 | G15: =F15+$U$8/100 -> 0.88420276 | H15: =G15+$U$8/100 -> 0.88170276 | I15: =H15+$U$8/100 -> 0.87920276 | J15: =I15+$U$8/100 -> 0.87670276 | K15: =J15+$U$8/100 -> 0.87420276 | L15: GM step per quarter | M15: Drift down from Q2 2026 (88.9%) per company AI-compute expectation. | N15: Series GM column; source-book Definitions (cost of revenue) | O15: +/-0.1 pp per quarter = about +/-$1M per quarter of gross profit in 2027 per 0.1 pp step. | Q15: Derived from Assumed parameter | S15: Fully loaded cost per head (USD k/yr) for the implied-headcount memo | T15: 330 | U15: 330 | V15: Calibrated so FY2025 non-GAAP opex / cost per head = average FY2025 headcount (calibration row below; rounded to $10k). Includes non-people opex (advertising, hosting), so it is a calibration constant, not a salary.
A16: R&D % rev (non-GAAP) | B16: Base | C16: =Series!AO27 -> 0.22764185 | D16: Q2 2026 | E16: QA-0587 | F16: =Series!AO27*((F14-$T$29/F7)/(Series!AO27+Series!AP27+Series!AQ27)) -> 0.22214013 | G16: =F16 -> 0.22214013 | H16: =$F16+$T$9/100 -> 0.21714013 | I16: =$F16+$T$9/100 -> 0.21714013 | J16: =$F16+$T$9/100 -> 0.21714013 | K16: =$F16+$T$9/100 -> 0.21714013 | L16: 2027 change parameter | M16: Q3 2026 = Q2 2026 ratio scaled so total opex matches the locked call (GM - op. margin); Q4 2026 held; 2027 = Q3 2026 ratio plus the 2027 change parameter (restructuring net of reinvestment). | N16: Series ratio columns | O16: Each 1 pp of revenue = about $17M of 2027 operating income at Base revenue. | P16: Headcount reduction size (savings not disclosed). | Q16: Derived from Assumed parameter / locked call | S16: Share repurchases (USD m per quarter) | T16: 0 | U16: 0 | V16: The $870M authorization was fully used by Q2 2026; no new program disclosed.
A17: R&D % rev (non-GAAP) | B17: Downside | C17: =Series!AO27 -> 0.22764185 | D17: Q2 2026 | E17: QA-0587 | F17: =F16*F7/F9 -> 0.2244604 | G17: =G16*G7/G9 -> 0.22729156 | H17: =H16*H7/H9 -> 0.22499049 | I17: =I16*I7/I9 -> 0.22788062 | J17: =J16*J7/J9 -> 0.23328213 | K17: =K16*K7/K9 -> 0.23931927 | L17: none (opex $ held) | M17: Downside BEFORE management action: opex dollars held at Base, so the ratio rises as revenue falls; the response is a model output, not an assumption. | N17: Series ratio columns | O17: Each 1 pp of revenue = about $17M of 2027 operating income at Base revenue. | P17: Headcount reduction size (savings not disclosed). | Q17: Derived from Assumed parameter / locked call
A18: S&M % rev (non-GAAP) | B18: Base | C18: =Series!AP27 -> 0.4098612 | D18: Q2 2026 | E18: QA-0625 | F18: =Series!AP27*((F14-$T$29/F7)/(Series!AO27+Series!AP27+Series!AQ27)) -> 0.39995553 | G18: =F18 -> 0.39995553 | H18: =$F18+$T$10/100 -> 0.39495553 | I18: =$F18+$T$10/100 -> 0.39495553 | J18: =$F18+$T$10/100 -> 0.39495553 | K18: =$F18+$T$10/100 -> 0.39495553 | L18: 2027 change parameter | M18: Q3 2026 = Q2 2026 ratio scaled so total opex matches the locked call (GM - op. margin); Q4 2026 held; 2027 = Q3 2026 ratio plus the 2027 change parameter (restructuring net of reinvestment). | N18: Series ratio columns; S&M ratios only Q1 2025 onward (AN-0348..AN-0350) | O18: Each 1 pp of revenue = about $17M of 2027 operating income at Base revenue. | P18: Headcount reduction size (savings not disclosed). | Q18: Derived from Assumed parameter / locked call | S18: Guidance inputs (Sourced) for derived parameters
A19: S&M % rev (non-GAAP) | B19: Downside | C19: =Series!AP27 -> 0.4098612 | D19: Q2 2026 | E19: QA-0625 | F19: =F18*F7/F9 -> 0.40413311 | G19: =G18*G7/G9 -> 0.40923051 | H19: =H18*H7/H9 -> 0.40923454 | I19: =I18*I7/I9 -> 0.41449138 | J19: =J18*J7/J9 -> 0.42431617 | K19: =K18*K7/K9 -> 0.43529711 | L19: none (opex $ held) | M19: Downside BEFORE management action: opex dollars held at Base, so the ratio rises as revenue falls; the response is a model output, not an assumption. | N19: Series ratio columns; S&M ratios only Q1 2025 onward (AN-0348..AN-0350) | O19: Each 1 pp of revenue = about $17M of 2027 operating income at Base revenue. | P19: Headcount reduction size (savings not disclosed). | Q19: Derived from Assumed parameter / locked call | S19: GH-0100 low (FY 2026 Revenue) | T19: 1466 | V19: GH-0100
A20: G&A % rev (non-GAAP) | B20: Base | C20: =Series!AQ27 -> 0.084101025 | D20: Q2 2026 | E20: QA-0663 | F20: =Series!AQ27*((F14-$T$29/F7)/(Series!AO27+Series!AP27+Series!AQ27)) -> 0.082068443 | G20: =F20 -> 0.082068443 | H20: =$F20+$T$11/100 -> 0.080068443 | I20: =$F20+$T$11/100 -> 0.080068443 | J20: =$F20+$T$11/100 -> 0.080068443 | K20: =$F20+$T$11/100 -> 0.080068443 | L20: 2027 change parameter | M20: Q3 2026 = Q2 2026 ratio scaled so total opex matches the locked call (GM - op. margin); Q4 2026 held; 2027 = Q3 2026 ratio plus the 2027 change parameter (restructuring net of reinvestment). | N20: Series ratio columns | O20: Each 1 pp of revenue = about $17M of 2027 operating income at Base revenue. | P20: Headcount reduction size (savings not disclosed). | Q20: Derived from Assumed parameter / locked call | S20: GH-0100 high (FY 2026 Revenue) | T20: 1474 | V20: GH-0100
A21: G&A % rev (non-GAAP) | B21: Downside | C21: =Series!AQ27 -> 0.084101025 | D21: Q2 2026 | E21: QA-0663 | F21: =F20*F7/F9 -> 0.082925656 | G21: =G20*G7/G9 -> 0.083971611 | H21: =H20*H7/H9 -> 0.082963193 | I21: =I20*I7/I9 -> 0.084028902 | J21: =J20*J7/J9 -> 0.086020658 | K21: =K20*K7/K9 -> 0.0882468 | L21: none (opex $ held) | M21: Downside BEFORE management action: opex dollars held at Base, so the ratio rises as revenue falls; the response is a model output, not an assumption. | N21: Series ratio columns | O21: Each 1 pp of revenue = about $17M of 2027 operating income at Base revenue. | P21: Headcount reduction size (savings not disclosed). | Q21: Derived from Assumed parameter / locked call | S21: GH-0102 low (Q3 2026 Revenue) | T21: 368 | V21: GH-0102
A22: Implied non-GAAP operating margin (memo) | B22: Base | C22: =Series!AR27 -> 0.16759868 | D22: Q2 2026 | E22: QA-0701 | F22: =F14-F16-F18-F20 -> 0.18403866 | G22: =G14-G16-G18-G20 -> 0.18303866 | H22: =H14-H16-H18-H20 -> 0.19403866 | I22: =I14-I16-I18-I20 -> 0.19303866 | J22: =J14-J16-J18-J20 -> 0.19203866 | K22: =K14-K16-K18-K20 -> 0.19103866 | L22: none (memo) | M22: Memo only: GM minus opex ratios; Base Q3 2026 equals the locked call margin by construction. | N22: Rows above | O22: See opex rows. | Q22: Derived | S22: GH-0102 high (Q3 2026 Revenue) | T22: 370 | V22: GH-0102
A23: Implied non-GAAP operating margin (memo) | B23: Downside | C23: =Series!AR27 -> 0.16759868 | D23: Q2 2026 | E23: QA-0701 | F23: =F15-F17-F19-F21 -> 0.17518359 | G23: =G15-G17-G19-G21 -> 0.16370909 | H23: =H15-H17-H19-H21 -> 0.16451454 | I23: =I15-I17-I19-I21 -> 0.15280185 | J23: =J15-J17-J19-J21 -> 0.13308381 | K23: =K15-K17-K19-K21 -> 0.11133958 | L23: none (memo) | M23: Memo only: GM minus opex ratios; Base Q3 2026 equals the locked call margin by construction. | N23: Rows above | O23: See opex rows. | Q23: Derived | S23: GH-0098 low (FY 2026 Adjusted free cash flow) | T23: 280 | V23: GH-0098
A24: Adjusted FCF (USD m) | B24: Base | C24: =Series!P27/1000 -> 52.344 | D24: Q2 2026 | E24: QA-1103 | F24: =$T$31*$T$32 -> 73.159541 | G24: =$T$31*(1-$T$32) -> 56.718459 | H24: =$T$12*H22*H7 -> 97.810696 | I24: =$T$12*I22*I7 -> 99.74148 | J24: =$T$12*J22*J7 -> 101.67979 | K24: =$T$12*K22*K7 -> 104.25253 | L24: Annual conversion (2027) | M24: Q3-Q4 2026: low-confidence figures tied to the FY guide (FY adj. FCF guide mid - H1 actual, split by 2023-2025 Q3 share), to be carried by the model with a label (Q3 was a NO CALL); 2027: non-GAAP op. income x annual conversion (Base = FY2026 guide-implied ~1.2x, Downside 1.0x), phased in the model by historical quarterly shares. | N24: GH-0098, GH-0099; Series conversion column; analysis Cash_Conversion seasonality | O24: +/-0.1x conversion = about +/-$30M of 2027 FCF. | P24: Severance cash in the FY FCF guide (unresolved). | Q24: Derived from Assumed parameter | S24: GH-0098 high (FY 2026 Adjusted free cash flow) | T24: 290 | V24: GH-0098
A25: Adjusted FCF (USD m) | B25: Downside | C25: =Series!P27/1000 -> 52.344 | D25: Q2 2026 | E25: QA-1103 | F25: =$T$31*$T$32*F23*F9/(F22*F7) -> 68.91958 | G25: =$T$31*(1-$T$32)*G23*G9/(G22*G7) -> 49.579038 | H25: =$U$12*H23*H9 -> 65.151051 | I25: =$U$12*I23*I9 -> 61.24011 | J25: =$U$12*J23*J9 -> 53.391602 | K25: =$U$12*K23*K9 -> 44.876653 | L25: Annual conversion (2027) | M25: Q3-Q4 2026: low-confidence figures tied to the FY guide (FY adj. FCF guide mid - H1 actual, split by 2023-2025 Q3 share), to be carried by the model with a label (Q3 was a NO CALL); 2027: non-GAAP op. income x annual conversion (Base = FY2026 guide-implied ~1.2x, Downside 1.0x), phased in the model by historical quarterly shares. | N25: GH-0098, GH-0099; Series conversion column; analysis Cash_Conversion seasonality | O25: +/-0.1x conversion = about +/-$30M of 2027 FCF. | P25: Severance cash in the FY FCF guide (unresolved). | Q25: Derived from Assumed parameter | S25: GH-0099 low (FY 2026 Non-GAAP operating income (loss)) | T25: 230 | V25: GH-0099
A26: Severance cash (USD m, outflow) | B26: Base | D26: n/a | E26: Annual restructuring rows (6K-20260722-RESTR) | F26: =$T$13/2 -> 16.25 | G26: =$T$13/2 -> 16.25 | H26: 0 | I26: 0 | J26: 0 | K26: 0 | L26: Severance cash total | M26: Explicit Assumed cash item, split evenly Q3/Q4 2026; excluded from non-GAAP. | N26: 6K-20260722-RESTR estimates ($30-35M) | O26: +/-$5M total; timing shift between Q3 and Q4 moves quarterly FCF one-for-one. | P26: Severance cash in the FY FCF guide; headcount reduction size. | Q26: Derived from Assumed parameter | S26: GH-0099 high (FY 2026 Non-GAAP operating income (loss)) | T26: 234 | V26: GH-0099
A27: Severance cash (USD m, outflow) | B27: Downside | D27: n/a | E27: Annual restructuring rows (6K-20260722-RESTR) | F27: =$U$13/2 -> 17.5 | G27: =$U$13/2 -> 17.5 | H27: 0 | I27: 0 | J27: 0 | K27: 0 | L27: Severance cash total | M27: Explicit Assumed cash item, split evenly Q3/Q4 2026; excluded from non-GAAP. | N27: 6K-20260722-RESTR estimates ($30-35M) | O27: +/-$5M total; timing shift between Q3 and Q4 moves quarterly FCF one-for-one. | P27: Severance cash in the FY FCF guide; headcount reduction size. | Q27: Derived from Assumed parameter | S27: H1 2026 revenue (USD k) | T27: 715886 | V27: QA-0038
A28: SBC (USD m, GAAP bridge) | B28: Base | C28: =Series!N27/1000 -> 41.218 | D28: Q2 2026 | E28: QA-0869 | F28: =$T$14*F7 -> 39.730158 | G28: =$T$14*G7 -> 41.465149 | H28: =$T$14*H7 -> 43.085438 | I28: =$T$14*I7 -> 44.163546 | J28: =$T$14*J7 -> 45.256233 | K28: =$T$14*K7 -> 46.644213 | L28: SBC % of revenue | M28: Flat % of revenue; restructuring SBC credit (~$15M) to be shown separately in the GAAP bridge. | N28: Series SBC % column; 6K-20260722-RESTR | O28: +/-1 pp of revenue = about +/-$17M per year of GAAP operating income. | Q28: Derived from Assumed parameter
A29: SBC (USD m, GAAP bridge) | B29: Downside | C29: =Series!N27/1000 -> 41.218 | D29: Q2 2026 | E29: QA-0869 | F29: =$U$14*F9 -> 39.319462 | G29: =$U$14*G9 -> 40.525366 | H29: =$U$14*H9 -> 41.582101 | I29: =$U$14*I9 -> 42.082025 | J29: =$U$14*J9 -> 42.124719 | K29: =$U$14*K9 -> 42.321416 | L29: SBC % of revenue | M29: Flat % of revenue; restructuring SBC credit (~$15M) to be shown separately in the GAAP bridge. | N29: Series SBC % column; 6K-20260722-RESTR | O29: +/-1 pp of revenue = about +/-$17M per year of GAAP operating income. | Q29: Derived from Assumed parameter | S29: Locked Q3 2026 call: non-GAAP op. income MID (USD m) | T29: 69.637 | V29: monday_q3_call.xlsx OpIncome_Margin!D90
A30: Implied headcount memo (heads, opex-based) | B30: Base | D30: n/a | E30: Annual employee rows (FY2025 year-end 3,155) | F30: =(F16+F18+F20)*F7*4*1000/$T$15 -> 3229.6163 | G30: =(G16+G18+G20)*G7*4*1000/$T$15 -> 3370.6516 | H30: =(H16+H18+H20)*H7*4*1000/$T$15 -> 3442.6774 | I30: =(I16+I18+I20)*I7*4*1000/$T$15 -> 3528.8221 | J30: =(J16+J18+J20)*J7*4*1000/$T$15 -> 3616.1316 | K30: =(K16+K18+K20)*K7*4*1000/$T$15 -> 3727.0361 | L30: Cost per head | M30: MEMO ONLY: annualized non-GAAP opex / Assumed fully loaded cost per head; overstates heads because opex includes advertising, hosting and other non-people costs. Used only to express hiring decisions in heads. | N30: Annual employee rows (20F-FY2025); Series opex | O30: +/-$50k per head changes implied heads by about -/+20%. | P30: Headcount reduction size. | Q30: Derived from Assumed parameter | S30: H1 2026 adjusted FCF (USD k) | T30: 155122 | V30: QA-1104
A31: Implied headcount memo (heads, opex-based) | B31: Downside | D31: n/a | E31: Annual employee rows (FY2025 year-end 3,155) | F31: =(F17+F19+F21)*F9*4*1000/$U$15 -> 3229.6163 | G31: =(G17+G19+G21)*G9*4*1000/$U$15 -> 3370.6516 | H31: =(H17+H19+H21)*H9*4*1000/$U$15 -> 3442.6774 | I31: =(I17+I19+I21)*I9*4*1000/$U$15 -> 3528.8221 | J31: =(J17+J19+J21)*J9*4*1000/$U$15 -> 3616.1316 | K31: =(K17+K19+K21)*K9*4*1000/$U$15 -> 3727.0361 | L31: Cost per head | M31: MEMO ONLY: annualized non-GAAP opex / Assumed fully loaded cost per head; overstates heads because opex includes advertising, hosting and other non-people costs. Used only to express hiring decisions in heads. | N31: Annual employee rows (20F-FY2025); Series opex | O31: +/-$50k per head changes implied heads by about -/+20%. | P31: Headcount reduction size. | Q31: Derived from Assumed parameter | S31: H2 2026 adj. FCF implied by FY guide midpoint (USD m) | T31: =(T23+T24)/2-T30/1000 -> 129.878
A32: Share repurchases (USD m) | B32: Base | D32: Q2 2026 | E32: Authorization exhausted (ER-2026Q2) | F32: =$T$16 -> 0 | G32: =$T$16 -> 0 | H32: =$T$16 -> 0 | I32: =$T$16 -> 0 | J32: =$T$16 -> 0 | K32: =$T$16 -> 0 | L32: Buybacks per quarter | M32: FLAG: none assumed; the $870M authorization was fully used by Q2 2026 and no new program is disclosed. | N32: QA repurchase rows; ER-2026Q2 | O32: A new program would reduce cash one-for-one. | Q32: Assumed (flagged) | S32: Mean Q3 share of H2 adj. FCF, 2023-2025 | T32: =AVERAGE(Series!P16/(Series!P16+Series!P17),Series!P20/(Series!P20+Series!P21),Series!P24/(Series!P24+Series!P25)) -> 0.56329433
A33: Share repurchases (USD m) | B33: Downside | D33: Q2 2026 | E33: Authorization exhausted (ER-2026Q2) | F33: =$U$16 -> 0 | G33: =$U$16 -> 0 | H33: =$U$16 -> 0 | I33: =$U$16 -> 0 | J33: =$U$16 -> 0 | K33: =$U$16 -> 0 | L33: Buybacks per quarter | M33: FLAG: none assumed; the $870M authorization was fully used by Q2 2026 and no new program is disclosed. | N33: QA repurchase rows; ER-2026Q2 | O33: A new program would reduce cash one-for-one. | Q33: Assumed (flagged) | S33: Employees, Dec 31, 2024 (AN-0085) | T33: 2508 | V33: AN-0085 / 20F-FY2024
S34: Employees, Dec 31, 2025 (AN-0051) | T34: 3155 | V34: AN-0051 / 20F-FY2025
A35: Interest income: NOT PROPOSED - not in the source book (see Driver_Map). cRPO / RPO: cross-check only (too sparse). Restructuring savings: not proposed separately; expressed through the 2027 opex-ratio parameters. | S35: Calibration: FY2025 non-GAAP opex / average FY2025 headcount (USD k per head) | T35: =(Series!F22+Series!F23+Series!F24+Series!F25+Series!H22+Series!H23+Series!H24+Series!H25+Series!J22+Series!J23+Series!J24+Series!J25)/((T33+T34)/2) -> 329.22338
A36: Unresolved items: (1) NDR measurement basis -> NDR rows; (2) severance cash in the FY FCF guide -> FCF and severance rows; (3) headcount reduction size / base -> opex ratios, customer adds, implied headcount.

Sheet Series
A1: Historical driver series copied from the source book (Quarterly_Actuals / Guidance_History) with Row IDs
A2: Blue = Sourced copy; adjacent column = source-book Row ID. Blank = not disclosed (or disclosed only as a floor, excluded). USD thousands unless stated.
A4: Quarter | B4: Revenue | C4: Row ID | D4: Gross profit (non-GAAP) | E4: Row ID | F4: R&D (non-GAAP) | G4: Row ID | H4: S&M (non-GAAP) | I4: Row ID | J4: G&A (non-GAAP) | K4: Row ID | L4: Operating income (non-GAAP) | M4: Row ID | N4: SBC total | O4: Row ID | P4: Adjusted FCF / FCF | Q4: Row ID | R4: Cash and equivalents | S4: Row ID | T4: Marketable securities | U4: Row ID | V4: NDR all customers (exact only) | W4: Row ID | X4: Customers >$50k ARR | Y4: Row ID | Z4: Customers >$100k ARR | AA4: Row ID | AB4: RPO (release, USD m) | AC4: Row ID | AD4: cRPO (release, USD m) | AE4: Row ID | AF4: Revenue guide low (USD m) | AG4: Revenue guide high (USD m) | AH4: GH Row ID | AI4: Revenue YoY growth | AJ4: Revenue QoQ growth | AK4: Residual = YoY growth - (NDR - 1) | AL4: Guide midpoint (USD m) | AM4: % beat vs guide midpoint | AN4: Gross margin (non-GAAP) | AO4: R&D % rev (non-GAAP) | AP4: S&M % rev (non-GAAP) | AQ4: G&A % rev (non-GAAP) | AR4: Op. margin (non-GAAP) | AS4: Adj. FCF / non-GAAP op. income | AT4: SBC % rev | AU4: Net adds >$50k
A5: Text / label | B5: Sourced (copied) | C5: Source-book Row ID | D5: Sourced (copied) | E5: Source-book Row ID | F5: Sourced (copied) | G5: Source-book Row ID | H5: Sourced (copied) | I5: Source-book Row ID | J5: Sourced (copied) | K5: Source-book Row ID | L5: Sourced (copied) | M5: Source-book Row ID | N5: Sourced (copied) | O5: Source-book Row ID | P5: Sourced (copied) | Q5: Source-book Row ID | R5: Sourced (copied) | S5: Source-book Row ID | T5: Sourced (copied) | U5: Source-book Row ID | V5: Sourced (copied) | W5: Source-book Row ID | X5: Sourced (copied) | Y5: Source-book Row ID | Z5: Sourced (copied) | AA5: Source-book Row ID | AB5: Sourced (copied) | AC5: Source-book Row ID | AD5: Sourced (copied) | AE5: Source-book Row ID | AF5: Sourced (copied) | AG5: Sourced (copied) | AH5: Source-book Row ID | AI5: Derived (formula) | AJ5: Derived (formula) | AK5: Derived (formula) | AL5: Derived (formula) | AM5: Derived (formula) | AN5: Derived (formula) | AO5: Derived (formula) | AP5: Derived (formula) | AQ5: Derived (formula) | AR5: Derived (formula) | AS5: Derived (formula) | AT5: Derived (formula) | AU5: Derived (formula)
A6: Q1 2021 | B6: 58972 | C6: QA-0001 | D6: 52579 | E6: QA-0475 | F6: 11044 | G6: QA-0551 | H6: 59014 | I6: QA-0589 | J6: 5828 | K6: QA-0627 | L6: -23307 | M6: QA-0665 | N6: 14540 | O6: QA-0833 | P6: -1595 | Q6: QA-1067 | R6: 124281 | S6: QA-1212 | X6: 335 | Y6: QA-1405 | AN6: =D6/B6 -> 0.89159262 | AO6: =F6/B6 -> 0.18727532 | AP6: =H6/B6 -> 1.0007122 | AQ6: =J6/B6 -> 0.098826562 | AR6: =L6/B6 -> -0.39522146 | AS6: =IF(L6<=0,"n/m",P6/L6) -> n/m | AT6: =N6/B6 -> 0.24655769
A7: Q2 2021 | B7: 70615 | C7: QA-0002 | D7: 63340 | E7: QA-0476 | F7: 11203 | G7: QA-0552 | H7: 55521 | I7: QA-0590 | J7: 6527 | K7: QA-0628 | L7: -9911 | M7: QA-0666 | N7: 17558 | O7: QA-0834 | P7: -1480 | Q7: QA-1068 | R7: 865328 | S7: QA-1213 | X7: 470 | Y7: QA-1406 | AJ7: =B7/B6-1 -> 0.19743268 | AN7: =D7/B7 -> 0.89697656 | AO7: =F7/B7 -> 0.15864901 | AP7: =H7/B7 -> 0.78624938 | AQ7: =J7/B7 -> 0.092430787 | AR7: =L7/B7 -> -0.14035262 | AS7: =IF(L7<=0,"n/m",P7/L7) -> n/m | AT7: =N7/B7 -> 0.24864406 | AU7: =X7-X6 -> 135
A8: Q3 2021 | B8: 83018 | C8: QA-0004 | D8: 74912 | E8: QA-0478 | F8: 14255 | G8: QA-0554 | H8: 60995 | I8: QA-0592 | J8: 9111 | K8: QA-0630 | L8: -9449 | M8: QA-0668 | N8: 19762 | O8: QA-0836 | P8: 2865 | Q8: QA-1070 | R8: 876220 | S8: QA-1214 | X8: 613 | Y8: QA-1407 | AF8: 74 | AG8: 75 | AH8: GH-0004 | AJ8: =B8/B7-1 -> 0.17564257 | AL8: =(AF8+AG8)/2 -> 74.5 | AM8: =(B8/1000-AL8)/AL8 -> 0.11433557 | AN8: =D8/B8 -> 0.90235852 | AO8: =F8/B8 -> 0.17170975 | AP8: =H8/B8 -> 0.73472018 | AQ8: =J8/B8 -> 0.10974728 | AR8: =L8/B8 -> -0.11381869 | AS8: =IF(L8<=0,"n/m",P8/L8) -> n/m | AT8: =N8/B8 -> 0.23804476 | AU8: =X8-X7 -> 143
A9: Q4 2021 | B9: 95545 | C9: QA-0006 | D9: 85987 | E9: QA-0480 | F9: 15405 | G9: QA-0556 | H9: 69418 | I9: QA-0594 | J9: 11093 | K9: QA-0632 | L9: -9929 | M9: QA-0670 | N9: 21669 | O9: QA-0838 | P9: 10110 | Q9: QA-1072 | R9: 886812 | S9: QA-1215 | X9: 793 | Y9: QA-1408 | AF9: 87 | AG9: 88 | AH9: GH-0008 | AJ9: =B9/B8-1 -> 0.15089499 | AL9: =(AF9+AG9)/2 -> 87.5 | AM9: =(B9/1000-AL9)/AL9 -> 0.091942857 | AN9: =D9/B9 -> 0.89996337 | AO9: =F9/B9 -> 0.16123293 | AP9: =H9/B9 -> 0.7265477 | AQ9: =J9/B9 -> 0.11610236 | AR9: =L9/B9 -> -0.10391962 | AS9: =IF(L9<=0,"n/m",P9/L9) -> n/m | AT9: =N9/B9 -> 0.22679366 | AU9: =X9-X8 -> 180
A10: Q1 2022 | B10: 108497 | C10: QA-0008 | D10: 96329 | E10: QA-0482 | F10: 19153 | G10: QA-0558 | H10: 108595 | I10: QA-0596 | J10: 12411 | K10: QA-0634 | L10: -43830 | M10: QA-0672 | N10: 23666 | O10: QA-0840 | P10: -16192 | Q10: QA-1074 | R10: 849576 | S10: QA-1216 | X10: 960 | Y10: QA-1409 | AF10: 100 | AG10: 102 | AH10: GH-0012 | AI10: =B10/B6-1 -> 0.83980533 | AJ10: =B10/B9-1 -> 0.13555916 | AK10: =IF(V10="","",AI10-(V10-1)) | AL10: =(AF10+AG10)/2 -> 101 | AM10: =(B10/1000-AL10)/AL10 -> 0.074227723 | AN10: =D10/B10 -> 0.88784943 | AO10: =F10/B10 -> 0.17653023 | AP10: =H10/B10 -> 1.0009033 | AQ10: =J10/B10 -> 0.11439026 | AR10: =L10/B10 -> -0.4039743 | AS10: =IF(L10<=0,"n/m",P10/L10) -> n/m | AT10: =N10/B10 -> 0.21812585 | AU10: =X10-X9 -> 167
A11: Q2 2022 | B11: 123718 | C11: QA-0009 | D11: 109903 | E11: QA-0483 | F11: 23963 | G11: QA-0559 | H11: 86665 | I11: QA-0597 | J11: 14633 | K11: QA-0635 | L11: -15358 | M11: QA-0673 | N11: 30822 | O11: QA-0841 | P11: -19295 | Q11: QA-1075 | R11: 834620 | S11: QA-1217 | X11: 1160 | Y11: QA-1410 | AF11: 117 | AG11: 119 | AH11: GH-0016 | AI11: =B11/B7-1 -> 0.75200736 | AJ11: =B11/B10-1 -> 0.14028959 | AK11: =IF(V11="","",AI11-(V11-1)) | AL11: =(AF11+AG11)/2 -> 118 | AM11: =(B11/1000-AL11)/AL11 -> 0.048457627 | AN11: =D11/B11 -> 0.88833476 | AO11: =F11/B11 -> 0.19369049 | AP11: =H11/B11 -> 0.70050437 | AQ11: =J11/B11 -> 0.11827705 | AR11: =L11/B11 -> -0.12413715 | AS11: =IF(L11<=0,"n/m",P11/L11) -> n/m | AT11: =N11/B11 -> 0.24913109 | AU11: =X11-X10 -> 200
A12: Q3 2022 | B12: 136893 | C12: QA-0011 | D12: 121746 | E12: QA-0485 | F12: 26259 | G12: QA-0561 | H12: 82432 | I12: QA-0599 | J12: 15240 | K12: QA-0637 | L12: -2185 | M12: QA-0675 | N12: 26054 | O12: QA-0843 | P12: 13959 | Q12: QA-1077 | R12: 852568 | S12: QA-1218 | X12: 1323 | Y12: QA-1411 | AF12: 130 | AG12: 131 | AH12: GH-0020 | AI12: =B12/B8-1 -> 0.64895565 | AJ12: =B12/B11-1 -> 0.10649218 | AK12: =IF(V12="","",AI12-(V12-1)) | AL12: =(AF12+AG12)/2 -> 130.5 | AM12: =(B12/1000-AL12)/AL12 -> 0.048988506 | AN12: =D12/B12 -> 0.88935154 | AO12: =F12/B12 -> 0.19182135 | AP12: =H12/B12 -> 0.60216373 | AQ12: =J12/B12 -> 0.11132783 | AR12: =L12/B12 -> -0.015961371 | AS12: =IF(L12<=0,"n/m",P12/L12) -> n/m | AT12: =N12/B12 -> 0.19032383 | AU12: =X12-X11 -> 163
A13: Q4 2022 | B13: 149921 | C13: QA-0013 | D13: 134929 | E13: QA-0487 | F13: 24715 | G13: QA-0563 | H13: 80919 | I13: QA-0601 | J13: 15017 | K13: QA-0639 | L13: 14278 | M13: QA-0677 | N13: 24378 | O13: QA-0845 | P13: 29665 | Q13: QA-1079 | R13: 885894 | S13: QA-1219 | X13: 1474 | Y13: QA-1412 | Z13: 527 | AA13: QA-1379 | AF13: 140 | AG13: 142 | AH13: GH-0024 | AI13: =B13/B9-1 -> 0.56911403 | AJ13: =B13/B12-1 -> 0.09516922 | AK13: =IF(V13="","",AI13-(V13-1)) | AL13: =(AF13+AG13)/2 -> 141 | AM13: =(B13/1000-AL13)/AL13 -> 0.063269504 | AN13: =D13/B13 -> 0.90000067 | AO13: =F13/B13 -> 0.16485349 | AP13: =H13/B13 -> 0.53974427 | AQ13: =J13/B13 -> 0.10016609 | AR13: =L13/B13 -> 0.095236825 | AS13: =IF(L13<=0,"n/m",P13/L13) -> 2.0776719 | AT13: =N13/B13 -> 0.16260564 | AU13: =X13-X12 -> 151
A14: Q1 2023 | B14: 162256 | C14: QA-0015 | D14: 146719 | E14: QA-0489 | F14: 28519 | G14: QA-0565 | H14: 102652 | I14: QA-0603 | J14: 15841 | K14: QA-0641 | L14: -293 | M14: QA-0679 | N14: 22459 | O14: QA-0847 | P14: 38682 | Q14: QA-1081 | R14: 935565 | S14: QA-1220 | X14: 1683 | Y14: QA-1413 | Z14: 588 | AA14: QA-1380 | AF14: 154 | AG14: 156 | AH14: GH-0028 | AI14: =B14/B10-1 -> 0.49548835 | AJ14: =B14/B13-1 -> 0.082276666 | AK14: =IF(V14="","",AI14-(V14-1)) | AL14: =(AF14+AG14)/2 -> 155 | AM14: =(B14/1000-AL14)/AL14 -> 0.046812903 | AN14: =D14/B14 -> 0.90424391 | AO14: =F14/B14 -> 0.17576546 | AP14: =H14/B14 -> 0.63265457 | AQ14: =J14/B14 -> 0.097629672 | AR14: =L14/B14 -> -0.0018057884 | AS14: =IF(L14<=0,"n/m",P14/L14) -> n/m | AT14: =N14/B14 -> 0.13841707 | AU14: =X14-X13 -> 209
A15: Q2 2023 | B15: 175679 | C15: QA-0016 | D15: 158008 | E15: QA-0490 | F15: 27908 | G15: QA-0566 | H15: 98831 | I15: QA-0604 | J15: 14652 | K15: QA-0642 | L15: 16617 | M15: QA-0680 | N15: 28784 | O15: QA-0848 | P15: 45932 | Q15: QA-1082 | R15: 989377 | S15: QA-1221 | X15: 1892 | Y15: QA-1414 | Z15: 677 | AA15: QA-1381 | AF15: 168 | AG15: 170 | AH15: GH-0032 | AI15: =B15/B11-1 -> 0.41999547 | AJ15: =B15/B14-1 -> 0.082727295 | AK15: =IF(V15="","",AI15-(V15-1)) | AL15: =(AF15+AG15)/2 -> 169 | AM15: =(B15/1000-AL15)/AL15 -> 0.03952071 | AN15: =D15/B15 -> 0.89941313 | AO15: =F15/B15 -> 0.15885792 | AP15: =H15/B15 -> 0.56256582 | AQ15: =J15/B15 -> 0.083402114 | AR15: =L15/B15 -> 0.094587287 | AS15: =IF(L15<=0,"n/m",P15/L15) -> 2.7641572 | AT15: =N15/B15 -> 0.16384428 | AU15: =X15-X14 -> 209
A16: Q3 2023 | B16: 189190 | C16: QA-0018 | D16: 168866 | E16: QA-0492 | F16: 28051 | G16: QA-0568 | H16: 101504 | I16: QA-0606 | J16: 15234 | K16: QA-0644 | L16: 24077 | M16: QA-0682 | N16: 26598 | O16: QA-0850 | P16: 64890 | Q16: QA-1084 | R16: 1054270 | S16: QA-1222 | X16: 2077 | Y16: QA-1415 | Z16: 749 | AA16: QA-1382 | AF16: 181 | AG16: 183 | AH16: GH-0036 | AI16: =B16/B12-1 -> 0.3820283 | AJ16: =B16/B15-1 -> 0.076907314 | AK16: =IF(V16="","",AI16-(V16-1)) | AL16: =(AF16+AG16)/2 -> 182 | AM16: =(B16/1000-AL16)/AL16 -> 0.039505495 | AN16: =D16/B16 -> 0.8925736 | AO16: =F16/B16 -> 0.14826894 | AP16: =H16/B16 -> 0.53651884 | AQ16: =J16/B16 -> 0.080522226 | AR16: =L16/B16 -> 0.1272636 | AS16: =IF(L16<=0,"n/m",P16/L16) -> 2.6951032 | AT16: =N16/B16 -> 0.14058883 | AU16: =X16-X15 -> 185
A17: Q4 2023 | B17: 202570 | C17: QA-0020 | D17: 181764 | E17: QA-0494 | F17: 33285 | G17: QA-0570 | H17: 110020 | I17: QA-0608 | J17: 17259 | K17: QA-0646 | L17: 21200 | M17: QA-0684 | N17: 22345 | O17: QA-0852 | P17: 55441 | Q17: QA-1086 | R17: 1116128 | S17: QA-1223 | V17: 1.1 | W17: QA-1310 | X17: 2295 | Y17: QA-1416 | Z17: 833 | AA17: QA-1383 | AF17: 196 | AG17: 198 | AH17: GH-0040 | AI17: =B17/B13-1 -> 0.35117829 | AJ17: =B17/B16-1 -> 0.070722554 | AK17: =IF(V17="","",AI17-(V17-1)) -> 0.25117829 | AL17: =(AF17+AG17)/2 -> 197 | AM17: =(B17/1000-AL17)/AL17 -> 0.028274112 | AN17: =D17/B17 -> 0.89728983 | AO17: =F17/B17 -> 0.16431357 | AP17: =H17/B17 -> 0.5431209 | AQ17: =J17/B17 -> 0.085200178 | AR17: =L17/B17 -> 0.10465518 | AS17: =IF(L17<=0,"n/m",P17/L17) -> 2.6151415 | AT17: =N17/B17 -> 0.11030755 | AU17: =X17-X16 -> 218
A18: Q1 2024 | B18: 216913 | C18: QA-0022 | D18: 194703 | E18: QA-0496 | F18: 34797 | G18: QA-0572 | H18: 120806 | I18: QA-0610 | J18: 17579 | K18: QA-0648 | L18: 21521 | M18: QA-0686 | N18: 26543 | O18: QA-0854 | P18: 89894 | Q18: QA-1088 | R18: 1224544 | S18: QA-1224 | V18: 1.1 | W18: QA-1311 | X18: 2491 | Y18: QA-1417 | Z18: 911 | AA18: QA-1384 | AF18: 207 | AG18: 211 | AH18: GH-0046 | AI18: =B18/B14-1 -> 0.33685657 | AJ18: =B18/B17-1 -> 0.070805154 | AK18: =IF(V18="","",AI18-(V18-1)) -> 0.23685657 | AL18: =(AF18+AG18)/2 -> 209 | AM18: =(B18/1000-AL18)/AL18 -> 0.037861244 | AN18: =D18/B18 -> 0.89760872 | AO18: =F18/B18 -> 0.16041915 | AP18: =H18/B18 -> 0.55693296 | AQ18: =J18/B18 -> 0.081041708 | AR18: =L18/B18 -> 0.099214893 | AS18: =IF(L18<=0,"n/m",P18/L18) -> 4.1770364 | AT18: =N18/B18 -> 0.12236703 | AU18: =X18-X17 -> 196
A19: Q2 2024 | B19: 236106 | C19: QA-0023 | D19: 214215 | E19: QA-0497 | F19: 36878 | G19: QA-0573 | H19: 120738 | I19: QA-0611 | J19: 18182 | K19: QA-0649 | L19: 38417 | M19: QA-0687 | N19: 36623 | O19: QA-0855 | P19: 50821 | Q19: QA-1089 | R19: 1290242 | S19: QA-1225 | V19: 1.1 | W19: QA-1312 | X19: 2713 | Y19: QA-1418 | Z19: 1009 | AA19: QA-1385 | AF19: 226 | AG19: 230 | AH19: GH-0052 | AI19: =B19/B15-1 -> 0.34396257 | AJ19: =B19/B18-1 -> 0.088482479 | AK19: =IF(V19="","",AI19-(V19-1)) -> 0.24396257 | AL19: =(AF19+AG19)/2 -> 228 | AM19: =(B19/1000-AL19)/AL19 -> 0.035552632 | AN19: =D19/B19 -> 0.90728317 | AO19: =F19/B19 -> 0.15619256 | AP19: =H19/B19 -> 0.51137201 | AQ19: =J19/B19 -> 0.077007785 | AR19: =L19/B19 -> 0.16271082 | AS19: =IF(L19<=0,"n/m",P19/L19) -> 1.3228779 | AT19: =N19/B19 -> 0.15511253 | AU19: =X19-X18 -> 222
A20: Q3 2024 | B20: 251000 | C20: QA-0025 | D20: 226909 | E20: QA-0499 | F20: 42973 | G20: QA-0575 | H20: 130339 | I20: QA-0613 | J20: 21417 | K20: QA-0651 | L20: 32180 | M20: QA-0689 | N20: 35374 | O20: QA-0857 | P20: 82412 | Q20: QA-1091 | R20: 1337155 | S20: QA-1226 | T20: 50667 | U20: QA-1237 | V20: 1.11 | W20: QA-1313 | X20: 2907 | Y20: QA-1419 | Z20: 1080 | AA20: QA-1386 | AB20: 548 | AC20: QA-1528 | AF20: 243 | AG20: 247 | AH20: GH-0058 | AI20: =B20/B16-1 -> 0.3267086 | AJ20: =B20/B19-1 -> 0.063081836 | AK20: =IF(V20="","",AI20-(V20-1)) -> 0.2167086 | AL20: =(AF20+AG20)/2 -> 245 | AM20: =(B20/1000-AL20)/AL20 -> 0.024489796 | AN20: =D20/B20 -> 0.90401992 | AO20: =F20/B20 -> 0.17120717 | AP20: =H20/B20 -> 0.51927888 | AQ20: =J20/B20 -> 0.085326693 | AR20: =L20/B20 -> 0.12820717 | AS20: =IF(L20<=0,"n/m",P20/L20) -> 2.5609695 | AT20: =N20/B20 -> 0.14093227 | AU20: =X20-X19 -> 194
A21: Q4 2024 | B21: 267976 | C21: QA-0027 | D21: 239080 | E21: QA-0501 | F21: 48066 | G21: QA-0577 | H21: 127791 | I21: QA-0615 | J21: 22958 | K21: QA-0653 | L21: 40265 | M21: QA-0691 | N21: 30669 | O21: QA-0859 | P21: 72703 | Q21: QA-1093 | R21: 1411602 | S21: QA-1227 | T21: 50004 | U21: QA-1238 | V21: 1.12 | W21: QA-1314 | X21: 3201 | Y21: QA-1420 | Z21: 1207 | AA21: QA-1387 | AB21: 614 | AC21: QA-1529 | AD21: 516 | AE21: QA-1519 | AF21: 260 | AG21: 262 | AH21: GH-0064 | AI21: =B21/B17-1 -> 0.32288098 | AJ21: =B21/B20-1 -> 0.067633466 | AK21: =IF(V21="","",AI21-(V21-1)) -> 0.20288098 | AL21: =(AF21+AG21)/2 -> 261 | AM21: =(B21/1000-AL21)/AL21 -> 0.026727969 | AN21: =D21/B21 -> 0.89216945 | AO21: =F21/B21 -> 0.17936681 | AP21: =H21/B21 -> 0.47687479 | AQ21: =J21/B21 -> 0.085671851 | AR21: =L21/B21 -> 0.15025599 | AS21: =IF(L21<=0,"n/m",P21/L21) -> 1.8056128 | AT21: =N21/B21 -> 0.11444682 | AU21: =X21-X20 -> 294
A22: Q1 2025 | B22: 282250 | C22: QA-0029 | D22: 254579 | E22: QA-0503 | F22: 53844 | G22: QA-0579 | H22: 135882 | I22: QA-0617 | J22: 24099 | K22: QA-0655 | L22: 40754 | M22: QA-0693 | N22: 30958 | O22: QA-0861 | P22: 109532 | Q22: QA-1095 | R22: 1527605 | S22: QA-1228 | T22: 60730 | U22: QA-1239 | V22: 1.12 | W22: QA-1315 | X22: 3444 | Y22: QA-1421 | Z22: 1328 | AA22: QA-1388 | AB22: 660 | AC22: QA-1530 | AD22: 568 | AE22: QA-1520 | AF22: 274 | AG22: 276 | AH22: GH-0069 | AI22: =B22/B18-1 -> 0.30121293 | AJ22: =B22/B21-1 -> 0.053265964 | AK22: =IF(V22="","",AI22-(V22-1)) -> 0.18121293 | AL22: =(AF22+AG22)/2 -> 275 | AM22: =(B22/1000-AL22)/AL22 -> 0.026363636 | AN22: =D22/B22 -> 0.9019628 | AO22: =F22/B22 -> 0.19076705 | AP22: =H22/B22 -> 0.48142427 | AQ22: =J22/B22 -> 0.085381754 | AR22: =L22/B22 -> 0.14438973 | AS22: =IF(L22<=0,"n/m",P22/L22) -> 2.687638 | AT22: =N22/B22 -> 0.10968291 | AU22: =X22-X21 -> 243
A23: Q2 2025 | B23: 299014 | C23: QA-0030 | D23: 270113 | E23: QA-0504 | F23: 59233 | G23: QA-0580 | H23: 139223 | I23: QA-0618 | J23: 26563 | K23: QA-0656 | L23: 45094 | M23: QA-0694 | N23: 56645 | O23: QA-0862 | P23: 64093 | Q23: QA-1096 | R23: 1590515 | S23: QA-1229 | T23: 60102 | U23: QA-1240 | V23: 1.11 | W23: QA-1316 | X23: 3702 | Y23: QA-1422 | Z23: 1472 | AA23: QA-1389 | AB23: 699 | AC23: QA-1531 | AD23: 588 | AE23: QA-1521 | AF23: 292 | AG23: 294 | AH23: GH-0074 | AI23: =B23/B19-1 -> 0.26643965 | AJ23: =B23/B22-1 -> 0.059394154 | AK23: =IF(V23="","",AI23-(V23-1)) -> 0.15643965 | AL23: =(AF23+AG23)/2 -> 293 | AM23: =(B23/1000-AL23)/AL23 -> 0.020525597 | AN23: =D23/B23 -> 0.90334566 | AO23: =F23/B23 -> 0.1980944 | AP23: =H23/B23 -> 0.46560696 | AQ23: =J23/B23 -> 0.088835305 | AR23: =L23/B23 -> 0.15080899 | AS23: =IF(L23<=0,"n/m",P23/L23) -> 1.4213199 | AT23: =N23/B23 -> 0.18943929 | AU23: =X23-X22 -> 258
A24: Q3 2025 | B24: 316855 | C24: QA-0032 | D24: 284031 | E24: QA-0506 | F24: 57772 | G24: QA-0582 | H24: 151804 | I24: QA-0620 | J24: 26971 | K24: QA-0658 | L24: 47484 | M24: QA-0696 | N24: 49862 | O24: QA-0864 | P24: 92301 | Q24: QA-1098 | R24: 1527246 | S24: QA-1230 | T24: 211740 | U24: QA-1241 | V24: 1.11 | W24: QA-1317 | X24: 3993 | Y24: QA-1423 | Z24: 1603 | AA24: QA-1390 | AB24: 747 | AC24: QA-1532 | AF24: 311 | AG24: 313 | AH24: GH-0079 | AI24: =B24/B20-1 -> 0.26237052 | AJ24: =B24/B23-1 -> 0.059666103 | AK24: =IF(V24="","",AI24-(V24-1)) -> 0.15237052 | AL24: =(AF24+AG24)/2 -> 312 | AM24: =(B24/1000-AL24)/AL24 -> 0.015560897 | AN24: =D24/B24 -> 0.89640687 | AO24: =F24/B24 -> 0.18232946 | AP24: =H24/B24 -> 0.47909612 | AQ24: =J24/B24 -> 0.085120954 | AR24: =L24/B24 -> 0.14986035 | AS24: =IF(L24<=0,"n/m",P24/L24) -> 1.9438337 | AT24: =N24/B24 -> 0.15736536 | AU24: =X24-X23 -> 291
