Workbook

Sheet README
A1: monday.com - PRE-REGISTERED Q3 2026 CALL (Phase 2a)
A3: Status | B3: DRAFT, NOT LOCKED. The owner will lock this workbook after review. No tag or lock has been applied by the builder.
A4: Date built | B4: 2026-10-28 (information cutoff October 28, 2026). monday.com is scheduled to report Q3 2026 on November 9, 2026; no Q3 2026 result was available or used.
A5: Method fixed before results | B5: Each metric sheet begins with a METHOD STATEMENT written before any value was computed. The calls are the mechanical output of those rules applied to source-book data plus the explicitly Assumed parameters listed on the Assumptions sheet.
A6: No-edit rule | B6: After the owner locks this workbook, the call (Low / Mid / High) and the method statements will NOT be edited. After November 9, 2026 only the "Actual" and "Within range?" columns of the Scorecard are filled; any later correction is recorded as a new, dated note, never by changing the call.
A7: Sources | B7: Inputs are copied from monday_sourcebook.xlsx (Row IDs QA-/GH-) and the guidance-beat history is cross-tied to monday_analysis.xlsx (Guidance_Accuracy column N). No new data sources.
A8: Labels | B8: Sourced = blue hard-coded copy with Row ID beside it. Derived = black live formula. Assumed = orange on a light-orange fill; each has a one-line rationale and a sensitivity (Assumptions sheet). Column B of every table states the label of the row; call cells are on a yellow fill.
A9: Units | B9: Revenue, operating income and FCF in USD millions for calls (actuals copied in USD thousands and converted by formula); NDR as a percentage; customers as a count.
A10: FX assumption | B10: Q3 2026 revenue guidance states no FX assumption; Q3 non-GAAP operating income guidance assumes a negative FX impact of 100-200 bps (GH-0101). The call assumes FX in Q3 2026 is as embedded in the company guidance: an ADDITIONAL FX adjustment of 0 bps (Assumed, sensitivity shown).
A11: Not included | B11: No narrative beyond the required sections, no recommendation, no operating plan, no forecast beyond Q3 2026.
A12: Sheets | B12: Revenue, OpIncome_Margin, Adj_FCF, NDR, Customers_50K, cRPO, Assumptions, Scorecard, Checks.

Sheet Revenue
A1: Q3 2026 revenue call
A2: USD millions unless stated. Q3 2026 guidance issued August 10, 2026 (GH-0102).
A5: 1. METHOD STATEMENT (fixed before computing)
A6: Rule: Call = Q3 2026 revenue guidance midpoint x (1 + historical % beat vs guidance midpoint) x (1 + additional FX adjustment). Base case (MID) uses the MEDIAN % beat of the last 8 quarters with a prior-quarter guide (Q3 2024-Q2 2026); LOW uses the MINIMUM and HIGH the MAXIMUM of those 8 beats. Shown but not used for the call: the same statistics over all 20 quarters, and a scenario using the smallest recent beat (Q4 2025, the quarter the company first quantified an FX headwind). Additional FX adjustment is Assumed at 0 bps (FX assumed as embedded in guidance). Median, not mean, so that one outlier quarter does not set the base case. | B6: Text (method)
A8: 2. Inputs
A9: Item | B9: Label | C9: Value / Low | D9: Mid | E9: High | F9: Row ID / reference | G9: Source ID | H9: Note / rationale | I9: Sensitivity
A10: Q3 2026 revenue guidance - low (USD m) | B10: Sourced | C10: 368 | F10: GH-0102 | G10: ER-2026Q2 | H10: GH-0102 "Total revenue of $368 million to $370 million"
A11: Q3 2026 revenue guidance - high (USD m) | B11: Sourced | C11: 370 | F11: GH-0102 | G11: ER-2026Q2
A12: Q2 2026 revenue (USD k) | B12: Sourced | C12: 364621 | F12: QA-0037 | G12: ER-2026Q2
A13: Q3 2025 revenue (USD k) | B13: Sourced | C13: 316855 | F13: QA-0032 | G13: ER-2025Q3
A14: Q1 2025 revenue (USD k) | B14: Sourced | C14: 282250 | F14: QA-0029 | G14: ER-2025Q1
A15: Q2 2025 revenue (USD k) | B15: Sourced | C15: 299014 | F15: QA-0030 | G15: ER-2025Q2
A16: Q4 2025 revenue (USD k) | B16: Sourced | C16: 333878 | F16: QA-0034 | G16: ER-2025Q4
A17: Q1 2026 revenue (USD k) | B17: Sourced | C17: 351265 | F17: QA-0036 | G17: ER-2026Q1
A18: Additional FX adjustment to Q3 revenue vs guidance (bps) | B18: Assumed | C18: 0 | H18: Revenue guidance states no FX assumption; no FX data after Aug 10 is in the source book; assume FX is as embedded in the guide. | I18: Each +/-100 bps changes the call by about +/-$3.8M (1% of the MID call).
A19: Beat window used for the call (quarters) | B19: Assumed | C19: 8 | H19: Recent 8 quarters reflect the current scale and guidance practice; all-history (20) shown as alternative. | I19: All-history MID would be higher (median 3.7% vs 2.5% beat); see section 3.
A21: Beat history (Sourced guidance and actuals; Derived % beat)
A22: Quarter | B22: Label | C22: Guide low (USD m) | D22: Guide high (USD m) | E22: Actual (USD k) | F22: GH Row ID / QA Row ID | G22: Source IDs | H22: Midpoint (USD m) | % beat vs midpoint | USD m beat | I22: Analysis tie (monday_analysis.xlsx) | J22: Midpoint (USD m) | K22: % beat vs midpoint | L22: USD m beat vs midpoint
A23: Q3 2021 | B23: Sourced (C:E); Derived (J:L) | C23: 74 | D23: 75 | E23: 83018 | F23: GH-0004 / QA-0004 | G23: ER-2021Q2 / ER-2021Q3 | I23: Guidance_Accuracy!N7 | J23: =(C23+D23)/2 -> 74.5 | K23: =(E23/1000-J23)/ABS(J23) -> 0.11433557 | L23: =E23/1000-J23 -> 8.518
A24: Q4 2021 | B24: Sourced (C:E); Derived (J:L) | C24: 87 | D24: 88 | E24: 95545 | F24: GH-0008 / QA-0006 | G24: ER-2021Q3 / ER-2021Q4 | I24: Guidance_Accuracy!N8 | J24: =(C24+D24)/2 -> 87.5 | K24: =(E24/1000-J24)/ABS(J24) -> 0.091942857 | L24: =E24/1000-J24 -> 8.045
A25: Q1 2022 | B25: Sourced (C:E); Derived (J:L) | C25: 100 | D25: 102 | E25: 108497 | F25: GH-0012 / QA-0008 | G25: ER-2021Q4 / ER-2022Q1 | I25: Guidance_Accuracy!N9 | J25: =(C25+D25)/2 -> 101 | K25: =(E25/1000-J25)/ABS(J25) -> 0.074227723 | L25: =E25/1000-J25 -> 7.497
A26: Q2 2022 | B26: Sourced (C:E); Derived (J:L) | C26: 117 | D26: 119 | E26: 123718 | F26: GH-0016 / QA-0009 | G26: ER-2022Q1 / ER-2022Q2 | I26: Guidance_Accuracy!N10 | J26: =(C26+D26)/2 -> 118 | K26: =(E26/1000-J26)/ABS(J26) -> 0.048457627 | L26: =E26/1000-J26 -> 5.718
A27: Q3 2022 | B27: Sourced (C:E); Derived (J:L) | C27: 130 | D27: 131 | E27: 136893 | F27: GH-0020 / QA-0011 | G27: ER-2022Q2 / ER-2022Q3 | I27: Guidance_Accuracy!N11 | J27: =(C27+D27)/2 -> 130.5 | K27: =(E27/1000-J27)/ABS(J27) -> 0.048988506 | L27: =E27/1000-J27 -> 6.393
A28: Q4 2022 | B28: Sourced (C:E); Derived (J:L) | C28: 140 | D28: 142 | E28: 149921 | F28: GH-0024 / QA-0013 | G28: ER-2022Q3 / ER-2022Q4 | I28: Guidance_Accuracy!N12 | J28: =(C28+D28)/2 -> 141 | K28: =(E28/1000-J28)/ABS(J28) -> 0.063269504 | L28: =E28/1000-J28 -> 8.921
A29: Q1 2023 | B29: Sourced (C:E); Derived (J:L) | C29: 154 | D29: 156 | E29: 162256 | F29: GH-0028 / QA-0015 | G29: ER-2022Q4 / ER-2023Q1 | I29: Guidance_Accuracy!N13 | J29: =(C29+D29)/2 -> 155 | K29: =(E29/1000-J29)/ABS(J29) -> 0.046812903 | L29: =E29/1000-J29 -> 7.256
A30: Q2 2023 | B30: Sourced (C:E); Derived (J:L) | C30: 168 | D30: 170 | E30: 175679 | F30: GH-0032 / QA-0016 | G30: ER-2023Q1 / ER-2023Q2 | I30: Guidance_Accuracy!N14 | J30: =(C30+D30)/2 -> 169 | K30: =(E30/1000-J30)/ABS(J30) -> 0.03952071 | L30: =E30/1000-J30 -> 6.679
A31: Q3 2023 | B31: Sourced (C:E); Derived (J:L) | C31: 181 | D31: 183 | E31: 189190 | F31: GH-0036 / QA-0018 | G31: ER-2023Q2 / ER-2023Q3 | I31: Guidance_Accuracy!N15 | J31: =(C31+D31)/2 -> 182 | K31: =(E31/1000-J31)/ABS(J31) -> 0.039505495 | L31: =E31/1000-J31 -> 7.19
A32: Q4 2023 | B32: Sourced (C:E); Derived (J:L) | C32: 196 | D32: 198 | E32: 202570 | F32: GH-0040 / QA-0020 | G32: ER-2023Q3 / ER-2023Q4 | I32: Guidance_Accuracy!N16 | J32: =(C32+D32)/2 -> 197 | K32: =(E32/1000-J32)/ABS(J32) -> 0.028274112 | L32: =E32/1000-J32 -> 5.57
A33: Q1 2024 | B33: Sourced (C:E); Derived (J:L) | C33: 207 | D33: 211 | E33: 216913 | F33: GH-0046 / QA-0022 | G33: ER-2023Q4 / ER-2024Q1 | I33: Guidance_Accuracy!N17 | J33: =(C33+D33)/2 -> 209 | K33: =(E33/1000-J33)/ABS(J33) -> 0.037861244 | L33: =E33/1000-J33 -> 7.913
A34: Q2 2024 | B34: Sourced (C:E); Derived (J:L) | C34: 226 | D34: 230 | E34: 236106 | F34: GH-0052 / QA-0023 | G34: ER-2024Q1 / ER-2024Q2 | I34: Guidance_Accuracy!N18 | J34: =(C34+D34)/2 -> 228 | K34: =(E34/1000-J34)/ABS(J34) -> 0.035552632 | L34: =E34/1000-J34 -> 8.106
... A42: Q2 2026 | B42: Sourced (C:E); Derived (J:L) | C42: 354 | D42: 356 | E42: 364621 | F42: GH-0094 / QA-0037 | G42: ER-2026Q1 / ER-2026Q2 | I42: Guidance_Accuracy!N26 | J42: =(C42+D42)/2 -> 355 | K42: =(E42/1000-J42)/ABS(J42) -> 0.027101408 | L42: =E42/1000-J42 -> 9.621
A44: 3. Calculation
A45: Item | B45: Label | C45: Value / Low | D45: Mid | E45: High | F45: Row ID / reference | G45: Source ID | H45: Note / rationale | I45: Sensitivity
A46: Q3 2026 guidance midpoint (USD m) | B46: Derived | D46: =(C10+C11)/2 -> 369
A47: Last-8 % beat: min / median / max | B47: Derived | C47: =MIN(K35:K42) -> 0.014826748 | D47: =MEDIAN(K35:K42) -> 0.025426716 | E47: =MAX(K35:K42) -> 0.036179941
A48: All-history (20) % beat: min / median / max | B48: Derived | C48: =MIN(K23:K42) -> 0.014826748 | D48: =MEDIAN(K23:K42) -> 0.037020593 | E48: =MAX(K23:K42) -> 0.11433557
A49: Smallest recent beat scenario (Q4 2025 % beat) | B49: Derived | D49: =K40 -> 0.014826748
A50: Alternative (not the call): all-history beats applied | B50: Derived | C50: =D46*(1+C48)*(1+C18/10000) -> 374.47107 | D50: =D46*(1+D48)*(1+C18/10000) -> 382.6606 | E50: =D46*(1+E48)*(1+C18/10000) -> 411.18983
A51: Scenario (not the call): smallest recent beat (Q4 2025) | B51: Derived | D51: =D46*(1+D49)*(1+C18/10000) -> 374.47107
A53: 4. CALL
...

Sheet OpIncome_Margin
A1: Q3 2026 non-GAAP operating income and margin call
A2: USD millions unless stated. Q3 2026 guidance issued August 10, 2026 (GH-0101), assuming a negative FX impact of 100-200 bps.
A5: 1. METHOD STATEMENT (fixed before computing)
A6: Rule: Call = Q3 2026 non-GAAP operating income guidance midpoint x (1 + historical % beat vs midpoint) x additional-FX factor. Base case (MID) uses the MEDIAN % beat of the last 8 quarters; HIGH the MAXIMUM; LOW uses the smallest recent beat (Q4 2025, ~13%), the quarter in which the company first quantified an FX headwind on margin, because the Q3 guide again quantifies an FX headwind. All-history statistics and a USD-beat version are shown as cross-checks, not used. Margin = operating income call / revenue call at the same point (LOW/LOW, MID/MID, HIGH/HIGH). Additional FX adjustment Assumed at 0 bps beyond the guide's stated 100-200 bps headwind. | B6: Text (method)
A8: 2. Inputs
A9: Item | B9: Label | C9: Value / Low | D9: Mid | E9: High | F9: Row ID / reference | G9: Source ID | H9: Note / rationale | I9: Sensitivity
A10: Q3 2026 non-GAAP op. income guidance - low (USD m) | B10: Sourced | C10: 57 | F10: GH-0101 | G10: ER-2026Q2 | H10: GH-0101; guide assumes negative FX of 100-200 bps
A11: Q3 2026 non-GAAP op. income guidance - high (USD m) | B11: Sourced | C11: 59 | F11: GH-0101 | G11: ER-2026Q2
A12: Q2 2026 non-GAAP operating income (USD k) | B12: Sourced | C12: 61110 | F12: QA-0701 | G12: ER-2026Q2
A13: Q2 2026 revenue (USD k) | B13: Sourced | C13: 364621 | F13: QA-0037 | G13: ER-2026Q2
A14: Additional FX impact on Q3 non-GAAP operating margin beyond guide (bps) | B14: Assumed | C14: 0 | H14: Guide already assumes -100 to -200 bps FX; no post-Aug 10 FX data in source book. | I14: Each -100 bps of margin is about -$3.8M of operating income at the MID revenue call.
A16: Beat history (Sourced guidance and actuals; Derived % beat)
A17: Quarter | B17: Label | C17: Guide low (USD m) | D17: Guide high (USD m) | E17: Actual (USD k) | F17: GH Row ID / QA Row ID | G17: Source IDs | H17: Midpoint (USD m) | % beat vs midpoint | USD m beat | I17: Analysis tie (monday_analysis.xlsx) | J17: Midpoint (USD m) | K17: % beat vs midpoint | L17: USD m beat vs midpoint
A18: Q3 2021 | B18: Sourced (C:E); Derived (J:L) | C18: -26 | D18: -25 | E18: -9449 | F18: GH-0003 / QA-0668 | G18: ER-2021Q2 / ER-2021Q3 | I18: Guidance_Accuracy!N32 | J18: =(C18+D18)/2 -> -25.5 | K18: =(E18/1000-J18)/ABS(J18) -> 0.62945098 | L18: =E18/1000-J18 -> 16.051
A19: Q4 2021 | B19: Sourced (C:E); Derived (J:L) | C19: -23 | D19: -22 | E19: -9929 | F19: GH-0007 / QA-0670 | G19: ER-2021Q3 / ER-2021Q4 | I19: Guidance_Accuracy!N33 | J19: =(C19+D19)/2 -> -22.5 | K19: =(E19/1000-J19)/ABS(J19) -> 0.55871111 | L19: =E19/1000-J19 -> 12.571
A20: Q1 2022 | B20: Sourced (C:E); Derived (J:L) | C20: -47 | D20: -45 | E20: -43830 | F20: GH-0011 / QA-0672 | G20: ER-2021Q4 / ER-2022Q1 | I20: Guidance_Accuracy!N34 | J20: =(C20+D20)/2 -> -46 | K20: =(E20/1000-J20)/ABS(J20) -> 0.047173913 | L20: =E20/1000-J20 -> 2.17
A21: Q2 2022 | B21: Sourced (C:E); Derived (J:L) | C21: -35 | D21: -33 | E21: -15358 | F21: GH-0015 / QA-0673 | G21: ER-2022Q1 / ER-2022Q2 | I21: Guidance_Accuracy!N35 | J21: =(C21+D21)/2 -> -34 | K21: =(E21/1000-J21)/ABS(J21) -> 0.54829412 | L21: =E21/1000-J21 -> 18.642
A22: Q3 2022 | B22: Sourced (C:E); Derived (J:L) | C22: -25 | D22: -24 | E22: -2185 | F22: GH-0019 / QA-0675 | G22: ER-2022Q2 / ER-2022Q3 | I22: Guidance_Accuracy!N36 | J22: =(C22+D22)/2 -> -24.5 | K22: =(E22/1000-J22)/ABS(J22) -> 0.91081633 | L22: =E22/1000-J22 -> 22.315
A23: Q4 2022 | B23: Sourced (C:E); Derived (J:L) | C23: -22 | D23: -20 | E23: 14278 | F23: GH-0023 / QA-0677 | G23: ER-2022Q3 / ER-2022Q4 | I23: Guidance_Accuracy!N37 | J23: =(C23+D23)/2 -> -21 | K23: =(E23/1000-J23)/ABS(J23) -> 1.6799048 | L23: =E23/1000-J23 -> 35.278
A24: Q1 2023 | B24: Sourced (C:E); Derived (J:L) | C24: -19 | D24: -17 | E24: -293 | F24: GH-0027 / QA-0679 | G24: ER-2022Q4 / ER-2023Q1 | I24: Guidance_Accuracy!N38 | J24: =(C24+D24)/2 -> -18 | K24: =(E24/1000-J24)/ABS(J24) -> 0.98372222 | L24: =E24/1000-J24 -> 17.707
A25: Q2 2023 | B25: Sourced (C:E); Derived (J:L) | C25: 2 | D25: 4 | E25: 16617 | F25: GH-0031 / QA-0680 | G25: ER-2023Q1 / ER-2023Q2 | I25: Guidance_Accuracy!N39 | J25: =(C25+D25)/2 -> 3 | K25: =(E25/1000-J25)/ABS(J25) -> 4.539 | L25: =E25/1000-J25 -> 13.617
A26: Q3 2023 | B26: Sourced (C:E); Derived (J:L) | C26: 4 | D26: 6 | E26: 24077 | F26: GH-0035 / QA-0682 | G26: ER-2023Q2 / ER-2023Q3 | I26: Guidance_Accuracy!N40 | J26: =(C26+D26)/2 -> 5 | K26: =(E26/1000-J26)/ABS(J26) -> 3.8154 | L26: =E26/1000-J26 -> 19.077
A27: Q4 2023 | B27: Sourced (C:E); Derived (J:L) | C27: 7 | D27: 9 | E27: 21200 | F27: GH-0039 / QA-0684 | G27: ER-2023Q3 / ER-2023Q4 | I27: Guidance_Accuracy!N41 | J27: =(C27+D27)/2 -> 8 | K27: =(E27/1000-J27)/ABS(J27) -> 1.65 | L27: =E27/1000-J27 -> 13.2
A28: Q1 2024 | B28: Sourced (C:E); Derived (J:L) | C28: 8 | D28: 12 | E28: 21521 | F28: GH-0045 / QA-0686 | G28: ER-2023Q4 / ER-2024Q1 | I28: Guidance_Accuracy!N42 | J28: =(C28+D28)/2 -> 10 | K28: =(E28/1000-J28)/ABS(J28) -> 1.1521 | L28: =E28/1000-J28 -> 11.521
A29: Q2 2024 | B29: Sourced (C:E); Derived (J:L) | C29: 17 | D29: 21 | E29: 38417 | F29: GH-0051 / QA-0687 | G29: ER-2024Q1 / ER-2024Q2 | I29: Guidance_Accuracy!N43 | J29: =(C29+D29)/2 -> 19 | K29: =(E29/1000-J29)/ABS(J29) -> 1.0219474 | L29: =E29/1000-J29 -> 19.417
... A37: Q2 2026 | B37: Sourced (C:E); Derived (J:L) | C37: 46 | D37: 48 | E37: 61110 | F37: GH-0093 / QA-0701 | G37: ER-2026Q1 / ER-2026Q2 | I37: Guidance_Accuracy!N51 | J37: =(C37+D37)/2 -> 47 | K37: =(E37/1000-J37)/ABS(J37) -> 0.30021277 | L37: =E37/1000-J37 -> 14.11
A39: 3. Calculation
A40: Item | B40: Label | C40: Value / Low | D40: Mid | E40: High | F40: Row ID / reference | G40: Source ID | H40: Note / rationale | I40: Sensitivity
A41: Q3 2026 guidance midpoint (USD m) | B41: Derived | D41: =(C10+C11)/2 -> 58
A42: Last-8 % beat: min / median / max | B42: Derived | C42: =MIN(K30:K37) -> 0.13327027 | D42: =MEDIAN(K30:K37) -> 0.34942619 | E42: =MAX(K30:K37) -> 0.56746154
A43: All-history (20) % beat: min / median / max (includes loss-guidance years) | B43: Derived | C43: =MIN(K18:K37) -> 0.047173913 | D43: =MEDIAN(K18:K37) -> 0.56308632 | E43: =MAX(K18:K37) -> 4.539
A44: Smallest recent beat (Q4 2025) | B44: Derived | D44: =K35 -> 0.13327027
A45: Last-8 USD beat: min / median / max (USD m) | B45: Derived | C45: =MIN(L30:L37) -> 4.931 | D45: =MEDIAN(L30:L37) -> 11.637 | E45: =MAX(L30:L37) -> 14.754
A47: 4. CALL
A48: Item | B48: Label | C48: Value / Low | D48: Mid | E48: High | F48: Row ID / reference | G48: Source ID | H48: Note / rationale | I48: Sensitivity
A49: Q3 2026 non-GAAP operating income CALL (USD m) | B49: Derived | C49: =D41*(1+D44)+C14/10000*Revenue!$D$55 -> 65.729676 | D49: =D41*(1+D42)+C14/10000*Revenue!$D$55 -> 78.266719 | E49: =D41*(1+E42)+C14/10000*Revenue!$D$55 -> 90.912769 | H49: LOW = smallest recent beat (Q4 2025); MID = last-8 median; HIGH = last-8 max.
A50: Q3 2026 non-GAAP operating margin CALL | B50: Derived | C50: =C49/Revenue!C55 -> 0.17552671 | D50: =D49/Revenue!D55 -> 0.20684553 | E50: =E49/Revenue!E55 -> 0.23777344 | H50: Op. income call / revenue call at the same point.
A52: Cross-checks
A53: Item | B53: Label | C53: Value / Low | D53: Mid | E53: High | F53: Row ID / reference | G53: Source ID | H53: Note / rationale | I53: Sensitivity
A54: Alternative (not the call): all-history % beats | B54: Derived | C54: =D41*(1+C43) -> 60.736087 | D54: =D41*(1+D43) -> 90.659007 | E54: =D41*(1+E43) -> 321.262
...

Sheet Adj_FCF
A1: Q3 2026 adjusted free cash flow call
A2: USD millions unless stated. FY2026 adjusted FCF guidance $280-290M (GH-0098, Aug 10, 2026).
A5: 1. METHOD STATEMENT (fixed before computing)
A6: Rule: H2 2026 implied adjusted FCF = FY2026 adjusted FCF guidance - H1 2026 actual adjusted FCF. Q3 call = H2 implied x Q3 share of H2 adjusted FCF, using 2023-2025 actuals (years with positive FCF in every quarter). MID = H2 midpoint x MEAN Q3 share; LOW = H2 low x MIN Q3 share; HIGH = H2 high x MAX Q3 share. No guidance-beat factor is applied (method as specified). Restructuring cash: Assumed 0 additional adjustment (the guide is taken as the company's full expectation); sensitivity shown. FX as embedded in the guide (company states -100 to -200 bps). | B6: Text (method)
A8: 2. Inputs
A9: Item | B9: Label | C9: Value / Low | D9: Mid | E9: High | F9: Row ID / reference | G9: Source ID | H9: Note / rationale | I9: Sensitivity
A10: FY2026 adjusted FCF guidance - low (USD m) | B10: Sourced | C10: 280 | F10: GH-0098 | G10: ER-2026Q2
A11: FY2026 adjusted FCF guidance - high (USD m) | B11: Sourced | C11: 290 | F11: GH-0098 | G11: ER-2026Q2
A12: H1 2026 adjusted FCF (USD k) | B12: Sourced | C12: 155122 | F12: QA-1104 | G12: ER-2026Q2
A13: Q3 2023 adjusted FCF / FCF (USD k) | B13: Sourced | C13: 64890 | F13: QA-1084 | G13: ER-2023Q3
A14: Q4 2023 adjusted FCF / FCF (USD k) | B14: Sourced | C14: 55441 | F14: QA-1086 | G14: ER-2023Q4
A15: Q3 2024 adjusted FCF / FCF (USD k) | B15: Sourced | C15: 82412 | F15: QA-1091 | G15: ER-2024Q3
A16: Q4 2024 adjusted FCF / FCF (USD k) | B16: Sourced | C16: 72703 | F16: QA-1093 | G16: ER-2024Q4
A17: Q3 2025 adjusted FCF / FCF (USD k) | B17: Sourced | C17: 92301 | F17: QA-1098 | G17: ER-2025Q3
A18: Q4 2025 adjusted FCF / FCF (USD k) | B18: Sourced | C18: 56734 | F18: QA-1100 | G18: ER-2025Q4
A19: Q3 2023 non-GAAP operating income (USD k) | B19: Sourced | C19: 24077 | F19: QA-0682 | G19: ER-2023Q3
A20: Q3 2024 non-GAAP operating income (USD k) | B20: Sourced | C20: 32180 | F20: QA-0689 | G20: ER-2024Q3
A21: Q3 2025 non-GAAP operating income (USD k) | B21: Sourced | C21: 47484 | F21: QA-0696 | G21: ER-2025Q3
... A24: Q3 2025 revenue (USD k) | B24: Sourced | C24: 316855 | F24: QA-0032 | G24: ER-2025Q3
A25: Additional restructuring cash deducted from Q3 adjusted FCF beyond the FY guide (USD m) | B25: Assumed | C25: 0 | H25: July 22 6-K: FY margin/FCF projections exclude restructuring charges; whether severance cash (~$30-35M est.) is inside the Aug 10 FCF guide is not stated; treat guide as complete. | I25: If severance cash of ~$30-35M falls in Q3 and is outside the guide, Q3 FCF would be ~$30-35M lower than the call.
A27: 3. Calculation
A28: Item | B28: Label | C28: Value / Low | D28: Mid | E28: High | F28: Row ID / reference | G28: Source ID | H28: Note / rationale | I28: Sensitivity
A29: H2 2026 implied adjusted FCF (USD m) | B29: Derived | C29: =C10-C12/1000 -> 124.878 | D29: =(C10+C11)/2-C12/1000 -> 129.878 | E29: =C11-C12/1000 -> 134.878
A30: Q3 share of H2 adjusted FCF, 2023 | B30: Derived | D30: =C13/(C13+C14) -> 0.53926253
A31: Q3 share of H2 adjusted FCF, 2024 | B31: Derived | D31: =C15/(C15+C16) -> 0.53129614
A32: Q3 share of H2 adjusted FCF, 2025 | B32: Derived | D32: =C17/(C17+C18) -> 0.61932432
A33: Q3 share: min / mean / max (2023-2025) | B33: Derived | C33: =MIN(D30,D31,D32) -> 0.53129614 | D33: =AVERAGE(D30,D31,D32) -> 0.56329433 | E33: =MAX(D30,D31,D32) -> 0.61932432
A35: 4. CALL
A36: Item | B36: Label | C36: Value / Low | D36: Mid | E36: High | F36: Row ID / reference | G36: Source ID | H36: Note / rationale | I36: Sensitivity
A37: Q3 2026 adjusted FCF CALL (USD m) | B37: Derived | C37: =C29*C33-C25 -> 66.347199 | D37: =D29*D33-C25 -> 73.159541 | E37: =E29*E33-C25 -> 83.533226 | H37: Derived from guide, H1 actual, seasonality; restructuring adjustment Assumed 0.
A39: Cross-checks
A40: Item | B40: Label | C40: Value / Low | D40: Mid | E40: High | F40: Row ID / reference | G40: Source ID | H40: Note / rationale | I40: Sensitivity
A41: Implied Q3 2026 adjusted FCF margin (vs revenue call) | B41: Derived | C41: =C37/Revenue!C55 -> 0.17717577 | D41: =D37/Revenue!D55 -> 0.19334813 | E41: =E37/Revenue!E55 -> 0.21847297
A42: Actual Q3 adjusted FCF margin 2023-2025: min / mean / max | B42: Derived | C42: =MIN(C13/C22,C15/C23,C17/C24) -> 0.29130359 | D42: =AVERAGE(C13/C22,C15/C23,C17/C24) -> 0.32087559 | E42: =MAX(C13/C22,C15/C23,C17/C24) -> 0.34298853
A43: Implied Q3 2026 FCF / non-GAAP op. income (vs op. income call) | B43: Derived | C43: =C37/OpIncome_Margin!C49 -> 1.0093949 | D43: =D37/OpIncome_Margin!D49 -> 0.93474649 | E43: =E37/OpIncome_Margin!E49 -> 0.9188283
A44: Actual Q3 FCF / non-GAAP op. income 2023-2025: min / mean / max | B44: Derived | C44: =MIN(C13/C19,C15/C20,C17/C21) -> 1.9438337 | D44: =AVERAGE(C13/C19,C15/C20,C17/C21) -> 2.3999688 | E44: =MAX(C13/C19,C15/C20,C17/C21) -> 2.6951032
A46: 5. What would make the call wrong
A47: (a) Restructuring severance cash lands in Q3 outside the guide (sensitivity ~-$30-35M). (b) Q3/Q4 timing differs from 2023-2025 (collections, billing seasonality, or a pricing-model change). (c) The company beats its FY FCF guide as it historically beat quarterly guides; the method applies no beat, so the call is biased low if that pattern holds. | B47: Text
A49: 6. Interview explanation (3 sentences)
A50: I call Q3 2026 adjusted free cash flow at $73.2M (range $66.3M-$83.5M): the $285M full-year guidance midpoint less $155.1M generated in H1 leaves about $130M for H2, and Q3 has historically produced 53%-62% of H2 free cash flow. That implies a Q3 FCF margin of about 19%, far below the 29%-34% of prior third quarters, because the method takes the full-year guide at face value with no beat. The biggest swing factor is restructuring severance cash, roughly $30-35M by the company's estimate; whether it falls in Q3 and whether the guide includes it is not disclosed. | B50: Text

Sheet NDR
A1: Q3 2026 all-customer net dollar retention call
A2: Percent. Exact values disclosed since Q4 2023; floors ("over X%") before that are excluded.
A5: 1. METHOD STATEMENT (fixed before computing)
A6: Rule: Call = latest disclosed all-customer NDR (Q2 2026) + quarterly change over the last 4 quarters (Q3 2025-Q2 2026). MID = latest + MEAN change; LOW = latest + MIN single-quarter change; HIGH = latest + MAX single-quarter change. The company reports whole percentages, so the scorecard treats the call as the whole-percent band from LOW to HIGH. Window 4 quarters is Assumed. | B6: Text (method)
A8: 2. Inputs
A9: Item | B9: Label | C9: Value / Low | D9: Mid | E9: High | F9: Row ID / reference | G9: Source ID | H9: Note / rationale | I9: Sensitivity
A10: Q2 2024 all-customer NDR | B10: Sourced | C10: 1.1 | F10: QA-1312 | G10: ER-2024Q2
A11: Q3 2024 all-customer NDR | B11: Sourced | C11: 1.11 | F11: QA-1313 | G11: ER-2024Q3
A12: Q4 2024 all-customer NDR | B12: Sourced | C12: 1.12 | F12: QA-1314 | G12: ER-2024Q4
A13: Q1 2025 all-customer NDR | B13: Sourced | C13: 1.12 | F13: QA-1315 | G13: ER-2025Q1
A14: Q2 2025 all-customer NDR | B14: Sourced | C14: 1.11 | F14: QA-1316 | G14: ER-2025Q2
A15: Q3 2025 all-customer NDR | B15: Sourced | C15: 1.11 | F15: QA-1317 | G15: ER-2025Q3
A16: Q4 2025 all-customer NDR | B16: Sourced | C16: 1.1 | F16: QA-1318 | G16: ER-2025Q4
A17: Q1 2026 all-customer NDR | B17: Sourced | C17: 1.1 | F17: QA-1319 | G17: ER-2026Q1
A18: Q2 2026 all-customer NDR | B18: Sourced | C18: 1.09 | F18: QA-1320 | G18: ER-2026Q2
A19: Trend window (quarters) | B19: Assumed | C19: 4 | H19: Most recent four quarters capture the anniversary of 2024-H1 2025 pricing adjustments cited by the company. | I19: 8-quarter window gives MID +0.0 pp change (latest 109%); see cross-check.
A21: 3. Calculation
A22: Item | B22: Label | C22: Value / Low | D22: Mid | E22: High | F22: Row ID / reference | G22: Source ID | H22: Note / rationale | I22: Sensitivity
A23: Change Q2 2024 -> Q3 2024 (pp) | B23: Derived | D23: =(C11-C10)*100 -> 1
A24: Change Q3 2024 -> Q4 2024 (pp) | B24: Derived | D24: =(C12-C11)*100 -> 1
A25: Change Q4 2024 -> Q1 2025 (pp) | B25: Derived | D25: =(C13-C12)*100 -> 0
A26: Change Q1 2025 -> Q2 2025 (pp) | B26: Derived | D26: =(C14-C13)*100 -> -1
A27: Change Q2 2025 -> Q3 2025 (pp) | B27: Derived | D27: =(C15-C14)*100 -> 0
A28: Change Q3 2025 -> Q4 2025 (pp) | B28: Derived | D28: =(C16-C15)*100 -> -1
A29: Change Q4 2025 -> Q1 2026 (pp) | B29: Derived | D29: =(C17-C16)*100 -> 0
A30: Change Q1 2026 -> Q2 2026 (pp) | B30: Derived | D30: =(C18-C17)*100 -> -1
A31: Last-4 change (pp): min / mean / max | B31: Derived | C31: =MIN(D27,D28,D29,D30) -> -1 | D31: =AVERAGE(D27,D28,D29,D30) -> -0.5 | E31: =MAX(D27,D28,D29,D30) -> 0
A32: Last-8 change (pp): min / mean / max (cross-check) | B32: Derived | C32: =MIN(D23,D24,D25,D26,D27,D28,D29,D30) -> -1 | D32: =AVERAGE(D23,D24,D25,D26,D27,D28,D29,D30) -> -0.125 | E32: =MAX(D23,D24,D25,D26,D27,D28,D29,D30) -> 1
A34: 4. CALL
A35: Item | B35: Label | C35: Value / Low | D35: Mid | E35: High | F35: Row ID / reference | G35: Source ID | H35: Note / rationale | I35: Sensitivity
A36: Q3 2026 all-customer NDR CALL | B36: Derived | C36: =C18+C31/100 -> 1.08 | D36: =C18+D31/100 -> 1.085 | E36: =C18+E31/100 -> 1.09 | H36: Scored as within range if the reported whole-% NDR is between LOW and HIGH inclusive.
A38: Cross-checks
A39: Item | B39: Label | C39: Value / Low | D39: Mid | E39: High | F39: Row ID / reference | G39: Source ID | H39: Note / rationale | I39: Sensitivity
A40: 8-quarter-window version (not the call) | B40: Derived | C40: =C18+C32/100 -> 1.08 | D40: =C18+D32/100 -> 1.08875 | E40: =C18+E32/100 -> 1.1
A41: Range of exact all-customer NDR, Q2 2024-Q2 2026: min / max | B41: Derived | C41: =MIN(C10,C11,C12,C13,C14,C15,C16,C17,C18) -> 1.09 | E41: =MAX(C10,C11,C12,C13,C14,C15,C16,C17,C18) -> 1.12
A43: 5. What would make the call wrong
A44: (a) NDR basis is not stated (point-in-time vs trailing 12-month weighted average); a trailing basis would move more slowly than the call assumes. (b) Seats-plus-credits / AI pricing (Q1 2026) adds expansion revenue faster than expected. (c) Restructuring-related go-to-market disruption increases contraction. (d) The company could stop or change the disclosure. | B44: Text
A46: 6. Interview explanation (3 sentences)
A47: I call all-customer net dollar retention at 108%-109% for Q3 2026 (midpoint 108.5%), extending the last four quarters' average decline of half a point from Q2's 109%. The company has said the 2024 and early-2025 price increases flattered retention and are now anniversarying, which fits the slow drift down from 112% in late 2024. It could prove wrong if the new seats-plus-credits AI pricing lifts expansion faster than expected, or if the undisclosed calculation basis (point-in-time vs trailing average) behaves differently than the trend assumes. | B47: Text

Sheet Customers_50K
A1: Q3 2026 paid customers with more than $50,000 in ARR - call
A2: Count, point-in-time at September 30, 2026.
A5: 1. METHOD STATEMENT (fixed before computing)
A6: Rule: Call = latest count (Q2 2026) + sequential net additions over the last 4 quarters (Q3 2025-Q2 2026). MID = latest + MEAN net adds; LOW = latest + MIN net adds; HIGH = latest + MAX net adds. Window 4 quarters is Assumed. Net adds are differences of disclosed point-in-time counts (Derived); counts are never summed. | B6: Text (method)
A8: 2. Inputs
A9: Item | B9: Label | C9: Value / Low | D9: Mid | E9: High | F9: Row ID / reference | G9: Source ID | H9: Note / rationale | I9: Sensitivity
A10: Q3 2024 paid customers >$50k ARR | B10: Sourced | C10: 2907 | F10: QA-1419 | G10: ER-2024Q3
A11: Q4 2024 paid customers >$50k ARR | B11: Sourced | C11: 3201 | F11: QA-1420 | G11: ER-2024Q4
A12: Q1 2025 paid customers >$50k ARR | B12: Sourced | C12: 3444 | F12: QA-1421 | G12: ER-2025Q1
A13: Q2 2025 paid customers >$50k ARR | B13: Sourced | C13: 3702 | F13: QA-1422 | G13: ER-2025Q2
A14: Q3 2025 paid customers >$50k ARR | B14: Sourced | C14: 3993 | F14: QA-1423 | G14: ER-2025Q3
A15: Q4 2025 paid customers >$50k ARR | B15: Sourced | C15: 4281 | F15: QA-1424 | G15: ER-2025Q4
A16: Q1 2026 paid customers >$50k ARR | B16: Sourced | C16: 4547 | F16: QA-1425 | G16: ER-2026Q1
A17: Q2 2026 paid customers >$50k ARR | B17: Sourced | C17: 4834 | F17: QA-1426 | G17: ER-2026Q2
A18: Trend window (quarters) | B18: Assumed | C18: 4 | H18: Recent quarters reflect current go-to-market after the 2025 enterprise push and before the July 2026 restructuring. | I18: Using the min/max of the last 4 bounds the call; each +/-10 net adds moves the call by +/-10.
A20: 3. Calculation
A21: Item | B21: Label | C21: Value / Low | D21: Mid | E21: High | F21: Row ID / reference | G21: Source ID | H21: Note / rationale | I21: Sensitivity
A22: Net adds Q2 2025 -> Q3 2025 | B22: Derived | D22: =C14-C13 -> 291
A23: Net adds Q3 2025 -> Q4 2025 | B23: Derived | D23: =C15-C14 -> 288
A24: Net adds Q4 2025 -> Q1 2026 | B24: Derived | D24: =C16-C15 -> 266
A25: Net adds Q1 2026 -> Q2 2026 | B25: Derived | D25: =C17-C16 -> 287
A26: Last-4 net adds: min / mean / max | B26: Derived | C26: =MIN(D22,D23,D24,D25) -> 266 | D26: =AVERAGE(D22,D23,D24,D25) -> 283 | E26: =MAX(D22,D23,D24,D25) -> 291
A28: 4. CALL
A29: Item | B29: Label | C29: Value / Low | D29: Mid | E29: High | F29: Row ID / reference | G29: Source ID | H29: Note / rationale | I29: Sensitivity
A30: Q3 2026 paid customers >$50k ARR CALL | B30: Derived | C30: =C17+C26 -> 5100 | D30: =C17+D26 -> 5117 | E30: =C17+E26 -> 5125
A32: Cross-checks
A33: Item | B33: Label | C33: Value / Low | D33: Mid | E33: High | F33: Row ID / reference | G33: Source ID | H33: Note / rationale | I33: Sensitivity
A34: Implied YoY growth vs Q3 2025 | B34: Derived | C34: =C30/C14-1 -> 0.27723516 | D34: =D30/C14-1 -> 0.28149261 | E34: =E30/C14-1 -> 0.28349612
A35: Actual YoY growth, Q3 2025-Q2 2026: min / mean / max | B35: Derived | C35: =MIN(C14/C10-1,C15/C11-1,C16/C12-1,C17/C13-1) -> 0.30578066 | D35: =AVERAGE(C14/C10-1,C15/C11-1,C16/C12-1,C17/C13-1) -> 0.33425584 | E35: =MAX(C14/C10-1,C15/C11-1,C16/C12-1,C17/C13-1) -> 0.37358101
A36: Actual YoY growth, Q2 2026 (latest) | B36: Derived | D36: =C17/C13-1 -> 0.30578066
A38: 5. What would make the call wrong
A39: (a) The ~20% workforce reduction (July 2026) reaches sales capacity and slows enterprise additions. (b) FX: ARR thresholds are nominal USD; a weaker USD lifts non-USD customers over $50k. (c) Seats-plus-credits pricing moves customers across the threshold faster or slower than recent quarters. | B39: Text
A41: 6. Interview explanation (3 sentences)
A42: I call paid customers above $50K ARR at 5,117 (range 5,100-5,125), adding the average of the last four quarters' net additions (283 a quarter) to Q2's 4,834. That implies about 28% year-over-year growth, a little below Q2's 30.6% and in line with the steady deceleration of this metric. The main risk is that the July 2026 workforce reduction reaches sales capacity, or that FX and the new pricing push customers across the nominal $50K threshold faster or slower than recent quarters. | B42: Text

Sheet cRPO
A1: Q3 2026 current RPO - assessment
A2: USD millions (release values, rounded).
A5: 1. METHOD STATEMENT (fixed before computing)
A6: Rule: a call is registered only if (i) at least four consecutive quarterly cRPO values and (ii) at least one prior Q3 observation (for seasonality) are disclosed on a consistent basis. If either condition fails, NO CALL is registered and the data inventory is shown. | B6: Text (method)
A8: 2. Inputs (all cRPO values in the source book)
A9: Item | B9: Label | C9: Value / Low | D9: Mid | E9: High | F9: Row ID / reference | G9: Source ID | H9: Note / rationale | I9: Sensitivity
A10: Q4 2024 cRPO (USD m) | B10: Sourced | C10: 516 | F10: QA-1519 | G10: ER-2025Q4
A11: Q1 2025 cRPO (USD m) | B11: Sourced | C11: 568 | F11: QA-1520 | G11: ER-2026Q1
A12: Q2 2025 cRPO (USD m) | B12: Sourced | C12: 588 | F12: QA-1521 | G12: ER-2026Q2
A13: Q4 2025 cRPO (USD m) | B13: Sourced | C13: 676 | F13: QA-1522 | G13: ER-2025Q4
A14: Q1 2026 cRPO (USD m) | B14: Sourced | C14: 716 | F14: QA-1523 | G14: ER-2026Q1
A15: Q2 2026 cRPO (USD m) | B15: Sourced | C15: 750 | F15: QA-1524 | G15: ER-2026Q2
A17: 3. Test of the rule
A18: Item | B18: Label | C18: Value / Low | D18: Mid | E18: High | F18: Row ID / reference | G18: Source ID | H18: Note / rationale | I18: Sensitivity
A19: Count of disclosed cRPO values | B19: Derived | D19: =COUNT(C10,C11,C12,C13,C14,C15) -> 6
A20: Q3 2025 (Sep 30, 2025) cRPO disclosed? | B20: Text | D20: No | H20: Q3 2025 release disclosed total RPO only; cRPO began Q4 2025 (comparatives from Dec 31, 2024).
A21: Longest run of consecutive quarterly values | B21: Text | D21: 3 quarters | H21: Q4 2025-Q2 2026 (and Q4 2024-Q2 2025); gap at Q3 2025.
A22: June 30, 2025 RPO basis | B22: Text | D22: Recast | H22: Source book D4/R2: June 30, 2025 RPO recast without explanation ($767.8M -> $699M); cRPO basis consistency unverified.
A24: 4. CALL
A25: Item | B25: Label | C25: Value / Low | D25: Mid | E25: High | F25: Row ID / reference | G25: Source ID | H25: Note / rationale | I25: Sensitivity
A26: Q3 2026 cRPO CALL | B26: Text | D26: NO CALL - too sparse | H26: Fails both conditions: no Q3 observation and only 3 consecutive quarters; plus the June 2025 RPO recast.
A28: 5. What would make this assessment wrong
A29: If the company were to disclose Q3 2025 cRPO in the Q3 2026 release (as a comparative), the seasonality gap would close for future calls; it does not change this pre-registered decision. | B29: Text
A31: 6. Interview explanation (3 sentences)
A32: I am not registering a current RPO call, because the company has disclosed only six cRPO values, with no Q3 observation and a gap at September 2025, so there is no seasonal reference point. The pre-set rule required at least four consecutive quarters and one prior Q3 on a consistent basis, and the June 2025 RPO recast also leaves the basis unverified. I will record the reported figure for reference, but it is not scored. | B32: Text

Sheet Assumptions
A1: Assumed values (every Assumed value in the workbook; each links to the cell that drives the call)
A3: Sheet | B3: Cell | C3: Assumption | D3: Value (link) | E3: One-line rationale | F3: Sensitivity
A4: Revenue | B4: C18 | C4: Additional FX adjustment to Q3 revenue vs guidance (bps) | D4: =Revenue!C18 -> 0 | E4: Revenue guidance states no FX assumption; no FX data after Aug 10 is in the source book; assume FX is as embedded in the guide. | F4: Each +/-100 bps changes the call by about +/-$3.8M (1% of the MID call).
A5: Revenue | B5: C19 | C5: Beat window used for the call (quarters) | D5: =Revenue!C19 -> 8 | E5: Recent 8 quarters reflect the current scale and guidance practice; all-history (20) shown as alternative. | F5: All-history MID would be higher (median 3.7% vs 2.5% beat); see section 3.
A6: OpIncome_Margin | B6: C14 | C6: Additional FX impact on Q3 non-GAAP operating margin beyond guide (bps) | D6: =OpIncome_Margin!C14 -> 0 | E6: Guide already assumes -100 to -200 bps FX; no post-Aug 10 FX data in source book. | F6: Each -100 bps of margin is about -$3.8M of operating income at the MID revenue call.
A7: Adj_FCF | B7: C25 | C7: Additional restructuring cash deducted from Q3 adjusted FCF beyond the FY guide (USD m) | D7: =Adj_FCF!C25 -> 0 | E7: July 22 6-K: FY margin/FCF projections exclude restructuring charges; whether severance cash (~$30-35M est.) is inside the Aug 10 FCF guide is not stated; treat guide as complete. | F7: If severance cash of ~$30-35M falls in Q3 and is outside the guide, Q3 FCF would be ~$30-35M lower than the call.
A8: NDR | B8: C19 | C8: Trend window (quarters) | D8: =NDR!C19 -> 4 | E8: Most recent four quarters capture the anniversary of 2024-H1 2025 pricing adjustments cited by the company. | F8: 8-quarter window gives MID +0.0 pp change (latest 109%); see cross-check.
A9: Customers_50K | B9: C18 | C9: Trend window (quarters) | D9: =Customers_50K!C18 -> 4 | E9: Recent quarters reflect current go-to-market after the 2025 enterprise push and before the July 2026 restructuring. | F9: Using the min/max of the last 4 bounds the call; each +/-10 net adds moves the call by +/-10.

Sheet Scorecard
A1: Scorecard - Q3 2026 (to be completed after November 9, 2026 WITHOUT changing the call)
A2: Low/Mid/High are links to the call cells (Derived). "Actual" and "Within range?" are intentionally blank until results are reported.
A4: Metric | B4: Unit | C4: Low | D4: Mid | E4: High | F4: Actual | G4: Within range? | H4: Scoring rule | I4: Label
A5: Revenue (USD m) | B5: USD millions | C5: =Revenue!C55 -> 374.47107 | D5: =Revenue!D55 -> 378.38246 | E5: =Revenue!E55 -> 382.3504 | H5: Within range if LOW <= actual <= HIGH (actual as reported by the company). | I5: Derived (links); F:G blank
A6: Non-GAAP operating income (USD m) | B6: USD millions | C6: =OpIncome_Margin!C49 -> 65.729676 | D6: =OpIncome_Margin!D49 -> 78.266719 | E6: =OpIncome_Margin!E49 -> 90.912769 | H6: Within range if LOW <= actual <= HIGH (actual as reported by the company). | I6: Derived (links); F:G blank
A7: Non-GAAP operating margin | B7: percentage | C7: =OpIncome_Margin!C50 -> 0.17552671 | D7: =OpIncome_Margin!D50 -> 0.20684553 | E7: =OpIncome_Margin!E50 -> 0.23777344 | H7: Within range if LOW <= actual <= HIGH (actual as reported by the company). | I7: Derived (links); F:G blank
A8: Adjusted free cash flow (USD m) | B8: USD millions | C8: =Adj_FCF!C37 -> 66.347199 | D8: =Adj_FCF!D37 -> 73.159541 | E8: =Adj_FCF!E37 -> 83.533226 | H8: Within range if LOW <= actual <= HIGH (actual as reported by the company). | I8: Derived (links); F:G blank
A9: All-customer net dollar retention | B9: percentage | C9: =NDR!C36 -> 1.08 | D9: =NDR!D36 -> 1.085 | E9: =NDR!E36 -> 1.09 | H9: Within range if reported whole-% NDR is between ROUND(LOW) and ROUND(HIGH) inclusive. | I9: Derived (links); F:G blank
A10: Paid customers >$50k ARR | B10: customer count | C10: =Customers_50K!C30 -> 5100 | D10: =Customers_50K!D30 -> 5117 | E10: =Customers_50K!E30 -> 5125 | H10: Within range if LOW <= actual <= HIGH (actual as reported by the company). | I10: Derived (links); F:G blank
A11: Current RPO (cRPO) | B11: USD millions | C11: NO CALL | D11: NO CALL | E11: NO CALL | H11: No call registered (too sparse; see cRPO sheet). Record the actual for reference only. | I11: Text; F:G blank

Sheet Checks
A1: Checks: every input tied to its source row (re-read by Row ID from monday_sourcebook.xlsx; beat % tied to monday_analysis.xlsx) + call ordering
A3: Check ID | B3: Type | C3: Cell | D3: Source row / reference | E3: Workbook value | F3: Source value (re-read) | G3: Difference | H3: Status | I3: Note
A4: C3-0001 | B4: Source book GH | C4: Revenue!C10 | D4: GH-0102 | E4: =Revenue!C10 -> 368 | F4: 368 | G4: =E4-F4 -> 0 | H4: =IF(ABS(G4)<=0.000001,"PASS","FAIL") -> PASS
A5: C3-0002 | B5: Source book GH | C5: Revenue!C11 | D5: GH-0102 | E5: =Revenue!C11 -> 370 | F5: 370 | G5: =E5-F5 -> 0 | H5: =IF(ABS(G5)<=0.000001,"PASS","FAIL") -> PASS
A6: C3-0003 | B6: Source book QA | C6: Revenue!C12 | D6: QA-0037 | E6: =Revenue!C12 -> 364621 | F6: 364621 | G6: =E6-F6 -> 0 | H6: =IF(ABS(G6)<=0.000001,"PASS","FAIL") -> PASS
A7: C3-0004 | B7: Source book QA | C7: Revenue!C13 | D7: QA-0032 | E7: =Revenue!C13 -> 316855 | F7: 316855 | G7: =E7-F7 -> 0 | H7: =IF(ABS(G7)<=0.000001,"PASS","FAIL") -> PASS
A8: C3-0005 | B8: Source book QA | C8: Revenue!C14 | D8: QA-0029 | E8: =Revenue!C14 -> 282250 | F8: 282250 | G8: =E8-F8 -> 0 | H8: =IF(ABS(G8)<=0.000001,"PASS","FAIL") -> PASS
A9: C3-0006 | B9: Source book QA | C9: Revenue!C15 | D9: QA-0030 | E9: =Revenue!C15 -> 299014 | F9: 299014 | G9: =E9-F9 -> 0 | H9: =IF(ABS(G9)<=0.000001,"PASS","FAIL") -> PASS
A10: C3-0007 | B10: Source book QA | C10: Revenue!C16 | D10: QA-0034 | E10: =Revenue!C16 -> 333878 | F10: 333878 | G10: =E10-F10 -> 0 | H10: =IF(ABS(G10)<=0.000001,"PASS","FAIL") -> PASS
A11: C3-0008 | B11: Source book QA | C11: Revenue!C17 | D11: QA-0036 | E11: =Revenue!C17 -> 351265 | F11: 351265 | G11: =E11-F11 -> 0 | H11: =IF(ABS(G11)<=0.000001,"PASS","FAIL") -> PASS
A12: C3-0009 | B12: Source book GH | C12: Revenue!C23 | D12: GH-0004 | E12: =Revenue!C23 -> 74 | F12: 74 | G12: =E12-F12 -> 0 | H12: =IF(ABS(G12)<=0.000001,"PASS","FAIL") -> PASS
A13: C3-0010 | B13: Source book GH | C13: Revenue!D23 | D13: GH-0004 | E13: =Revenue!D23 -> 75 | F13: 75 | G13: =E13-F13 -> 0 | H13: =IF(ABS(G13)<=0.000001,"PASS","FAIL") -> PASS
A14: C3-0011 | B14: Source book QA | C14: Revenue!E23 | D14: QA-0004 | E14: =Revenue!E23 -> 83018 | F14: 83018 | G14: =E14-F14 -> 0 | H14: =IF(ABS(G14)<=0.000001,"PASS","FAIL") -> PASS
A15: C3-0012 | B15: Analysis tie (% beat) | C15: Revenue!K23 | D15: Guidance_Accuracy!N7 | E15: =Revenue!K23 -> 0.11433557 | F15: 0.11433557 | G15: =E15-F15 -> 0 | H15: =IF(ABS(G15)<=0.000001,"PASS","FAIL") -> PASS
A16: C3-0013 | B16: Source book GH | C16: Revenue!C24 | D16: GH-0008 | E16: =Revenue!C24 -> 87 | F16: 87 | G16: =E16-F16 -> 0 | H16: =IF(ABS(G16)<=0.000001,"PASS","FAIL") -> PASS
A17: C3-0014 | B17: Source book GH | C17: Revenue!D24 | D17: GH-0008 | E17: =Revenue!D24 -> 88 | F17: 88 | G17: =E17-F17 -> 0 | H17: =IF(ABS(G17)<=0.000001,"PASS","FAIL") -> PASS
A18: C3-0015 | B18: Source book QA | C18: Revenue!E24 | D18: QA-0006 | E18: =Revenue!E24 -> 95545 | F18: 95545 | G18: =E18-F18 -> 0 | H18: =IF(ABS(G18)<=0.000001,"PASS","FAIL") -> PASS
A19: C3-0016 | B19: Analysis tie (% beat) | C19: Revenue!K24 | D19: Guidance_Accuracy!N8 | E19: =Revenue!K24 -> 0.091942857 | F19: 0.091942857 | G19: =E19-F19 -> 0 | H19: =IF(ABS(G19)<=0.000001,"PASS","FAIL") -> PASS
A20: C3-0017 | B20: Source book GH | C20: Revenue!C25 | D20: GH-0012 | E20: =Revenue!C25 -> 100 | F20: 100 | G20: =E20-F20 -> 0 | H20: =IF(ABS(G20)<=0.000001,"PASS","FAIL") -> PASS
A21: C3-0018 | B21: Source book GH | C21: Revenue!D25 | D21: GH-0012 | E21: =Revenue!D25 -> 102 | F21: 102 | G21: =E21-F21 -> 0 | H21: =IF(ABS(G21)<=0.000001,"PASS","FAIL") -> PASS
A22: C3-0019 | B22: Source book QA | C22: Revenue!E25 | D22: QA-0008 | E22: =Revenue!E25 -> 108497 | F22: 108497 | G22: =E22-F22 -> 0 | H22: =IF(ABS(G22)<=0.000001,"PASS","FAIL") -> PASS
A23: C3-0020 | B23: Analysis tie (% beat) | C23: Revenue!K25 | D23: Guidance_Accuracy!N9 | E23: =Revenue!K25 -> 0.074227723 | F23: 0.074227723 | G23: =E23-F23 -> 0 | H23: =IF(ABS(G23)<=0.000001,"PASS","FAIL") -> PASS
A24: C3-0021 | B24: Source book GH | C24: Revenue!C26 | D24: GH-0016 | E24: =Revenue!C26 -> 117 | F24: 117 | G24: =E24-F24 -> 0 | H24: =IF(ABS(G24)<=0.000001,"PASS","FAIL") -> PASS
A25: C3-0022 | B25: Source book GH | C25: Revenue!D26 | D25: GH-0016 | E25: =Revenue!D26 -> 119 | F25: 119 | G25: =E25-F25 -> 0 | H25: =IF(ABS(G25)<=0.000001,"PASS","FAIL") -> PASS
A26: C3-0023 | B26: Source book QA | C26: Revenue!E26 | D26: QA-0009 | E26: =Revenue!E26 -> 123718 | F26: 123718 | G26: =E26-F26 -> 0 | H26: =IF(ABS(G26)<=0.000001,"PASS","FAIL") -> PASS
A27: C3-0024 | B27: Analysis tie (% beat) | C27: Revenue!K26 | D27: Guidance_Accuracy!N10 | E27: =Revenue!K26 -> 0.048457627 | F27: 0.048457627 | G27: =E27-F27 -> 0 | H27: =IF(ABS(G27)<=0.000001,"PASS","FAIL") -> PASS
A28: C3-0025 | B28: Source book GH | C28: Revenue!C27 | D28: GH-0020 | E28: =Revenue!C27 -> 130 | F28: 130 | G28: =E28-F28 -> 0 | H28: =IF(ABS(G28)<=0.000001,"PASS","FAIL") -> PASS
A29: C3-0026 | B29: Source book GH | C29: Revenue!D27 | D29: GH-0020 | E29: =Revenue!D27 -> 131 | F29: 131 | G29: =E29-F29 -> 0 | H29: =IF(ABS(G29)<=0.000001,"PASS","FAIL") -> PASS
A30: C3-0027 | B30: Source book QA | C30: Revenue!E27 | D30: QA-0011 | E30: =Revenue!E27 -> 136893 | F30: 136893 | G30: =E30-F30 -> 0 | H30: =IF(ABS(G30)<=0.000001,"PASS","FAIL") -> PASS
A31: C3-0028 | B31: Analysis tie (% beat) | C31: Revenue!K27 | D31: Guidance_Accuracy!N11 | E31: =Revenue!K27 -> 0.048988506 | F31: 0.048988506 | G31: =E31-F31 -> 0 | H31: =IF(ABS(G31)<=0.000001,"PASS","FAIL") -> PASS
A32: C3-0029 | B32: Source book GH | C32: Revenue!C28 | D32: GH-0024 | E32: =Revenue!C28 -> 140 | F32: 140 | G32: =E32-F32 -> 0 | H32: =IF(ABS(G32)<=0.000001,"PASS","FAIL") -> PASS
A33: C3-0030 | B33: Source book GH | C33: Revenue!D28 | D33: GH-0024 | E33: =Revenue!D28 -> 142 | F33: 142 | G33: =E33-F33 -> 0 | H33: =IF(ABS(G33)<=0.000001,"PASS","FAIL") -> PASS
A34: C3-0031 | B34: Source book QA | C34: Revenue!E28 | D34: QA-0013 | E34: =Revenue!E28 -> 149921 | F34: 149921 | G34: =E34-F34 -> 0 | H34: =IF(ABS(G34)<=0.000001,"PASS","FAIL") -> PASS
A35: C3-0032 | B35: Analysis tie (% beat) | C35: Revenue!K28 | D35: Guidance_Accuracy!N12 | E35: =Revenue!K28 -> 0.063269504 | F35: 0.063269504 | G35: =E35-F35 -> 0 | H35: =IF(ABS(G35)<=0.000001,"PASS","FAIL") -> PASS
A36: C3-0033 | B36: Source book GH | C36: Revenue!C29 | D36: GH-0028 | E36: =Revenue!C29 -> 154 | F36: 154 | G36: =E36-F36 -> 0 | H36: =IF(ABS(G36)<=0.000001,"PASS","FAIL") -> PASS
A37: C3-0034 | B37: Source book GH | C37: Revenue!D29 | D37: GH-0028 | E37: =Revenue!D29 -> 156 | F37: 156 | G37: =E37-F37 -> 0 | H37: =IF(ABS(G37)<=0.000001,"PASS","FAIL") -> PASS
A38: C3-0035 | B38: Source book QA | C38: Revenue!E29 | D38: QA-0015 | E38: =Revenue!E29 -> 162256 | F38: 162256 | G38: =E38-F38 -> 0 | H38: =IF(ABS(G38)<=0.000001,"PASS","FAIL") -> PASS
A39: C3-0036 | B39: Analysis tie (% beat) | C39: Revenue!K29 | D39: Guidance_Accuracy!N13 | E39: =Revenue!K29 -> 0.046812903 | F39: 0.046812903 | G39: =E39-F39 -> 0 | H39: =IF(ABS(G39)<=0.000001,"PASS","FAIL") -> PASS
A40: C3-0037 | B40: Source book GH | C40: Revenue!C30 | D40: GH-0032 | E40: =Revenue!C30 -> 168 | F40: 168 | G40: =E40-F40 -> 0 | H40: =IF(ABS(G40)<=0.000001,"PASS","FAIL") -> PASS
A41: C3-0038 | B41: Source book GH | C41: Revenue!D30 | D41: GH-0032 | E41: =Revenue!D30 -> 170 | F41: 170 | G41: =E41-F41 -> 0 | H41: =IF(ABS(G41)<=0.000001,"PASS","FAIL") -> PASS
...
