Workbook

Sheet README
A1: monday.com Operating Plan & Rolling Reforecast - Phase 1 Historical Analysis
A3: Purpose | B3: Historical analysis of monday.com built entirely on the Phase 0 source book (monday_sourcebook.xlsx). It measures guidance accuracy, places revenue growth beside disclosed KPIs, describes margin and cash-conversion structure, and computes what current guidance arithmetically implies for H2 2026.
A4: Information cutoff | B4: October 28, 2026 (inherited from the source book; latest underlying filing August 10, 2026).
A5: Source | B5: monday_sourcebook.xlsx only (branch phase0-sourcebook). No new data sources. Every input is a copy of a source-book value with the source-book Row ID (and Source ID) beside it.
A6: Labels | B6: Sourced (copied from source book) = blue font hard-code, Row ID adjacent. Derived = black-font live formula. Assumed = none in Phase 1. The second header row of every table states the label for every cell in that column; "Text / label", "Row ID" and "Source ID" columns are identifiers, not data.
A7: Assumed values | B7: NONE. Presentation conventions (e.g., pairing guidance range ends low-with-low in the H2-implied table, choosing 2022-2025 as the seasonality window) are stated next to the table and are not data assumptions.
A8: What Phase 1 does NOT do | B8: No forecast, no operating plan, no Q3 2026 call, no scenario, no driver model, no assertion that any KPI drives revenue, no smoothing / annualizing / normalizing of any series (the 2025 commission change is shown, not adjusted), no modification of the source book.
A9: Units | B9: USD thousands for actuals (as in the source book); USD millions for guidance; percentages as decimals displayed as %; basis points for FX; counts for customers.
A10: Sheets | B10: Guidance_Accuracy, Growth_Decomposition, Margin_Structure, Cash_Conversion, Deceleration, Findings, Checks.
A11: Checks | B11: Every copied input is re-read from the source book by Row ID and compared (Checks sheet), plus internal arithmetic tie-outs.
A13: Blank source-book values encountered (left blank, not filled)
A15: Structural blanks | B15: YoY growth for 2021 quarters (2020 quarters not in source book); KPI cohorts before their first disclosure (see Growth_Decomposition flags); quarterly FCF guidance outside 2024; revenue FX impact Q3 2024-Q1 2026; commission % for quarters (only annual / half-year disclosed).

Sheet Guidance_Accuracy
A1: Guidance accuracy: next-quarter guidance vs. reported actual
A2: Guidance (USD millions) copied from Guidance_History; actuals (USD thousands) copied from Quarterly_Actuals. Every quarter with a guidance vintage issued in the prior quarter's release is included. Q3 2026 guidance (GH-0101/GH-0102) has no actual yet and is excluded.
A4: Revenue
A5: Quarter | B5: GH Row ID | C5: Source ID | D5: Guidance issued | E5: Guidance metric label | F5: Low (USD m) | G5: High (USD m) | H5: Midpoint (USD m) | I5: Actual (USD k) | J5: Actual Row ID | K5: Actual Source ID | L5: Actual (USD m) | M5: Actual - midpoint (USD m) | N5: % difference vs midpoint | O5: Outcome | P5: Beat top (1/0) | Q5: In range (1/0) | R5: Missed bottom (1/0) | S5: Disclosed FX impact on revenue growth (bps) | T5: FX Row ID | U5: FX Source ID | V5: Disclosed FX impact on non-GAAP op. margin (bps) | W5: FX Row ID | X5: FX Source ID | Y5: FX assumption stated in the guidance (copied text) and notes
A6: Text / label | B6: Source-book Row ID | C6: Source ID | D6: Sourced (copied) | E6: Sourced (copied) | F6: Sourced (copied from source book) | G6: Sourced (copied from source book) | H6: Derived (formula) | I6: Sourced (copied from source book) | J6: Source-book Row ID | K6: Source ID | L6: Derived (formula) | M6: Derived (formula) | N6: Derived (formula) | O6: Derived (formula) | P6: Derived (formula) | Q6: Derived (formula) | R6: Derived (formula) | S6: Sourced (copied from source book) | T6: Source-book Row ID | U6: Source ID | V6: Sourced (copied from source book) | W6: Source-book Row ID | X6: Source ID | Y6: Sourced text / note
A7: Q3 2021 | B7: GH-0004 | C7: ER-2021Q2 | D7: 44425 | E7: Revenue | F7: 74 | G7: 75 | H7: =(F7+G7)/2 -> 74.5 | I7: 83018 | J7: QA-0004 | K7: ER-2021Q3 | L7: =I7/1000 -> 83.018 | M7: =L7-H7 -> 8.518 | N7: =M7/ABS(H7) -> 0.11433557 | O7: =IF(L7>G7,"Beat top",IF(L7>=F7,"In range","Missed bottom")) -> Beat top | P7: =IF(L7>G7,1,0) -> 1 | Q7: =IF(AND(L7>=F7,L7<=G7),1,0) -> 0 | R7: =IF(L7<F7,1,0) -> 0
A8: Q4 2021 | B8: GH-0008 | C8: ER-2021Q3 | D8: 44510 | E8: Revenue | F8: 87 | G8: 88 | H8: =(F8+G8)/2 -> 87.5 | I8: 95545 | J8: QA-0006 | K8: ER-2021Q4 | L8: =I8/1000 -> 95.545 | M8: =L8-H8 -> 8.045 | N8: =M8/ABS(H8) -> 0.091942857 | O8: =IF(L8>G8,"Beat top",IF(L8>=F8,"In range","Missed bottom")) -> Beat top | P8: =IF(L8>G8,1,0) -> 1 | Q8: =IF(AND(L8>=F8,L8<=G8),1,0) -> 0 | R8: =IF(L8<F8,1,0) -> 0
A9: Q1 2022 | B9: GH-0012 | C9: ER-2021Q4 | D9: 44615 | E9: Revenue | F9: 100 | G9: 102 | H9: =(F9+G9)/2 -> 101 | I9: 108497 | J9: QA-0008 | K9: ER-2022Q1 | L9: =I9/1000 -> 108.497 | M9: =L9-H9 -> 7.497 | N9: =M9/ABS(H9) -> 0.074227723 | O9: =IF(L9>G9,"Beat top",IF(L9>=F9,"In range","Missed bottom")) -> Beat top | P9: =IF(L9>G9,1,0) -> 1 | Q9: =IF(AND(L9>=F9,L9<=G9),1,0) -> 0 | R9: =IF(L9<F9,1,0) -> 0 | S9: -100 | T9: QA-1546 | U9: ER-2022Q3
A10: Q2 2022 | B10: GH-0016 | C10: ER-2022Q1 | D10: 44697 | E10: Revenue | F10: 117 | G10: 119 | H10: =(F10+G10)/2 -> 118 | I10: 123718 | J10: QA-0009 | K10: ER-2022Q2 | L10: =I10/1000 -> 123.718 | M10: =L10-H10 -> 5.718 | N10: =M10/ABS(H10) -> 0.048457627 | O10: =IF(L10>G10,"Beat top",IF(L10>=F10,"In range","Missed bottom")) -> Beat top | P10: =IF(L10>G10,1,0) -> 1 | Q10: =IF(AND(L10>=F10,L10<=G10),1,0) -> 0 | R10: =IF(L10<F10,1,0) -> 0 | S10: -200 | T10: QA-1547 | U10: ER-2022Q3
A11: Q3 2022 | B11: GH-0020 | C11: ER-2022Q2 | D11: 44781 | E11: Revenue | F11: 130 | G11: 131 | H11: =(F11+G11)/2 -> 130.5 | I11: 136893 | J11: QA-0011 | K11: ER-2022Q3 | L11: =I11/1000 -> 136.893 | M11: =L11-H11 -> 6.393 | N11: =M11/ABS(H11) -> 0.048988506 | O11: =IF(L11>G11,"Beat top",IF(L11>=F11,"In range","Missed bottom")) -> Beat top | P11: =IF(L11>G11,1,0) -> 1 | Q11: =IF(AND(L11>=F11,L11<=G11),1,0) -> 0 | R11: =IF(L11<F11,1,0) -> 0 | S11: -300 | T11: QA-1548 | U11: ER-2022Q3
A12: Q4 2022 | B12: GH-0024 | C12: ER-2022Q3 | D12: 44879 | E12: Revenue | F12: 140 | G12: 142 | H12: =(F12+G12)/2 -> 141 | I12: 149921 | J12: QA-0013 | K12: ER-2022Q4 | L12: =I12/1000 -> 149.921 | M12: =L12-H12 -> 8.921 | N12: =M12/ABS(H12) -> 0.063269504 | O12: =IF(L12>G12,"Beat top",IF(L12>=F12,"In range","Missed bottom")) -> Beat top | P12: =IF(L12>G12,1,0) -> 1 | Q12: =IF(AND(L12>=F12,L12<=G12),1,0) -> 0 | R12: =IF(L12<F12,1,0) -> 0 | S12: -300 | T12: QA-1549 | U12: ER-2022Q4
A13: Q1 2023 | B13: GH-0028 | C13: ER-2022Q4 | D13: 44970 | E13: Revenue | F13: 154 | G13: 156 | H13: =(F13+G13)/2 -> 155 | I13: 162256 | J13: QA-0015 | K13: ER-2023Q1 | L13: =I13/1000 -> 162.256 | M13: =L13-H13 -> 7.256 | N13: =M13/ABS(H13) -> 0.046812903 | O13: =IF(L13>G13,"Beat top",IF(L13>=F13,"In range","Missed bottom")) -> Beat top | P13: =IF(L13>G13,1,0) -> 1 | Q13: =IF(AND(L13>=F13,L13<=G13),1,0) -> 0 | R13: =IF(L13<F13,1,0) -> 0 | S13: -100 | T13: QA-1551 | U13: ER-2023Q1
A14: Q2 2023 | B14: GH-0032 | C14: ER-2023Q1 | D14: 45061 | E14: Revenue | F14: 168 | G14: 170 | H14: =(F14+G14)/2 -> 169 | I14: 175679 | J14: QA-0016 | K14: ER-2023Q2 | L14: =I14/1000 -> 175.679 | M14: =L14-H14 -> 6.679 | N14: =M14/ABS(H14) -> 0.03952071 | O14: =IF(L14>G14,"Beat top",IF(L14>=F14,"In range","Missed bottom")) -> Beat top | P14: =IF(L14>G14,1,0) -> 1 | Q14: =IF(AND(L14>=F14,L14<=G14),1,0) -> 0 | R14: =IF(L14<F14,1,0) -> 0 | S14: -100 | T14: QA-1552 | U14: ER-2023Q2
A15: Q3 2023 | B15: GH-0036 | C15: ER-2023Q2 | D15: 45152 | E15: Revenue | F15: 181 | G15: 183 | H15: =(F15+G15)/2 -> 182 | I15: 189190 | J15: QA-0018 | K15: ER-2023Q3 | L15: =I15/1000 -> 189.19 | M15: =L15-H15 -> 7.19 | N15: =M15/ABS(H15) -> 0.039505495 | O15: =IF(L15>G15,"Beat top",IF(L15>=F15,"In range","Missed bottom")) -> Beat top | P15: =IF(L15>G15,1,0) -> 1 | Q15: =IF(AND(L15>=F15,L15<=G15),1,0) -> 0 | R15: =IF(L15<F15,1,0) -> 0 | S15: 0 | T15: QA-1553 | U15: ER-2023Q3
A16: Q4 2023 | B16: GH-0040 | C16: ER-2023Q3 | D16: 45243 | E16: Revenue | F16: 196 | G16: 198 | H16: =(F16+G16)/2 -> 197 | I16: 202570 | J16: QA-0020 | K16: ER-2023Q4 | L16: =I16/1000 -> 202.57 | M16: =L16-H16 -> 5.57 | N16: =M16/ABS(H16) -> 0.028274112 | O16: =IF(L16>G16,"Beat top",IF(L16>=F16,"In range","Missed bottom")) -> Beat top | P16: =IF(L16>G16,1,0) -> 1 | Q16: =IF(AND(L16>=F16,L16<=G16),1,0) -> 0 | R16: =IF(L16<F16,1,0) -> 0 | S16: 0 | T16: QA-1554 | U16: ER-2023Q4
A17: Q1 2024 | B17: GH-0046 | C17: ER-2023Q4 | D17: 45334 | E17: Revenue | F17: 207 | G17: 211 | H17: =(F17+G17)/2 -> 209 | I17: 216913 | J17: QA-0022 | K17: ER-2024Q1 | L17: =I17/1000 -> 216.913 | M17: =L17-H17 -> 7.913 | N17: =M17/ABS(H17) -> 0.037861244 | O17: =IF(L17>G17,"Beat top",IF(L17>=F17,"In range","Missed bottom")) -> Beat top | P17: =IF(L17>G17,1,0) -> 1 | Q17: =IF(AND(L17>=F17,L17<=G17),1,0) -> 0 | R17: =IF(L17<F17,1,0) -> 0 | S17: 0 | T17: QA-1556 | U17: ER-2024Q1
A18: Q2 2024 | B18: GH-0052 | C18: ER-2024Q1 | D18: 45427 | E18: Revenue | F18: 226 | G18: 230 | H18: =(F18+G18)/2 -> 228 | I18: 236106 | J18: QA-0023 | K18: ER-2024Q2 | L18: =I18/1000 -> 236.106 | M18: =L18-H18 -> 8.106 | N18: =M18/ABS(H18) -> 0.035552632 | O18: =IF(L18>G18,"Beat top",IF(L18>=F18,"In range","Missed bottom")) -> Beat top | P18: =IF(L18>G18,1,0) -> 1 | Q18: =IF(AND(L18>=F18,L18<=G18),1,0) -> 0 | R18: =IF(L18<F18,1,0) -> 0 | S18: 0 | T18: QA-1557 | U18: ER-2024Q2
A19: Q3 2024 | B19: GH-0058 | C19: ER-2024Q2 | D19: 45516 | E19: Revenue | F19: 243 | G19: 247 | H19: =(F19+G19)/2 -> 245 | I19: 251000 | J19: QA-0025 | K19: ER-2024Q3 | L19: =I19/1000 -> 251 | M19: =L19-H19 -> 6 | N19: =M19/ABS(H19) -> 0.024489796 | O19: =IF(L19>G19,"Beat top",IF(L19>=F19,"In range","Missed bottom")) -> Beat top | P19: =IF(L19>G19,1,0) -> 1 | Q19: =IF(AND(L19>=F19,L19<=G19),1,0) -> 0 | R19: =IF(L19<F19,1,0) -> 0
A20: Q4 2024 | B20: GH-0064 | C20: ER-2024Q3 | D20: 45608 | E20: Revenue | F20: 260 | G20: 262 | H20: =(F20+G20)/2 -> 261 | I20: 267976 | J20: QA-0027 | K20: ER-2024Q4 | L20: =I20/1000 -> 267.976 | M20: =L20-H20 -> 6.976 | N20: =M20/ABS(H20) -> 0.026727969 | O20: =IF(L20>G20,"Beat top",IF(L20>=F20,"In range","Missed bottom")) -> Beat top | P20: =IF(L20>G20,1,0) -> 1 | Q20: =IF(AND(L20>=F20,L20<=G20),1,0) -> 0 | R20: =IF(L20<F20,1,0) -> 0
A21: Q1 2025 | B21: GH-0069 | C21: ER-2024Q4 | D21: 45698 | E21: Revenue | F21: 274 | G21: 276 | H21: =(F21+G21)/2 -> 275 | I21: 282250 | J21: QA-0029 | K21: ER-2025Q1 | L21: =I21/1000 -> 282.25 | M21: =L21-H21 -> 7.25 | N21: =M21/ABS(H21) -> 0.026363636 | O21: =IF(L21>G21,"Beat top",IF(L21>=F21,"In range","Missed bottom")) -> Beat top | P21: =IF(L21>G21,1,0) -> 1 | Q21: =IF(AND(L21>=F21,L21<=G21),1,0) -> 0 | R21: =IF(L21<F21,1,0) -> 0
A22: Q2 2025 | B22: GH-0074 | C22: ER-2025Q1 | D22: 45789 | E22: Revenue | F22: 292 | G22: 294 | H22: =(F22+G22)/2 -> 293 | I22: 299014 | J22: QA-0030 | K22: ER-2025Q2 | L22: =I22/1000 -> 299.014 | M22: =L22-H22 -> 6.014 | N22: =M22/ABS(H22) -> 0.020525597 | O22: =IF(L22>G22,"Beat top",IF(L22>=F22,"In range","Missed bottom")) -> Beat top | P22: =IF(L22>G22,1,0) -> 1 | Q22: =IF(AND(L22>=F22,L22<=G22),1,0) -> 0 | R22: =IF(L22<F22,1,0) -> 0
A23: Q3 2025 | B23: GH-0079 | C23: ER-2025Q2 | D23: 45880 | E23: Revenue | F23: 311 | G23: 313 | H23: =(F23+G23)/2 -> 312 | I23: 316855 | J23: QA-0032 | K23: ER-2025Q3 | L23: =I23/1000 -> 316.855 | M23: =L23-H23 -> 4.855 | N23: =M23/ABS(H23) -> 0.015560897 | O23: =IF(L23>G23,"Beat top",IF(L23>=F23,"In range","Missed bottom")) -> Beat top | P23: =IF(L23>G23,1,0) -> 1 | Q23: =IF(AND(L23>=F23,L23<=G23),1,0) -> 0 | R23: =IF(L23<F23,1,0) -> 0
A24: Q4 2025 | B24: GH-0084 | C24: ER-2025Q3 | D24: 45971 | E24: Revenue | F24: 328 | G24: 330 | H24: =(F24+G24)/2 -> 329 | I24: 333878 | J24: QA-0034 | K24: ER-2025Q4 | L24: =I24/1000 -> 333.878 | M24: =L24-H24 -> 4.878 | N24: =M24/ABS(H24) -> 0.014826748 | O24: =IF(L24>G24,"Beat top",IF(L24>=F24,"In range","Missed bottom")) -> Beat top | P24: =IF(L24>G24,1,0) -> 1 | Q24: =IF(AND(L24>=F24,L24<=G24),1,0) -> 0 | R24: =IF(L24<F24,1,0) -> 0 | V24: -180 | W24: QA-1559 | X24: ER-2025Q4
A25: Q1 2026 | B25: GH-0089 | C25: ER-2025Q4 | D25: 46062 | E25: Revenue | F25: 338 | G25: 340 | H25: =(F25+G25)/2 -> 339 | I25: 351265 | J25: QA-0036 | K25: ER-2026Q1 | L25: =I25/1000 -> 351.265 | M25: =L25-H25 -> 12.265 | N25: =M25/ABS(H25) -> 0.036179941 | O25: =IF(L25>G25,"Beat top",IF(L25>=F25,"In range","Missed bottom")) -> Beat top | P25: =IF(L25>G25,1,0) -> 1 | Q25: =IF(AND(L25>=F25,L25<=G25),1,0) -> 0 | R25: =IF(L25<F25,1,0) -> 0 | V25: -190 | W25: QA-1561 | X25: ER-2026Q1
A26: Q2 2026 | B26: GH-0094 | C26: ER-2026Q1 | D26: 46153 | E26: Revenue | F26: 354 | G26: 356 | H26: =(F26+G26)/2 -> 355 | I26: 364621 | J26: QA-0037 | K26: ER-2026Q2 | L26: =I26/1000 -> 364.621 | M26: =L26-H26 -> 9.621 | N26: =M26/ABS(H26) -> 0.027101408 | O26: =IF(L26>G26,"Beat top",IF(L26>=F26,"In range","Missed bottom")) -> Beat top | P26: =IF(L26>G26,1,0) -> 1 | Q26: =IF(AND(L26>=F26,L26<=G26),1,0) -> 0 | R26: =IF(L26<F26,1,0) -> 0 | S26: 110 | T26: QA-1558 | U26: ER-2026Q2 | V26: -210 | W26: QA-1562 | X26: ER-2026Q2
A29: Non-GAAP operating income
A30: Quarter | B30: GH Row ID | C30: Source ID | D30: Guidance issued | E30: Guidance metric label | F30: Low (USD m) | G30: High (USD m) | H30: Midpoint (USD m) | I30: Actual (USD k) | J30: Actual Row ID | K30: Actual Source ID | L30: Actual (USD m) | M30: Actual - midpoint (USD m) | N30: % difference vs midpoint | O30: Outcome | P30: Beat top (1/0) | Q30: In range (1/0) | R30: Missed bottom (1/0) | S30: Disclosed FX impact on revenue growth (bps) | T30: FX Row ID | U30: FX Source ID | V30: Disclosed FX impact on non-GAAP op. margin (bps) | W30: FX Row ID | X30: FX Source ID | Y30: FX assumption stated in the guidance (copied text) and notes
A31: Text / label | B31: Source-book Row ID | C31: Source ID | D31: Sourced (copied) | E31: Sourced (copied) | F31: Sourced (copied from source book) | G31: Sourced (copied from source book) | H31: Derived (formula) | I31: Sourced (copied from source book) | J31: Source-book Row ID | K31: Source ID | L31: Derived (formula) | M31: Derived (formula) | N31: Derived (formula) | O31: Derived (formula) | P31: Derived (formula) | Q31: Derived (formula) | R31: Derived (formula) | S31: Sourced (copied from source book) | T31: Source-book Row ID | U31: Source ID | V31: Sourced (copied from source book) | W31: Source-book Row ID | X31: Source ID | Y31: Sourced text / note
A32: Q3 2021 | B32: GH-0003 | C32: ER-2021Q2 | D32: 44425 | E32: Non-GAAP operating income (loss) | F32: -26 | G32: -25 | H32: =(F32+G32)/2 -> -25.5 | I32: -9449 | J32: QA-0668 | K32: ER-2021Q3 | L32: =I32/1000 -> -9.449 | M32: =L32-H32 -> 16.051 | N32: =M32/ABS(H32) -> 0.62945098 | O32: =IF(L32>G32,"Beat top",IF(L32>=F32,"In range","Missed bottom")) -> Beat top | P32: =IF(L32>G32,1,0) -> 1 | Q32: =IF(AND(L32>=F32,L32<=G32),1,0) -> 0 | R32: =IF(L32<F32,1,0) -> 0 | Y32: Guided as an operating loss; % difference uses ABS(midpoint).
A33: Q4 2021 | B33: GH-0007 | C33: ER-2021Q3 | D33: 44510 | E33: Non-GAAP operating income (loss) | F33: -23 | G33: -22 | H33: =(F33+G33)/2 -> -22.5 | I33: -9929 | J33: QA-0670 | K33: ER-2021Q4 | L33: =I33/1000 -> -9.929 | M33: =L33-H33 -> 12.571 | N33: =M33/ABS(H33) -> 0.55871111 | O33: =IF(L33>G33,"Beat top",IF(L33>=F33,"In range","Missed bottom")) -> Beat top | P33: =IF(L33>G33,1,0) -> 1 | Q33: =IF(AND(L33>=F33,L33<=G33),1,0) -> 0 | R33: =IF(L33<F33,1,0) -> 0 | Y33: Guided as an operating loss; % difference uses ABS(midpoint).
A34: Q1 2022 | B34: GH-0011 | C34: ER-2021Q4 | D34: 44615 | E34: Non-GAAP operating income (loss) | F34: -47 | G34: -45 | H34: =(F34+G34)/2 -> -46 | I34: -43830 | J34: QA-0672 | K34: ER-2022Q1 | L34: =I34/1000 -> -43.83 | M34: =L34-H34 -> 2.17 | N34: =M34/ABS(H34) -> 0.047173913 | O34: =IF(L34>G34,"Beat top",IF(L34>=F34,"In range","Missed bottom")) -> Beat top | P34: =IF(L34>G34,1,0) -> 1 | Q34: =IF(AND(L34>=F34,L34<=G34),1,0) -> 0 | R34: =IF(L34<F34,1,0) -> 0 | S34: -100 | T34: QA-1546 | U34: ER-2022Q3 | Y34: Guided as an operating loss; % difference uses ABS(midpoint).
A35: Q2 2022 | B35: GH-0015 | C35: ER-2022Q1 | D35: 44697 | E35: Non-GAAP operating income (loss) | F35: -35 | G35: -33 | H35: =(F35+G35)/2 -> -34 | I35: -15358 | J35: QA-0673 | K35: ER-2022Q2 | L35: =I35/1000 -> -15.358 | M35: =L35-H35 -> 18.642 | N35: =M35/ABS(H35) -> 0.54829412 | O35: =IF(L35>G35,"Beat top",IF(L35>=F35,"In range","Missed bottom")) -> Beat top | P35: =IF(L35>G35,1,0) -> 1 | Q35: =IF(AND(L35>=F35,L35<=G35),1,0) -> 0 | R35: =IF(L35<F35,1,0) -> 0 | S35: -200 | T35: QA-1547 | U35: ER-2022Q3 | Y35: Guided as an operating loss; % difference uses ABS(midpoint).
A36: Q3 2022 | B36: GH-0019 | C36: ER-2022Q2 | D36: 44781 | E36: Non-GAAP operating income (loss) | F36: -25 | G36: -24 | H36: =(F36+G36)/2 -> -24.5 | I36: -2185 | J36: QA-0675 | K36: ER-2022Q3 | L36: =I36/1000 -> -2.185 | M36: =L36-H36 -> 22.315 | N36: =M36/ABS(H36) -> 0.91081633 | O36: =IF(L36>G36,"Beat top",IF(L36>=F36,"In range","Missed bottom")) -> Beat top | P36: =IF(L36>G36,1,0) -> 1 | Q36: =IF(AND(L36>=F36,L36<=G36),1,0) -> 0 | R36: =IF(L36<F36,1,0) -> 0 | S36: -300 | T36: QA-1548 | U36: ER-2022Q3 | Y36: Guided as an operating loss; % difference uses ABS(midpoint).
A37: Q4 2022 | B37: GH-0023 | C37: ER-2022Q3 | D37: 44879 | E37: Non-GAAP operating income (loss) | F37: -22 | G37: -20 | H37: =(F37+G37)/2 -> -21 | I37: 14278 | J37: QA-0677 | K37: ER-2022Q4 | L37: =I37/1000 -> 14.278 | M37: =L37-H37 -> 35.278 | N37: =M37/ABS(H37) -> 1.6799048 | O37: =IF(L37>G37,"Beat top",IF(L37>=F37,"In range","Missed bottom")) -> Beat top | P37: =IF(L37>G37,1,0) -> 1 | Q37: =IF(AND(L37>=F37,L37<=G37),1,0) -> 0 | R37: =IF(L37<F37,1,0) -> 0 | S37: -300 | T37: QA-1549 | U37: ER-2022Q4 | Y37: Guided as an operating loss; % difference uses ABS(midpoint).
A38: Q1 2023 | B38: GH-0027 | C38: ER-2022Q4 | D38: 44970 | E38: Non-GAAP operating income (loss) | F38: -19 | G38: -17 | H38: =(F38+G38)/2 -> -18 | I38: -293 | J38: QA-0679 | K38: ER-2023Q1 | L38: =I38/1000 -> -0.293 | M38: =L38-H38 -> 17.707 | N38: =M38/ABS(H38) -> 0.98372222 | O38: =IF(L38>G38,"Beat top",IF(L38>=F38,"In range","Missed bottom")) -> Beat top | P38: =IF(L38>G38,1,0) -> 1 | Q38: =IF(AND(L38>=F38,L38<=G38),1,0) -> 0 | R38: =IF(L38<F38,1,0) -> 0 | S38: -100 | T38: QA-1551 | U38: ER-2023Q1 | Y38: Guided as an operating loss; % difference uses ABS(midpoint).
A39: Q2 2023 | B39: GH-0031 | C39: ER-2023Q1 | D39: 45061 | E39: Non-GAAP operating income (loss) | F39: 2 | G39: 4 | H39: =(F39+G39)/2 -> 3 | I39: 16617 | J39: QA-0680 | K39: ER-2023Q2 | L39: =I39/1000 -> 16.617 | M39: =L39-H39 -> 13.617 | N39: =M39/ABS(H39) -> 4.539 | O39: =IF(L39>G39,"Beat top",IF(L39>=F39,"In range","Missed bottom")) -> Beat top | P39: =IF(L39>G39,1,0) -> 1 | Q39: =IF(AND(L39>=F39,L39<=G39),1,0) -> 0 | R39: =IF(L39<F39,1,0) -> 0 | S39: -100 | T39: QA-1552 | U39: ER-2023Q2
A40: Q3 2023 | B40: GH-0035 | C40: ER-2023Q2 | D40: 45152 | E40: Non-GAAP operating income (loss) | F40: 4 | G40: 6 | H40: =(F40+G40)/2 -> 5 | I40: 24077 | J40: QA-0682 | K40: ER-2023Q3 | L40: =I40/1000 -> 24.077 | M40: =L40-H40 -> 19.077 | N40: =M40/ABS(H40) -> 3.8154 | O40: =IF(L40>G40,"Beat top",IF(L40>=F40,"In range","Missed bottom")) -> Beat top | P40: =IF(L40>G40,1,0) -> 1 | Q40: =IF(AND(L40>=F40,L40<=G40),1,0) -> 0 | R40: =IF(L40<F40,1,0) -> 0 | S40: 0 | T40: QA-1553 | U40: ER-2023Q3
A41: Q4 2023 | B41: GH-0039 | C41: ER-2023Q3 | D41: 45243 | E41: Non-GAAP operating income (loss) | F41: 7 | G41: 9 | H41: =(F41+G41)/2 -> 8 | I41: 21200 | J41: QA-0684 | K41: ER-2023Q4 | L41: =I41/1000 -> 21.2 | M41: =L41-H41 -> 13.2 | N41: =M41/ABS(H41) -> 1.65 | O41: =IF(L41>G41,"Beat top",IF(L41>=F41,"In range","Missed bottom")) -> Beat top | P41: =IF(L41>G41,1,0) -> 1 | Q41: =IF(AND(L41>=F41,L41<=G41),1,0) -> 0 | R41: =IF(L41<F41,1,0) -> 0 | S41: 0 | T41: QA-1554 | U41: ER-2023Q4
A42: Q1 2024 | B42: GH-0045 | C42: ER-2023Q4 | D42: 45334 | E42: Non-GAAP operating income (loss) | F42: 8 | G42: 12 | H42: =(F42+G42)/2 -> 10 | I42: 21521 | J42: QA-0686 | K42: ER-2024Q1 | L42: =I42/1000 -> 21.521 | M42: =L42-H42 -> 11.521 | N42: =M42/ABS(H42) -> 1.1521 | O42: =IF(L42>G42,"Beat top",IF(L42>=F42,"In range","Missed bottom")) -> Beat top | P42: =IF(L42>G42,1,0) -> 1 | Q42: =IF(AND(L42>=F42,L42<=G42),1,0) -> 0 | R42: =IF(L42<F42,1,0) -> 0 | S42: 0 | T42: QA-1556 | U42: ER-2024Q1
A43: Q2 2024 | B43: GH-0051 | C43: ER-2024Q1 | D43: 45427 | E43: Non-GAAP operating income (loss) | F43: 17 | G43: 21 | H43: =(F43+G43)/2 -> 19 | I43: 38417 | J43: QA-0687 | K43: ER-2024Q2 | L43: =I43/1000 -> 38.417 | M43: =L43-H43 -> 19.417 | N43: =M43/ABS(H43) -> 1.0219474 | O43: =IF(L43>G43,"Beat top",IF(L43>=F43,"In range","Missed bottom")) -> Beat top | P43: =IF(L43>G43,1,0) -> 1 | Q43: =IF(AND(L43>=F43,L43<=G43),1,0) -> 0 | R43: =IF(L43<F43,1,0) -> 0 | S43: 0 | T43: QA-1557 | U43: ER-2024Q2
...

Sheet Growth_Decomposition
A1: Revenue growth alongside disclosed KPIs (descriptive only)
A2: This table places revenue growth next to the KPIs the company discloses. It does not claim that any KPI drives revenue. Blank = not disclosed in the source book for that period.
A4: Quarter | B4: Revenue (USD k) | C4: Row ID | D4: Source ID | E4: Revenue YoY growth | F4: Revenue QoQ growth | G4: NDR - all customers | H4: Row ID | I4: Source ID | J4: NDR - >10 users | K4: Row ID | L4: Source ID | M4: NDR - >$50k ARR | N4: Row ID | O4: Source ID | P4: NDR - >$100k ARR | Q4: Row ID | R4: Source ID | S4: Customers >10 users | T4: Row ID | U4: Source ID | V4: Customers >10 users YoY growth | W4: Customers >$50k ARR | X4: Row ID | Y4: Source ID | Z4: Customers >$50k ARR YoY growth | AA4: Customers >$100k ARR | AB4: Row ID | AC4: Source ID | AD4: Customers >$100k ARR YoY growth | AE4: Customers >$500k ARR | AF4: Row ID | AG4: Source ID | AH4: Customers >$500k ARR YoY growth | AI4: ARR share >10 users | AJ4: Row ID | AK4: Source ID | AL4: ARR share >$50k | AM4: Row ID | AN4: Source ID | AO4: ARR share >$100k | AP4: Row ID | AQ4: Source ID | AR4: ARR share >$500k | AS4: Row ID | AT4: Source ID | AU4: Flags (floors, definition and comparability notes)
A5: Text / label | B5: Sourced (copied from source book) | C5: Source-book Row ID | D5: Source ID | E5: Derived (formula) | F5: Derived (formula) | G5: Sourced (copied from source book) (floor where marked) | H5: Source-book Row ID | I5: Source ID | J5: Sourced (copied from source book) (floor where marked) | K5: Source-book Row ID | L5: Source ID | M5: Sourced (copied from source book) (floor where marked) | N5: Source-book Row ID | O5: Source ID | P5: Sourced (copied from source book) (floor where marked) | Q5: Source-book Row ID | R5: Source ID | S5: Sourced (copied from source book) (floor where marked) | T5: Source-book Row ID | U5: Source ID | V5: Derived (formula) | W5: Sourced (copied from source book) (floor where marked) | X5: Source-book Row ID | Y5: Source ID | Z5: Derived (formula) | AA5: Sourced (copied from source book) (floor where marked) | AB5: Source-book Row ID | AC5: Source ID | AD5: Derived (formula) | AE5: Sourced (copied from source book) (floor where marked) | AF5: Source-book Row ID | AG5: Source ID | AH5: Derived (formula) | AI5: Sourced (copied from source book) (floor where marked) | AJ5: Source-book Row ID | AK5: Source ID | AL5: Sourced (copied from source book) (floor where marked) | AM5: Source-book Row ID | AN5: Source ID | AO5: Sourced (copied from source book) (floor where marked) | AP5: Source-book Row ID | AQ5: Source ID | AR5: Sourced (copied from source book) (floor where marked) | AS5: Source-book Row ID | AT5: Source ID | AU5: Text / label
A6: Q1 2021 | B6: 58972 | C6: QA-0001 | D6: ER-2022Q1 | W6: 335 | X6: QA-1405 | Y6: ER-2022Q1 | AL6: 0.12 | AM6: QA-1492 | AN6: ER-2022Q1 | AU6: YoY revenue growth blank: 2020 quarters are not in the source book (history starts Q1 2021). Customer counts and ARR shares are point-in-time; ARR thresholds are nominal USD.
A7: Q2 2021 | B7: 70615 | C7: QA-0002 | D7: ER-2021Q2 | F7: =IF(OR(B7="",B6=""),"",B7/B6-1) -> 0.19743268 | J7: 1.25 | K7: QA-1353 (floor) | L7: ER-2021Q2 | W7: 470 | X7: QA-1406 | Y7: ER-2021Q2 | AU7: YoY revenue growth blank: 2020 quarters are not in the source book (history starts Q1 2021). NDR - >10 users: floor only (over 125%). >10 users NDR is the only NDR cohort disclosed (cohorts added: all customers Q4 2021, >$50k Q1 2022, >$100k Q4 2023). Customer counts and ARR shares are point-in-time; ARR thresholds are nominal USD.
A8: Q3 2021 | B8: 83018 | C8: QA-0004 | D8: ER-2021Q3 | F8: =IF(OR(B8="",B7=""),"",B8/B7-1) -> 0.17564257 | J8: 1.3 | K8: QA-1354 (floor) | L8: ER-2021Q3 | W8: 613 | X8: QA-1407 | Y8: ER-2021Q3 | AU8: YoY revenue growth blank: 2020 quarters are not in the source book (history starts Q1 2021). NDR - >10 users: floor only (over 130%). Customer counts and ARR shares are point-in-time; ARR thresholds are nominal USD.
A9: Q4 2021 | B9: 95545 | C9: QA-0006 | D9: ER-2021Q4 | F9: =IF(OR(B9="",B8=""),"",B9/B8-1) -> 0.15089499 | G9: 1.2 | H9: QA-1302 (floor) | I9: ER-2021Q4 | J9: 1.35 | K9: QA-1355 (floor) | L9: ER-2021Q4 | W9: 793 | X9: QA-1408 | Y9: ER-2021Q4 | AI9: 0.72 | AJ9: QA-1510 | AK9: ER-2021Q4 | AU9: YoY revenue growth blank: 2020 quarters are not in the source book (history starts Q1 2021). NDR - all customers: floor only (over 120%). NDR - >10 users: floor only (over 135%). Customer counts and ARR shares are point-in-time; ARR thresholds are nominal USD.
A10: Q1 2022 | B10: 108497 | C10: QA-0008 | D10: ER-2022Q1 | E10: =IF(OR(B10="",B6=""),"",B10/B6-1) -> 0.83980533 | F10: =IF(OR(B10="",B9=""),"",B10/B9-1) -> 0.13555916 | G10: 1.25 | H10: QA-1303 (floor) | I10: ER-2022Q1 | J10: 1.35 | K10: QA-1356 (floor) | L10: ER-2022Q1 | M10: 1.5 | N10: QA-1334 (floor) | O10: ER-2022Q1 | V10: =IF(OR(S10="",S6=""),"",S10/S6-1) | W10: 960 | X10: QA-1409 | Y10: ER-2022Q1 | Z10: =IF(OR(W10="",W6=""),"",W10/W6-1) -> 1.8656716 | AD10: =IF(OR(AA10="",AA6=""),"",AA10/AA6-1) | AH10: =IF(OR(AE10="",AE6=""),"",AE10/AE6-1) | AL10: 0.22 | AM10: QA-1493 | AN10: ER-2022Q1 | AU10: NDR - all customers: floor only (over 125%). NDR - >10 users: floor only (over 135%). NDR - >$50k ARR: floor only (over 150%). Customer counts and ARR shares are point-in-time; ARR thresholds are nominal USD.
A11: Q2 2022 | B11: 123718 | C11: QA-0009 | D11: ER-2022Q2 | E11: =IF(OR(B11="",B7=""),"",B11/B7-1) -> 0.75200736 | F11: =IF(OR(B11="",B10=""),"",B11/B10-1) -> 0.14028959 | G11: 1.25 | H11: QA-1304 (floor) | I11: ER-2022Q2 | J11: 1.35 | K11: QA-1357 (floor) | L11: ER-2022Q2 | M11: 1.5 | N11: QA-1335 (floor) | O11: ER-2022Q2 | V11: =IF(OR(S11="",S7=""),"",S11/S7-1) | W11: 1160 | X11: QA-1410 | Y11: ER-2022Q2 | Z11: =IF(OR(W11="",W7=""),"",W11/W7-1) -> 1.4680851 | AD11: =IF(OR(AA11="",AA7=""),"",AA11/AA7-1) | AH11: =IF(OR(AE11="",AE7=""),"",AE11/AE7-1) | AU11: NDR - all customers: floor only (over 125%). NDR - >10 users: floor only (over 135%). NDR - >$50k ARR: floor only (over 150%). Customer counts and ARR shares are point-in-time; ARR thresholds are nominal USD.
A12: Q3 2022 | B12: 136893 | C12: QA-0011 | D12: ER-2022Q3 | E12: =IF(OR(B12="",B8=""),"",B12/B8-1) -> 0.64895565 | F12: =IF(OR(B12="",B11=""),"",B12/B11-1) -> 0.10649218 | G12: 1.2 | H12: QA-1305 (floor) | I12: ER-2022Q3 | J12: 1.35 | K12: QA-1358 (floor) | L12: ER-2022Q3 | M12: 1.45 | N12: QA-1336 (floor) | O12: ER-2022Q3 | V12: =IF(OR(S12="",S8=""),"",S12/S8-1) | W12: 1323 | X12: QA-1411 | Y12: ER-2022Q3 | Z12: =IF(OR(W12="",W8=""),"",W12/W8-1) -> 1.1582382 | AD12: =IF(OR(AA12="",AA8=""),"",AA12/AA8-1) | AH12: =IF(OR(AE12="",AE8=""),"",AE12/AE8-1) | AU12: NDR - all customers: floor only (over 120%). NDR - >10 users: floor only (over 135%). NDR - >$50k ARR: floor only (over 145%). Customer counts and ARR shares are point-in-time; ARR thresholds are nominal USD.
A13: Q4 2022 | B13: 149921 | C13: QA-0013 | D13: ER-2022Q4 | E13: =IF(OR(B13="",B9=""),"",B13/B9-1) -> 0.56911403 | F13: =IF(OR(B13="",B12=""),"",B13/B12-1) -> 0.09516922 | G13: 1.21 | H13: QA-1321 | I13: 20F-FY2024 | J13: 1.3 | K13: QA-1374 | L13: 20F-FY2024 | M13: 1.37 | N13: QA-1352 | O13: 20F-FY2024 | P13: 1.35 | Q13: QA-1333 | R13: 20F-FY2024 | V13: =IF(OR(S13="",S9=""),"",S13/S9-1) | W13: 1474 | X13: QA-1412 | Y13: ER-2022Q4 | Z13: =IF(OR(W13="",W9=""),"",W13/W9-1) -> 0.85876419 | AA13: 527 | AB13: QA-1379 | AC13: ER-2023Q4 | AD13: =IF(OR(AA13="",AA9=""),"",AA13/AA9-1) | AH13: =IF(OR(AE13="",AE9=""),"",AE13/AE9-1) | AU13: NDR - all customers: exact value from 20F-FY2024 later disclosure (release gave a floor). NDR - >10 users: exact value from 20F-FY2024 later disclosure (release gave a floor). NDR - >$50k ARR: exact value from 20F-FY2024 later disclosure (release gave a floor). NDR - >$100k ARR: exact value from 20F-FY2024 later disclosure (release gave a floor). NDR >10 users Q4 2022: release and FY2022/FY2023 20-Fs say "over 130%", FY2024 20-F says 130% (source-book discrepancy D5). Customer counts and ARR shares are point-in-time; ARR thresholds are nominal USD.
A14: Q1 2023 | B14: 162256 | C14: QA-0015 | D14: ER-2023Q1 | E14: =IF(OR(B14="",B10=""),"",B14/B10-1) -> 0.49548835 | F14: =IF(OR(B14="",B13=""),"",B14/B13-1) -> 0.082276666 | G14: 1.15 | H14: QA-1307 (floor) | I14: ER-2023Q1 | J14: 1.25 | K14: QA-1360 (floor) | L14: ER-2023Q1 | M14: 1.25 | N14: QA-1338 (floor) | O14: ER-2023Q1 | S14: 47228 | T14: QA-1460 | U14: ER-2024Q1 | V14: =IF(OR(S14="",S10=""),"",S14/S10-1) | W14: 1683 | X14: QA-1413 | Y14: ER-2023Q1 | Z14: =IF(OR(W14="",W10=""),"",W14/W10-1) -> 0.753125 | AA14: 588 | AB14: QA-1380 | AC14: ER-2024Q1 | AD14: =IF(OR(AA14="",AA10=""),"",AA14/AA10-1) | AH14: =IF(OR(AE14="",AE10=""),"",AE14/AE10-1) | AU14: NDR - all customers: floor only (over 115%). NDR - >10 users: floor only (over 125%). NDR - >$50k ARR: floor only (over 125%). Customer counts and ARR shares are point-in-time; ARR thresholds are nominal USD.
A15: Q2 2023 | B15: 175679 | C15: QA-0016 | D15: ER-2023Q2 | E15: =IF(OR(B15="",B11=""),"",B15/B11-1) -> 0.41999547 | F15: =IF(OR(B15="",B14=""),"",B15/B14-1) -> 0.082727295 | G15: 1.1 | H15: QA-1308 (floor) | I15: ER-2023Q2 | J15: 1.2 | K15: QA-1361 (floor) | L15: ER-2023Q2 | M15: 1.2 | N15: QA-1339 (floor) | O15: ER-2023Q2 | S15: 49936 | T15: QA-1461 | U15: ER-2024Q2 | V15: =IF(OR(S15="",S11=""),"",S15/S11-1) | W15: 1892 | X15: QA-1414 | Y15: ER-2023Q2 | Z15: =IF(OR(W15="",W11=""),"",W15/W11-1) -> 0.63103448 | AA15: 677 | AB15: QA-1381 | AC15: ER-2024Q2 | AD15: =IF(OR(AA15="",AA11=""),"",AA15/AA11-1) | AH15: =IF(OR(AE15="",AE11=""),"",AE15/AE11-1) | AU15: NDR - all customers: floor only (over 110%). NDR - >10 users: floor only (over 120%). NDR - >$50k ARR: floor only (over 120%). Customer counts and ARR shares are point-in-time; ARR thresholds are nominal USD.
A16: Q3 2023 | B16: 189190 | C16: QA-0018 | D16: ER-2023Q3 | E16: =IF(OR(B16="",B12=""),"",B16/B12-1) -> 0.3820283 | F16: =IF(OR(B16="",B15=""),"",B16/B15-1) -> 0.076907314 | G16: 1.1 | H16: QA-1309 (floor) | I16: ER-2023Q3 | J16: 1.15 | K16: QA-1362 (floor) | L16: ER-2023Q3 | M16: 1.15 | N16: QA-1340 (floor) | O16: ER-2023Q3 | S16: 52015 | T16: QA-1462 | U16: ER-2024Q3 | V16: =IF(OR(S16="",S12=""),"",S16/S12-1) | W16: 2077 | X16: QA-1415 | Y16: ER-2023Q3 | Z16: =IF(OR(W16="",W12=""),"",W16/W12-1) -> 0.56991686 | AA16: 749 | AB16: QA-1382 | AC16: ER-2024Q3 | AD16: =IF(OR(AA16="",AA12=""),"",AA16/AA12-1) | AH16: =IF(OR(AE16="",AE12=""),"",AE16/AE12-1) | AU16: NDR - all customers: floor only (over 110%). NDR - >10 users: floor only (over 115%). NDR - >$50k ARR: floor only (over 115%). Customer counts and ARR shares are point-in-time; ARR thresholds are nominal USD.
A17: Q4 2023 | B17: 202570 | C17: QA-0020 | D17: ER-2023Q4 | E17: =IF(OR(B17="",B13=""),"",B17/B13-1) -> 0.35117829 | F17: =IF(OR(B17="",B16=""),"",B17/B16-1) -> 0.070722554 | G17: 1.1 | H17: QA-1310 | I17: ER-2023Q4 | J17: 1.15 | K17: QA-1363 | L17: ER-2023Q4 | M17: 1.15 | N17: QA-1341 | O17: ER-2023Q4 | P17: 1.14 | Q17: QA-1322 | R17: ER-2023Q4 | S17: 53688 | T17: QA-1463 | U17: ER-2024Q4 | V17: =IF(OR(S17="",S13=""),"",S17/S13-1) | W17: 2295 | X17: QA-1416 | Y17: ER-2023Q4 | Z17: =IF(OR(W17="",W13=""),"",W17/W13-1) -> 0.55698779 | AA17: 833 | AB17: QA-1383 | AC17: ER-2023Q4 | AD17: =IF(OR(AA17="",AA13=""),"",AA17/AA13-1) -> 0.58064516 | AH17: =IF(OR(AE17="",AE13=""),"",AE17/AE13-1) | AU17: First quarter with exact (not floor) NDR values; >$100k cohort added. Customer counts and ARR shares are point-in-time; ARR thresholds are nominal USD.
A18: Q1 2024 | B18: 216913 | C18: QA-0022 | D18: ER-2024Q1 | E18: =IF(OR(B18="",B14=""),"",B18/B14-1) -> 0.33685657 | F18: =IF(OR(B18="",B17=""),"",B18/B17-1) -> 0.070805154 | G18: 1.1 | H18: QA-1311 | I18: ER-2024Q1 | J18: 1.14 | K18: QA-1364 | L18: ER-2024Q1 | M18: 1.14 | N18: QA-1342 | O18: ER-2024Q1 | P18: 1.13 | Q18: QA-1323 | R18: ER-2024Q1 | S18: 55515 | T18: QA-1464 | U18: ER-2024Q1 | V18: =IF(OR(S18="",S14=""),"",S18/S14-1) -> 0.17546794 | W18: 2491 | X18: QA-1417 | Y18: ER-2024Q1 | Z18: =IF(OR(W18="",W14=""),"",W18/W14-1) -> 0.48009507 | AA18: 911 | AB18: QA-1384 | AC18: ER-2024Q1 | AD18: =IF(OR(AA18="",AA14=""),"",AA18/AA14-1) -> 0.54931973 | AH18: =IF(OR(AE18="",AE14=""),"",AE18/AE14-1) | AU18: Company (FY2025 20-F) says pricing adjustments in 2024 and H1 2025 positively affected NDR; comparability with other periods is limited. Customer counts and ARR shares are point-in-time; ARR thresholds are nominal USD.
A19: Q2 2024 | B19: 236106 | C19: QA-0023 | D19: ER-2024Q2 | E19: =IF(OR(B19="",B15=""),"",B19/B15-1) -> 0.34396257 | F19: =IF(OR(B19="",B18=""),"",B19/B18-1) -> 0.088482479 | G19: 1.1 | H19: QA-1312 | I19: ER-2024Q2 | J19: 1.14 | K19: QA-1365 | L19: ER-2024Q2 | M19: 1.14 | N19: QA-1343 | O19: ER-2024Q2 | P19: 1.14 | Q19: QA-1324 | R19: ER-2024Q2 | S19: 57203 | T19: QA-1465 | U19: ER-2024Q2 | V19: =IF(OR(S19="",S15=""),"",S19/S15-1) -> 0.14552627 | W19: 2713 | X19: QA-1418 | Y19: ER-2024Q2 | Z19: =IF(OR(W19="",W15=""),"",W19/W15-1) -> 0.43393235 | AA19: 1009 | AB19: QA-1385 | AC19: ER-2024Q2 | AD19: =IF(OR(AA19="",AA15=""),"",AA19/AA15-1) -> 0.49039882 | AH19: =IF(OR(AE19="",AE15=""),"",AE19/AE15-1) | AU19: Company (FY2025 20-F) says pricing adjustments in 2024 and H1 2025 positively affected NDR; comparability with other periods is limited. Customer counts and ARR shares are point-in-time; ARR thresholds are nominal USD.
A20: Q3 2024 | B20: 251000 | C20: QA-0025 | D20: ER-2024Q3 | E20: =IF(OR(B20="",B16=""),"",B20/B16-1) -> 0.3267086 | F20: =IF(OR(B20="",B19=""),"",B20/B19-1) -> 0.063081836 | G20: 1.11 | H20: QA-1313 | I20: ER-2024Q3 | J20: 1.14 | K20: QA-1366 | L20: ER-2024Q3 | M20: 1.15 | N20: QA-1344 | O20: ER-2024Q3 | P20: 1.15 | Q20: QA-1325 | R20: ER-2024Q3 | S20: 58760 | T20: QA-1466 | U20: ER-2024Q3 | V20: =IF(OR(S20="",S16=""),"",S20/S16-1) -> 0.12967413 | W20: 2907 | X20: QA-1419 | Y20: ER-2024Q3 | Z20: =IF(OR(W20="",W16=""),"",W20/W16-1) -> 0.39961483 | AA20: 1080 | AB20: QA-1386 | AC20: ER-2024Q3 | AD20: =IF(OR(AA20="",AA16=""),"",AA20/AA16-1) -> 0.44192256 | AE20: 45 | AF20: QA-1448 | AG20: ER-2025Q3 | AH20: =IF(OR(AE20="",AE16=""),"",AE20/AE16-1) | AI20: 0.79 | AJ20: QA-1511 | AK20: ER-2025Q3 | AL20: 0.34 | AM20: QA-1494 | AN20: ER-2025Q3 | AO20: 0.22 | AP20: QA-1484 | AQ20: ER-2025Q3 | AR20: 0.04 | AS20: QA-1502 | AT20: ER-2025Q3 | AU20: Company (FY2025 20-F) says pricing adjustments in 2024 and H1 2025 positively affected NDR; comparability with other periods is limited. Customer counts and ARR shares are point-in-time; ARR thresholds are nominal USD.
A21: Q4 2024 | B21: 267976 | C21: QA-0027 | D21: ER-2024Q4 | E21: =IF(OR(B21="",B17=""),"",B21/B17-1) -> 0.32288098 | F21: =IF(OR(B21="",B20=""),"",B21/B20-1) -> 0.067633466 | G21: 1.12 | H21: QA-1314 | I21: ER-2024Q4 | J21: 1.15 | K21: QA-1367 | L21: ER-2024Q4 | M21: 1.15 | N21: QA-1345 | O21: ER-2024Q4 | P21: 1.16 | Q21: QA-1326 | R21: ER-2024Q4 | S21: 59214 | T21: QA-1467 | U21: ER-2024Q4 | V21: =IF(OR(S21="",S17=""),"",S21/S17-1) -> 0.10292803 | W21: 3201 | X21: QA-1420 | Y21: ER-2024Q4 | Z21: =IF(OR(W21="",W17=""),"",W21/W17-1) -> 0.39477124 | AA21: 1207 | AB21: QA-1387 | AC21: ER-2024Q4 | AD21: =IF(OR(AA21="",AA17=""),"",AA21/AA17-1) -> 0.44897959 | AE21: 50 | AF21: QA-1449 | AG21: ER-2025Q4 | AH21: =IF(OR(AE21="",AE17=""),"",AE21/AE17-1) | AI21: 0.79 | AJ21: QA-1512 | AK21: ER-2025Q4 | AL21: 0.36 | AM21: QA-1495 | AN21: ER-2025Q4 | AO21: 0.24 | AP21: QA-1485 | AQ21: ER-2025Q4 | AR21: 0.04 | AS21: QA-1503 | AT21: ER-2025Q4 | AU21: Company (FY2025 20-F) says pricing adjustments in 2024 and H1 2025 positively affected NDR; comparability with other periods is limited. Customer counts and ARR shares are point-in-time; ARR thresholds are nominal USD.
A22: Q1 2025 | B22: 282250 | C22: QA-0029 | D22: ER-2025Q1 | E22: =IF(OR(B22="",B18=""),"",B22/B18-1) -> 0.30121293 | F22: =IF(OR(B22="",B21=""),"",B22/B21-1) -> 0.053265964 | G22: 1.12 | H22: QA-1315 | I22: ER-2025Q1 | J22: 1.15 | K22: QA-1368 | L22: ER-2025Q1 | M22: 1.16 | N22: QA-1346 | O22: ER-2025Q1 | P22: 1.17 | Q22: QA-1327 | R22: ER-2025Q1 | S22: 60566 | T22: QA-1468 | U22: ER-2025Q1 | V22: =IF(OR(S22="",S18=""),"",S22/S18-1) -> 0.090984419 | W22: 3444 | X22: QA-1421 | Y22: ER-2025Q1 | Z22: =IF(OR(W22="",W18=""),"",W22/W18-1) -> 0.38257728 | AA22: 1328 | AB22: QA-1388 | AC22: ER-2025Q1 | AD22: =IF(OR(AA22="",AA18=""),"",AA22/AA18-1) -> 0.45773875 | AE22: 57 | AF22: QA-1450 | AG22: ER-2026Q1 | AH22: =IF(OR(AE22="",AE18=""),"",AE22/AE18-1) | AI22: 0.8 | AJ22: QA-1513 | AK22: ER-2026Q1 | AL22: 0.37 | AM22: QA-1496 | AN22: ER-2026Q1 | AO22: 0.24 | AP22: QA-1486 | AQ22: ER-2026Q1 | AR22: 0.05 | AS22: QA-1504 | AT22: ER-2026Q1 | AU22: Company (FY2025 20-F) says pricing adjustments in 2024 and H1 2025 positively affected NDR; comparability with other periods is limited. Customer counts and ARR shares are point-in-time; ARR thresholds are nominal USD.
A23: Q2 2025 | B23: 299014 | C23: QA-0030 | D23: ER-2025Q2 | E23: =IF(OR(B23="",B19=""),"",B23/B19-1) -> 0.26643965 | F23: =IF(OR(B23="",B22=""),"",B23/B22-1) -> 0.059394154 | G23: 1.11 | H23: QA-1316 | I23: ER-2025Q2 | J23: 1.15 | K23: QA-1369 | L23: ER-2025Q2 | M23: 1.16 | N23: QA-1347 | O23: ER-2025Q2 | P23: 1.17 | Q23: QA-1328 | R23: ER-2025Q2 | S23: 61803 | T23: QA-1469 | U23: ER-2025Q2 | V23: =IF(OR(S23="",S19=""),"",S23/S19-1) -> 0.080415363 | W23: 3702 | X23: QA-1422 | Y23: ER-2025Q2 | Z23: =IF(OR(W23="",W19=""),"",W23/W19-1) -> 0.3645411 | AA23: 1472 | AB23: QA-1389 | AC23: ER-2025Q2 | AD23: =IF(OR(AA23="",AA19=""),"",AA23/AA19-1) -> 0.45887017 | AE23: 68 | AF23: QA-1451 | AG23: ER-2026Q2 | AH23: =IF(OR(AE23="",AE19=""),"",AE23/AE19-1) | AI23: 0.8 | AJ23: QA-1514 | AK23: ER-2026Q2 | AL23: 0.38 | AM23: QA-1497 | AN23: ER-2026Q2 | AO23: 0.26 | AP23: QA-1487 | AQ23: ER-2026Q2 | AR23: 0.05 | AS23: QA-1505 | AT23: ER-2026Q2 | AU23: Company (FY2025 20-F) says pricing adjustments in 2024 and H1 2025 positively affected NDR; comparability with other periods is limited. Customer counts and ARR shares are point-in-time; ARR thresholds are nominal USD.
A24: Q3 2025 | B24: 316855 | C24: QA-0032 | D24: ER-2025Q3 | E24: =IF(OR(B24="",B20=""),"",B24/B20-1) -> 0.26237052 | F24: =IF(OR(B24="",B23=""),"",B24/B23-1) -> 0.059666103 | G24: 1.11 | H24: QA-1317 | I24: ER-2025Q3 | J24: 1.15 | K24: QA-1370 | L24: ER-2025Q3 | M24: 1.17 | N24: QA-1348 | O24: ER-2025Q3 | P24: 1.17 | Q24: QA-1329 | R24: ER-2025Q3 | S24: 63075 | T24: QA-1470 | U24: ER-2025Q3 | V24: =IF(OR(S24="",S20=""),"",S24/S20-1) -> 0.073434309 | W24: 3993 | X24: QA-1423 | Y24: ER-2025Q3 | Z24: =IF(OR(W24="",W20=""),"",W24/W20-1) -> 0.37358101 | AA24: 1603 | AB24: QA-1390 | AC24: ER-2025Q3 | AD24: =IF(OR(AA24="",AA20=""),"",AA24/AA20-1) -> 0.48425926 | AE24: 78 | AF24: QA-1452 | AG24: ER-2025Q3 | AH24: =IF(OR(AE24="",AE20=""),"",AE24/AE20-1) -> 0.73333333 | AI24: 0.81 | AJ24: QA-1515 | AK24: ER-2025Q3 | AL24: 0.4 | AM24: QA-1498 | AN24: ER-2025Q3 | AO24: 0.27 | AP24: QA-1488 | AQ24: ER-2025Q3 | AR24: 0.06 | AS24: QA-1506 | AT24: ER-2025Q3 | AU24: Company says NDR reflects expansion partly offset by the anniversary of 2024-H1 2025 pricing adjustments. >$500k cohort and ARR-share-by-threshold disclosures begin (comparatives from Q3 2024). Customer counts and ARR shares are point-in-time; ARR thresholds are nominal USD.
A25: Q4 2025 | B25: 333878 | C25: QA-0034 | D25: ER-2025Q4 | E25: =IF(OR(B25="",B21=""),"",B25/B21-1) -> 0.24592501 | F25: =IF(OR(B25="",B24=""),"",B25/B24-1) -> 0.05372489 | G25: 1.1 | H25: QA-1318 | I25: ER-2025Q4 | J25: 1.14 | K25: QA-1371 | L25: ER-2025Q4 | M25: 1.16 | N25: QA-1349 | O25: ER-2025Q4 | P25: 1.16 | Q25: QA-1330 | R25: ER-2025Q4 | S25: 63914 | T25: QA-1471 | U25: ER-2025Q4 | V25: =IF(OR(S25="",S21=""),"",S25/S21-1) -> 0.079373121 | W25: 4281 | X25: QA-1424 | Y25: ER-2025Q4 | Z25: =IF(OR(W25="",W21=""),"",W25/W21-1) -> 0.33739456 | AA25: 1756 | AB25: QA-1391 | AC25: ER-2025Q4 | AD25: =IF(OR(AA25="",AA21=""),"",AA25/AA21-1) -> 0.45484673 | AE25: 87 | AF25: QA-1453 | AG25: ER-2025Q4 | AH25: =IF(OR(AE25="",AE21=""),"",AE25/AE21-1) -> 0.74 | AI25: 0.81 | AJ25: QA-1516 | AK25: ER-2025Q4 | AL25: 0.41 | AM25: QA-1499 | AN25: ER-2025Q4 | AO25: 0.28 | AP25: QA-1489 | AQ25: ER-2025Q4 | AR25: 0.06 | AS25: QA-1507 | AT25: ER-2025Q4 | AU25: Company says NDR reflects expansion partly offset by the anniversary of 2024-H1 2025 pricing adjustments. Customer counts and ARR shares are point-in-time; ARR thresholds are nominal USD.
A26: Q1 2026 | B26: 351265 | C26: QA-0036 | D26: ER-2026Q1 | E26: =IF(OR(B26="",B22=""),"",B26/B22-1) -> 0.24451727 | F26: =IF(OR(B26="",B25=""),"",B26/B25-1) -> 0.052075908 | G26: 1.1 | H26: QA-1319 | I26: ER-2026Q1 | J26: 1.14 | K26: QA-1372 | L26: ER-2026Q1 | M26: 1.16 | N26: QA-1350 | O26: ER-2026Q1 | P26: 1.15 | Q26: QA-1331 | R26: ER-2026Q1 | S26: 65016 | T26: QA-1472 | U26: ER-2026Q1 | V26: =IF(OR(S26="",S22=""),"",S26/S22-1) -> 0.073473566 | W26: 4547 | X26: QA-1425 | Y26: ER-2026Q1 | Z26: =IF(OR(W26="",W22=""),"",W26/W22-1) -> 0.32026713 | AA26: 1844 | AB26: QA-1392 | AC26: ER-2026Q1 | AD26: =IF(OR(AA26="",AA22=""),"",AA26/AA22-1) -> 0.38855422 | AE26: 99 | AF26: QA-1454 | AG26: ER-2026Q1 | AH26: =IF(OR(AE26="",AE22=""),"",AE26/AE22-1) -> 0.73684211 | AI26: 0.82 | AJ26: QA-1517 | AK26: ER-2026Q1 | AL26: 0.42 | AM26: QA-1500 | AN26: ER-2026Q1 | AO26: 0.29 | AP26: QA-1490 | AQ26: ER-2026Q1 | AR26: 0.06 | AS26: QA-1508 | AT26: ER-2026Q1 | AU26: Company says NDR reflects expansion partly offset by the anniversary of 2024-H1 2025 pricing adjustments. Q1 2026: AI Work Platform launched with seats-plus-credits pricing (source book Definitions / Not_Disclosed). Customer counts and ARR shares are point-in-time; ARR thresholds are nominal USD.
A27: Q2 2026 | B27: 364621 | C27: QA-0037 | D27: ER-2026Q2 | E27: =IF(OR(B27="",B23=""),"",B27/B23-1) -> 0.21941113 | F27: =IF(OR(B27="",B26=""),"",B27/B26-1) -> 0.038022576 | G27: 1.09 | H27: QA-1320 | I27: ER-2026Q2 | J27: 1.13 | K27: QA-1373 | L27: ER-2026Q2 | M27: 1.15 | N27: QA-1351 | O27: ER-2026Q2 | P27: 1.15 | Q27: QA-1332 | R27: ER-2026Q2 | S27: 65783 | T27: QA-1473 | U27: ER-2026Q2 | V27: =IF(OR(S27="",S23=""),"",S27/S23-1) -> 0.064398168 | W27: 4834 | X27: QA-1426 | Y27: ER-2026Q2 | Z27: =IF(OR(W27="",W23=""),"",W27/W23-1) -> 0.30578066 | AA27: 2019 | AB27: QA-1393 | AC27: ER-2026Q2 | AD27: =IF(OR(AA27="",AA23=""),"",AA27/AA23-1) -> 0.37160326 | AE27: 114 | AF27: QA-1455 | AG27: ER-2026Q2 | AH27: =IF(OR(AE27="",AE23=""),"",AE27/AE23-1) -> 0.67647059 | AI27: 0.82 | AJ27: QA-1518 | AK27: ER-2026Q2 | AL27: 0.43 | AM27: QA-1501 | AN27: ER-2026Q2 | AO27: 0.3 | AP27: QA-1491 | AQ27: ER-2026Q2 | AR27: 0.07 | AS27: QA-1509 | AT27: ER-2026Q2 | AU27: Company says NDR reflects expansion partly offset by the anniversary of 2024-H1 2025 pricing adjustments. Q1 2026: AI Work Platform launched with seats-plus-credits pricing (source book Definitions / Not_Disclosed). Customer counts and ARR shares are point-in-time; ARR thresholds are nominal USD.
A30: Chart data (Derived links to the table above; for plotting only)
A31: Quarter | B31: Revenue YoY growth | C31: NDR all (value or floor) | D31: NDR >$100k | E31: Customers >$100k YoY growth | F31: ARR share >$100k
A32: Text / label | B32: Derived (formula) | C32: Derived (formula) | D32: Derived (formula) | E32: Derived (formula) | F32: Derived (formula)
A33: =A6 -> Q1 2021 | B33: =IF(E6="","",E6) | C33: =IF(G6="","",G6) | D33: =IF(P6="","",P6) | E33: =IF(AD6="","",AD6) | F33: =IF(AO6="","",AO6)
A34: =A7 -> Q2 2021 | B34: =IF(E7="","",E7) | C34: =IF(G7="","",G7) | D34: =IF(P7="","",P7) | E34: =IF(AD7="","",AD7) | F34: =IF(AO7="","",AO7)
A35: =A8 -> Q3 2021 | B35: =IF(E8="","",E8) | C35: =IF(G8="","",G8) | D35: =IF(P8="","",P8) | E35: =IF(AD8="","",AD8) | F35: =IF(AO8="","",AO8)
A36: =A9 -> Q4 2021 | B36: =IF(E9="","",E9) | C36: =IF(G9="","",G9) -> 1.2 | D36: =IF(P9="","",P9) | E36: =IF(AD9="","",AD9) | F36: =IF(AO9="","",AO9)
A37: =A10 -> Q1 2022 | B37: =IF(E10="","",E10) -> 0.83980533 | C37: =IF(G10="","",G10) -> 1.25 | D37: =IF(P10="","",P10) | E37: =IF(AD10="","",AD10) | F37: =IF(AO10="","",AO10)
A38: =A11 -> Q2 2022 | B38: =IF(E11="","",E11) -> 0.75200736 | C38: =IF(G11="","",G11) -> 1.25 | D38: =IF(P11="","",P11) | E38: =IF(AD11="","",AD11) | F38: =IF(AO11="","",AO11)
A39: =A12 -> Q3 2022 | B39: =IF(E12="","",E12) -> 0.64895565 | C39: =IF(G12="","",G12) -> 1.2 | D39: =IF(P12="","",P12) | E39: =IF(AD12="","",AD12) | F39: =IF(AO12="","",AO12)
A40: =A13 -> Q4 2022 | B40: =IF(E13="","",E13) -> 0.56911403 | C40: =IF(G13="","",G13) -> 1.21 | D40: =IF(P13="","",P13) -> 1.35 | E40: =IF(AD13="","",AD13) | F40: =IF(AO13="","",AO13)
A41: =A14 -> Q1 2023 | B41: =IF(E14="","",E14) -> 0.49548835 | C41: =IF(G14="","",G14) -> 1.15 | D41: =IF(P14="","",P14) | E41: =IF(AD14="","",AD14) | F41: =IF(AO14="","",AO14)
A42: =A15 -> Q2 2023 | B42: =IF(E15="","",E15) -> 0.41999547 | C42: =IF(G15="","",G15) -> 1.1 | D42: =IF(P15="","",P15) | E42: =IF(AD15="","",AD15) | F42: =IF(AO15="","",AO15)
A43: =A16 -> Q3 2023 | B43: =IF(E16="","",E16) -> 0.3820283 | C43: =IF(G16="","",G16) -> 1.1 | D43: =IF(P16="","",P16) | E43: =IF(AD16="","",AD16) | F43: =IF(AO16="","",AO16)
...

Sheet Margin_Structure
A1: Margin structure: gross margin and operating expense ratios (GAAP and non-GAAP)
A2: Inputs USD thousands from Quarterly_Actuals (3-month and fiscal-year rows). Ratios are Derived (line / revenue). No adjustment is made for the 2025 commission model change.
A4: Period | B4: Basis | C4: Fiscal year | D4: Fiscal quarter | E4: Revenue (USD k) | F4: Row ID | G4: Source ID | H4: Gross profit (GAAP) (USD k) | I4: Row ID | J4: Source ID | K4: Gross profit (non-GAAP) (USD k) | L4: Row ID | M4: Source ID | N4: R&D (GAAP) (USD k) | O4: Row ID | P4: Source ID | Q4: R&D (non-GAAP) (USD k) | R4: Row ID | S4: Source ID | T4: S&M (GAAP) (USD k) | U4: Row ID | V4: Source ID | W4: S&M (non-GAAP) (USD k) | X4: Row ID | Y4: Source ID | Z4: G&A (GAAP) (USD k) | AA4: Row ID | AB4: Source ID | AC4: G&A (non-GAAP) (USD k) | AD4: Row ID | AE4: Source ID | AF4: Operating income (GAAP) (USD k) | AG4: Row ID | AH4: Source ID | AI4: Operating income (non-GAAP) (USD k) | AJ4: Row ID | AK4: Source ID | AL4: Gross margin (GAAP) | AM4: Gross margin (non-GAAP) | AN4: R&D % rev (GAAP) | AO4: R&D % rev (non-GAAP) | AP4: S&M % rev (GAAP) | AQ4: S&M % rev (non-GAAP) | AR4: G&A % rev (GAAP) | AS4: G&A % rev (non-GAAP) | AT4: Operating margin (GAAP) | AU4: Operating margin (non-GAAP) | AV4: Gross margin (non-GAAP): quarter minus same-year FY ratio | AW4: R&D % rev (non-GAAP): quarter minus same-year FY ratio | AX4: S&M % rev (non-GAAP): quarter minus same-year FY ratio | AY4: G&A % rev (non-GAAP): quarter minus same-year FY ratio | AZ4: Operating margin (non-GAAP): quarter minus same-year FY ratio
A5: Text / label | B5: Text / label | C5: Text / label | D5: Text / label | E5: Sourced (copied from source book) | F5: Source-book Row ID | G5: Source ID | H5: Sourced (copied from source book) | I5: Source-book Row ID | J5: Source ID | K5: Sourced (copied from source book) | L5: Source-book Row ID | M5: Source ID | N5: Sourced (copied from source book) | O5: Source-book Row ID | P5: Source ID | Q5: Sourced (copied from source book) | R5: Source-book Row ID | S5: Source ID | T5: Sourced (copied from source book) | U5: Source-book Row ID | V5: Source ID | W5: Sourced (copied from source book) | X5: Source-book Row ID | Y5: Source ID | Z5: Sourced (copied from source book) | AA5: Source-book Row ID | AB5: Source ID | AC5: Sourced (copied from source book) | AD5: Source-book Row ID | AE5: Source ID | AF5: Sourced (copied from source book) | AG5: Source-book Row ID | AH5: Source ID | AI5: Sourced (copied from source book) | AJ5: Source-book Row ID | AK5: Source ID | AL5: Derived (formula) | AM5: Derived (formula) | AN5: Derived (formula) | AO5: Derived (formula) | AP5: Derived (formula) | AQ5: Derived (formula) | AR5: Derived (formula) | AS5: Derived (formula) | AT5: Derived (formula) | AU5: Derived (formula) | AV5: Derived (formula) | AW5: Derived (formula) | AX5: Derived (formula) | AY5: Derived (formula) | AZ5: Derived (formula)
A6: Q1 2021 | B6: Quarter | C6: 2021 | D6: 1 | E6: 58972 | F6: QA-0001 | G6: ER-2022Q1 | H6: 51048 | I6: QA-0077 | J6: ER-2022Q1 | K6: 52579 | L6: QA-0475 | M6: ER-2022Q1 | N6: 15581 | O6: QA-0153 | P6: ER-2022Q1 | Q6: 11044 | R6: QA-0551 | S6: ER-2022Q1 | T6: 63048 | U6: QA-0191 | V6: ER-2022Q1 | W6: 59014 | X6: QA-0589 | Y6: ER-2022Q1 | Z6: 10266 | AA6: QA-0229 | AB6: ER-2022Q1 | AC6: 5828 | AD6: QA-0627 | AE6: ER-2022Q1 | AF6: -37847 | AG6: QA-0307 | AH6: ER-2022Q1 | AI6: -23307 | AJ6: QA-0665 | AK6: ER-2022Q1 | AL6: =H6/E6 -> 0.86563115 | AM6: =K6/E6 -> 0.89159262 | AN6: =N6/E6 -> 0.26421013 | AO6: =Q6/E6 -> 0.18727532 | AP6: =T6/E6 -> 1.0691175 | AQ6: =W6/E6 -> 1.0007122 | AR6: =Z6/E6 -> 0.17408262 | AS6: =AC6/E6 -> 0.098826562 | AT6: =AF6/E6 -> -0.64177915 | AU6: =AI6/E6 -> -0.39522146 | AV6: =AM6-AM28 -> -0.0067296254 | AW6: =AO6-AO28 -> 0.018828132 | AX6: =AQ6-AQ28 -> 0.20581361 | AY6: =AS6-AS28 -> -0.0068330196 | AZ6: =AU6-AU28 -> -0.22453835
A7: Q2 2021 | B7: Quarter | C7: 2021 | D7: 2 | E7: 70615 | F7: QA-0002 | G7: ER-2021Q2 | H7: 61507 | I7: QA-0078 | J7: ER-2021Q2 | K7: 63340 | L7: QA-0476 | M7: ER-2021Q2 | N7: 16271 | O7: QA-0154 | P7: ER-2021Q2 | Q7: 11203 | R7: QA-0552 | S7: ER-2021Q2 | T7: 61057 | U7: QA-0192 | V7: ER-2021Q2 | W7: 55521 | X7: QA-0590 | Y7: ER-2021Q2 | Z7: 11648 | AA7: QA-0230 | AB7: ER-2021Q2 | AC7: 6527 | AD7: QA-0628 | AE7: ER-2021Q2 | AF7: -27469 | AG7: QA-0308 | AH7: ER-2021Q2 | AI7: -9911 | AJ7: QA-0666 | AK7: ER-2021Q2 | AL7: =H7/E7 -> 0.87101891 | AM7: =K7/E7 -> 0.89697656 | AN7: =N7/E7 -> 0.23041847 | AO7: =Q7/E7 -> 0.15864901 | AP7: =T7/E7 -> 0.86464632 | AQ7: =W7/E7 -> 0.78624938 | AR7: =Z7/E7 -> 0.16495079 | AS7: =AC7/E7 -> 0.092430787 | AT7: =AF7/E7 -> -0.38899667 | AU7: =AI7/E7 -> -0.14035262 | AV7: =AM7-AM28 -> -0.0013456826 | AW7: =AO7-AO28 -> -0.0097981726 | AX7: =AQ7-AQ28 -> -0.0086492079 | AY7: =AS7-AS28 -> -0.013228795 | AZ7: =AU7-AU28 -> 0.030330493
A8: Q3 2021 | B8: Quarter | C8: 2021 | D8: 3 | E8: 83018 | F8: QA-0004 | G8: ER-2021Q3 | H8: 72805 | I8: QA-0080 | J8: ER-2021Q3 | K8: 74912 | L8: QA-0478 | M8: ER-2021Q3 | N8: 19875 | O8: QA-0156 | P8: ER-2021Q3 | Q8: 14255 | R8: QA-0554 | S8: ER-2021Q3 | T8: 67443 | U8: QA-0194 | V8: ER-2021Q3 | W8: 60995 | X8: QA-0592 | Y8: ER-2021Q3 | Z8: 14698 | AA8: QA-0232 | AB8: ER-2021Q3 | AC8: 9111 | AD8: QA-0630 | AE8: ER-2021Q3 | AF8: -29211 | AG8: QA-0310 | AH8: ER-2021Q3 | AI8: -9449 | AJ8: QA-0668 | AK8: ER-2021Q3 | AL8: =H8/E8 -> 0.87697849 | AM8: =K8/E8 -> 0.90235852 | AN8: =N8/E8 -> 0.23940591 | AO8: =Q8/E8 -> 0.17170975 | AP8: =T8/E8 -> 0.81239008 | AQ8: =W8/E8 -> 0.73472018 | AR8: =Z8/E8 -> 0.17704594 | AS8: =AC8/E8 -> 0.10974728 | AT8: =AF8/E8 -> -0.35186345 | AU8: =AI8/E8 -> -0.11381869 | AV8: =AM8-AM28 -> 0.004036279 | AW8: =AO8-AO28 -> 0.0032625649 | AX8: =AQ8-AQ28 -> -0.060178407 | AY8: =AS8-AS28 -> 0.0040877023 | AZ8: =AU8-AU28 -> 0.056864419
A9: Q4 2021 | B9: Quarter | C9: 2021 | D9: 4 | E9: 95545 | F9: QA-0006 | G9: ER-2021Q4 | H9: 83777 | I9: QA-0082 | J9: ER-2021Q4 | K9: 85987 | L9: QA-0480 | M9: ER-2021Q4 | N9: 21959 | O9: QA-0158 | P9: ER-2021Q4 | Q9: 15405 | R9: QA-0556 | S9: ER-2021Q4 | T9: 76535 | U9: QA-0196 | V9: ER-2021Q4 | W9: 69418 | X9: QA-0594 | Y9: ER-2021Q4 | Z9: 16881 | AA9: QA-0234 | AB9: ER-2021Q4 | AC9: 11093 | AD9: QA-0632 | AE9: ER-2021Q4 | AF9: -31598 | AG9: QA-0312 | AH9: ER-2021Q4 | AI9: -9929 | AJ9: QA-0670 | AK9: ER-2021Q4 | AL9: =H9/E9 -> 0.87683291 | AM9: =K9/E9 -> 0.89996337 | AN9: =N9/E9 -> 0.22982888 | AO9: =Q9/E9 -> 0.16123293 | AP9: =T9/E9 -> 0.80103616 | AQ9: =W9/E9 -> 0.7265477 | AR9: =Z9/E9 -> 0.17668115 | AS9: =AC9/E9 -> 0.11610236 | AT9: =AF9/E9 -> -0.33071328 | AU9: =AI9/E9 -> -0.10391962 | AV9: =AM9-AM28 -> 0.0016411224 | AW9: =AO9-AO28 -> -0.0072142579 | AX9: =AQ9-AQ28 -> -0.068350888 | AY9: =AS9-AS28 -> 0.010442779 | AZ9: =AU9-AU28 -> 0.06676349
A10: Q1 2022 | B10: Quarter | C10: 2022 | D10: 1 | E10: 108497 | F10: QA-0008 | G10: ER-2022Q1 | H10: 93888 | I10: QA-0084 | J10: ER-2022Q1 | K10: 96329 | L10: QA-0482 | M10: ER-2022Q1 | N10: 26541 | O10: QA-0160 | P10: ER-2022Q1 | Q10: 19153 | R10: QA-0558 | S10: ER-2022Q1 | T10: 115973 | U10: QA-0198 | V10: ER-2022Q1 | W10: 108595 | X10: QA-0596 | Y10: ER-2022Q1 | Z10: 18870 | AA10: QA-0236 | AB10: ER-2022Q1 | AC10: 12411 | AD10: QA-0634 | AE10: ER-2022Q1 | AF10: -67496 | AG10: QA-0314 | AH10: ER-2022Q1 | AI10: -43830 | AJ10: QA-0672 | AK10: ER-2022Q1 | AL10: =H10/E10 -> 0.86535112 | AM10: =K10/E10 -> 0.88784943 | AN10: =N10/E10 -> 0.24462428 | AO10: =Q10/E10 -> 0.17653023 | AP10: =T10/E10 -> 1.0689051 | AQ10: =W10/E10 -> 1.0009033 | AR10: =Z10/E10 -> 0.17392186 | AS10: =AC10/E10 -> 0.11439026 | AT10: =AF10/E10 -> -0.62210015 | AU10: =AI10/E10 -> -0.4039743 | AV10: =AM10-AM29 -> -0.0040217335 | AW10: =AO10-AO29 -> -0.0047505881 | AX10: =AQ10-AQ29 -> 0.30997654 | AY10: =AS10-AS29 -> 0.0039898774 | AZ10: =AU10-AU29 -> -0.31323756
A11: Q2 2022 | B11: Quarter | C11: 2022 | D11: 2 | E11: 123718 | F11: QA-0009 | G11: ER-2022Q2 | H11: 106988 | I11: QA-0085 | J11: ER-2022Q2 | K11: 109903 | L11: QA-0483 | M11: ER-2022Q2 | N11: 33962 | O11: QA-0161 | P11: ER-2022Q2 | Q11: 23963 | R11: QA-0559 | S11: ER-2022Q2 | T11: 96740 | U11: QA-0199 | V11: ER-2022Q2 | W11: 86665 | X11: QA-0597 | Y11: ER-2022Q2 | Z11: 22466 | AA11: QA-0237 | AB11: ER-2022Q2 | AC11: 14633 | AD11: QA-0635 | AE11: ER-2022Q2 | AF11: -46180 | AG11: QA-0315 | AH11: ER-2022Q2 | AI11: -15358 | AJ11: QA-0673 | AK11: ER-2022Q2 | AL11: =H11/E11 -> 0.86477311 | AM11: =K11/E11 -> 0.88833476 | AN11: =N11/E11 -> 0.27451139 | AO11: =Q11/E11 -> 0.19369049 | AP11: =T11/E11 -> 0.78193957 | AQ11: =W11/E11 -> 0.70050437 | AR11: =Z11/E11 -> 0.18159039 | AS11: =AC11/E11 -> 0.11827705 | AT11: =AF11/E11 -> -0.37326824 | AU11: =AI11/E11 -> -0.12413715 | AV11: =AM11-AM29 -> -0.0035364058 | AW11: =AO11-AO29 -> 0.012409675 | AX11: =AQ11-AQ29 -> 0.0095776616 | AY11: =AS11-AS29 -> 0.0078766672 | AZ11: =AU11-AU29 -> -0.03340041
A12: Q3 2022 | B12: Quarter | C12: 2022 | D12: 3 | E12: 136893 | F12: QA-0011 | G12: ER-2022Q3 | H12: 119063 | I12: QA-0087 | J12: ER-2022Q3 | K12: 121746 | L12: QA-0485 | M12: ER-2022Q3 | N12: 33984 | O12: QA-0163 | P12: ER-2022Q3 | Q12: 26259 | R12: QA-0561 | S12: ER-2022Q3 | T12: 90970 | U12: QA-0201 | V12: ER-2022Q3 | W12: 82432 | X12: QA-0599 | Y12: ER-2022Q3 | Z12: 22348 | AA12: QA-0239 | AB12: ER-2022Q3 | AC12: 15240 | AD12: QA-0637 | AE12: ER-2022Q3 | AF12: -28239 | AG12: QA-0317 | AH12: ER-2022Q3 | AI12: -2185 | AJ12: QA-0675 | AK12: ER-2022Q3 | AL12: =H12/E12 -> 0.86975229 | AM12: =K12/E12 -> 0.88935154 | AN12: =N12/E12 -> 0.24825228 | AO12: =Q12/E12 -> 0.19182135 | AP12: =T12/E12 -> 0.66453361 | AQ12: =W12/E12 -> 0.60216373 | AR12: =Z12/E12 -> 0.16325159 | AS12: =AC12/E12 -> 0.11132783 | AT12: =AF12/E12 -> -0.2062852 | AU12: =AI12/E12 -> -0.015961371 | AV12: =AM12-AM29 -> -0.0025196298 | AW12: =AO12-AO29 -> 0.010540535 | AX12: =AQ12-AQ29 -> -0.088762978 | AY12: =AS12-AS29 -> 0.00092744313 | AZ12: =AU12-AU29 -> 0.07477537
A13: Q4 2022 | B13: Quarter | C13: 2022 | D13: 4 | E13: 149921 | F13: QA-0013 | G13: ER-2022Q4 | H13: 132562 | I13: QA-0089 | J13: ER-2022Q4 | K13: 134929 | L13: QA-0487 | M13: ER-2022Q4 | N13: 32560 | O13: QA-0165 | P13: ER-2022Q4 | Q13: 24715 | R13: QA-0563 | S13: ER-2022Q4 | T13: 88385 | U13: QA-0203 | V13: ER-2022Q4 | W13: 80919 | X13: QA-0601 | Y13: ER-2022Q4 | Z13: 21717 | AA13: QA-0241 | AB13: ER-2022Q4 | AC13: 15017 | AD13: QA-0639 | AE13: ER-2022Q4 | AF13: -10100 | AG13: QA-0319 | AH13: ER-2022Q4 | AI13: 14278 | AJ13: QA-0677 | AK13: ER-2022Q4 | AL13: =H13/E13 -> 0.88421235 | AM13: =K13/E13 -> 0.90000067 | AN13: =N13/E13 -> 0.21718105 | AO13: =Q13/E13 -> 0.16485349 | AP13: =T13/E13 -> 0.58954383 | AQ13: =W13/E13 -> 0.53974427 | AR13: =Z13/E13 -> 0.14485629 | AS13: =AC13/E13 -> 0.10016609 | AT13: =AF13/E13 -> -0.067368814 | AU13: =AI13/E13 -> 0.095236825 | AV13: =AM13-AM29 -> 0.0081294999 | AW13: =AO13-AO29 -> -0.016427325 | AX13: =AQ13-AQ29 -> -0.15118245 | AY13: =AS13-AS29 -> -0.010234295 | AZ13: =AU13-AU29 -> 0.18597357
A14: Q1 2023 | B14: Quarter | C14: 2023 | D14: 1 | E14: 162256 | F14: QA-0015 | G14: ER-2023Q1 | H14: 145242 | I14: QA-0091 | J14: ER-2023Q1 | K14: 146719 | L14: QA-0489 | M14: ER-2023Q1 | N14: 37063 | O14: QA-0167 | P14: ER-2023Q1 | Q14: 28519 | R14: QA-0565 | S14: ER-2023Q1 | T14: 107680 | U14: QA-0205 | V14: ER-2023Q1 | W14: 102652 | X14: QA-0603 | Y14: ER-2023Q1 | Z14: 23251 | AA14: QA-0243 | AB14: ER-2023Q1 | AC14: 15841 | AD14: QA-0641 | AE14: ER-2023Q1 | AF14: -22752 | AG14: QA-0321 | AH14: ER-2023Q1 | AI14: -293 | AJ14: QA-0679 | AK14: ER-2023Q1 | AL14: =H14/E14 -> 0.89514101 | AM14: =K14/E14 -> 0.90424391 | AN14: =N14/E14 -> 0.22842299 | AO14: =Q14/E14 -> 0.17576546 | AP14: =T14/E14 -> 0.66364264 | AQ14: =W14/E14 -> 0.63265457 | AR14: =Z14/E14 -> 0.14329824 | AS14: =AC14/E14 -> 0.097629672 | AT14: =AF14/E14 -> -0.14022286 | AU14: =AI14/E14 -> -0.0018057884 | AV14: =AM14-AM30 -> 0.006119352 | AW14: =AO14-AO30 -> 0.01437885 | AX14: =AQ14-AQ30 -> 0.066655078 | AY14: =AS14-AS30 -> 0.011311415 | AZ14: =AU14-AU30 -> -0.086225991
A15: Q2 2023 | B15: Quarter | C15: 2023 | D15: 2 | E15: 175679 | F15: QA-0016 | G15: ER-2023Q2 | H15: 156163 | I15: QA-0092 | J15: ER-2023Q2 | K15: 158008 | L15: QA-0490 | M15: ER-2023Q2 | N15: 39106 | O15: QA-0168 | P15: ER-2023Q2 | Q15: 27908 | R15: QA-0566 | S15: ER-2023Q2 | T15: 107443 | U15: QA-0206 | V15: ER-2023Q2 | W15: 98831 | X15: QA-0604 | Y15: ER-2023Q2 | Z15: 21781 | AA15: QA-0244 | AB15: ER-2023Q2 | AC15: 14652 | AD15: QA-0642 | AE15: ER-2023Q2 | AF15: -12167 | AG15: QA-0322 | AH15: ER-2023Q2 | AI15: 16617 | AJ15: QA-0680 | AK15: ER-2023Q2 | AL15: =H15/E15 -> 0.88891103 | AM15: =K15/E15 -> 0.89941313 | AN15: =N15/E15 -> 0.22259917 | AO15: =Q15/E15 -> 0.15885792 | AP15: =T15/E15 -> 0.61158704 | AQ15: =W15/E15 -> 0.56256582 | AR15: =Z15/E15 -> 0.12398181 | AS15: =AC15/E15 -> 0.083402114 | AT15: =AF15/E15 -> -0.069256997 | AU15: =AI15/E15 -> 0.094587287 | AV15: =AM15-AM30 -> 0.0012885753 | AW15: =AO15-AO30 -> -0.0025286897 | AX15: =AQ15-AQ30 -> -0.0034336769 | AY15: =AS15-AS30 -> -0.0029161422 | AZ15: =AU15-AU30 -> 0.010167084
