Workbook

Sheet README
A1: monday.com Operating Plan & Rolling Reforecast - Phase 0 Source Book
A3: Purpose and scope
A4: Purpose | B4: Phase 0 SOURCE BOOK for a public-data Strategic FP&A operating plan and rolling reforecast of monday.com Ltd. (NASDAQ: MNDY; SEC CIK 0001845338). It preserves the information set that was publicly available in SEC-hosted primary filings before monday.com reports Q3 2026 results (scheduled November 9, 2026).
A5: Information cutoff | B5: October 28, 2026. No source published after this date is used. The latest primary document used is the Q2 2026 earnings release and H1 2026 interim report furnished on Form 6-K on August 10, 2026 (the last 6-K/20-F in the EDGAR index before the cutoff).
A6: No forecast / no plan | B6: Phase 0 contains NO forecast, NO operating plan, NO operating assumptions, NO scenario modeling, NO synthetic KPI history and NO back-solving of undisclosed KPIs. Company guidance is recorded only as disclosed history (Guidance_History). No revenue-model architecture, customer-driver methodology, phasing, headcount, expense-driver or scenario decision has been made.
A7: Primary sources | B7: Only SEC-hosted primary documents: 6-K exhibits (earnings press releases, interim financial statements and MD&A, other press releases, proxy materials) and Form 20-F annual reports with their exhibits. No data aggregator or secondary source is used. Full list on the Sources sheet.
A8: Investor relations website | B8: ir.monday.com was UNAVAILABLE: direct access returned HTTP 403 with a Cloudflare bot challenge. It was not used, no secondary source was substituted, and no attempt was made to circumvent the block. Investor presentations, the September 17, 2025 Investor Day materials (including any financial targets), webcast transcripts and IR-only KPI supplements are therefore NOT in this source book (see Sources: IR-WEB and Not_Disclosed).
A9: Classification labels
A10: Sourced | B10: Read directly from a primary filing / release / exhibit. Hard-coded and shown in BLUE font. Every Sourced value has a Source ID and an exact document / table / section reference adjacent to it.
A11: Derived | B11: Only mechanical transformations of disclosed values (e.g., unrounded margin = disclosed profit / disclosed revenue; sum of disclosed balance-sheet components; guidance midpoint = average of disclosed low and high; midpoint change). Every Derived value is a live Excel formula (BLACK font) and its row shows the formula and the Sourced input rows. Derived is never used to estimate an undisclosed KPI, total ARR, headcount, new ARR, budgets, missing customer metrics or planning assumptions.
A12: Assumed | B12: A judgment. There are NO Assumed values in Phase 0.
A13: Font conventions | B13: BLUE = hard-coded Sourced input. BLACK = formula (Derived values, checks). GREEN = link to another row (Guidance_History prior-vintage columns). RED text in Notes = conflict / restatement / discrepancy flag.
A14: Missing data, conflicts, restatements
A15: Blank cells | B15: A blank value means NOT DISCLOSED or NOT COMPARABLE for that period unless the Notes say otherwise. A blank historical value stays blank unless (1) the inputs are explicitly disclosed, (2) it is a simple mechanical calculation, (3) it is labeled Derived, and (4) the formula and sources are shown. Line items not presented in a statement (e.g., restructuring before Q2 2026) are left blank, not set to zero. A disclosed "—" (nil) in a statement is recorded as 0.
A16: Lower-bound disclosures | B16: Where a source gives only a floor (e.g., NDR "over 125%"), As Reported keeps the wording, Normalized Low holds the floor and Normalized Value is blank. Ranges keep As Reported plus Normalized Low / High.
A17: Conflicts | B17: If two primary documents disagree, both values are kept, both sources are identified, the conflict is flagged in Notes (red) and in a Checks row, and the current value is stated with the reason. Nothing is silently overwritten. See the discrepancy log below.
A18: Restatements | B18: Every prior-year comparative column in all 21 earnings releases (1,094 statement values) was compared with the originally reported value: no restated financial-statement values were found. KPI comparatives in later releases were compared with original KPI disclosures: no differences. Restatements / recasts / corrections found elsewhere are listed in the restatement log below and flagged in place.
A19: Units and period basis
A20: Units | B20: USD thousands (financial statements, reconciliations; as presented by the company); USD millions (guidance, RPO/cRPO per releases, share repurchases per release text); USD (per-share, if any); percentage (stored as a decimal fraction, displayed as %; company-reported margins are whole-percent rounded); basis points (FX impacts; 100 bps = 1 percentage point); customer count; employee count; shares.
A21: Period basis | B21: Quarterly (3 months) | Year-to-date (6 months / 9 months) | Annual (12 months, fiscal year = calendar year) | Point-in-time (balance sheet date or KPI as-of date) | Trailing-twelve-month (only where the company says so; NDR definition references a TTM weighted average but disclosures do not state which basis is reported - see Definitions) | Guidance period (next quarter or full fiscal year). Every row carries its period basis; period types are never mixed in a check.
A22: Sign conventions | B22: Values follow the company presentation: expenses positive on the income statement; operating losses negative; cash outflows negative in cash-flow and FCF reconciliation rows; opex SBC adjustments negative in the opex reconciliation (as presented). FX impacts: negative = unfavorable to the reported metric.
A23: Fiscal calendar | B23: Fiscal year ends December 31. Q1 = Jan-Mar, Q2 = Apr-Jun, Q3 = Jul-Sep, Q4 = Oct-Dec.
A24: Historical start date
A25: Start: Q1 2021 | B25: Quarterly_Actuals starts at Q1 2021. Reasons: (1) monday.com IPO'd in June 2021; the first earnings release is Q2 2021 and every quarter from Q1 2021 to Q2 2026 is available on a consistent basis (Q1 2021 from the prior-year column of the Q1 2022 release); (2) FY2021 is the first fiscal year with all four quarters disclosed and the first audited year in a 20-F, so quarter-to-year additivity can be tested from 2021; (3) 2020 quarters exist only as Q2-Q4 comparatives in IPO-year releases and Q1 2020 was never disclosed standalone, so 2020 could not be assembled as a complete quarterly year. KPIs are included from whenever each was first disclosed (see Not_Disclosed and the coverage notes); earlier periods are blank.
A26: Sheet guide
A27: Sources | B27: Every primary document used, with SEC URL, accession number, exhibit number, publication date, and the IR-site unavailability record.
A28: Quarterly_Actuals | B28: Long-format history (one row per metric x period x basis): P&L (GAAP and non-GAAP), SBC, restructuring, cash flow and adjusted FCF, balance-sheet cash items, repurchases, NDR by cohort, paid customers by threshold, share of ARR by cohort, RPO / cRPO, FX impacts. YTD and annual rows are included for flow metrics to support additivity checks.
A29: Guidance_History | B29: Every guidance vintage (Q2 2021 release through Q2 2026 release, plus the July 22, 2026 outlook update); older vintages are never overwritten.
A30: Annual | B30: 20-F (and interim-report / other 6-K) disclosures: headcount, SBC detail, leases, commitments, acquisitions, restructuring plan, repurchase program, tax, FX hedging, geographic revenue, audited statement totals, etc.
A31: Reconciliations | B31: GAAP-to-non-GAAP reconciliations (gross profit, each opex line, operating income, net income) and OCF-to-(adjusted) FCF, by quarter and fiscal year, in the company's own structure.
A32: Definitions | B32: Company definitions and scope of KPIs and non-GAAP measures, effective periods, definition / methodology changes and comparability warnings.
A33: Checks | B33: 982 formula checks with PASS/FAIL and explanations for each FAIL. Point-in-time metrics are never summed.
A34: Not_Disclosed | B34: Planning variables that would be useful but are not disclosed, with search scope and possible later treatment. Documents limitations only; no assumptions are created.
A35: Discrepancy log (primary-source conflicts and inconsistencies)
A36: D1 FY2021 adjusted FCF | B36: FY2023 20-F Item 5.A reconciliation prints FY2021 adjusted FCF 7,303 (same as the HQ add-back line); its components and four other primary sources give 9,900. Current: 9,900. (Quarterly_Actuals conflict row; Checks.)
A37: D2 FY2021 total opex | B37: FY2021 20-F Item 5.A summary table prints 395,292; audited statements, Item 5 comparison table and Q4 2021 release show 395,262. Current: 395,262. (Annual; Checks.)
A38: D3 Q4 D&A (2024, 2025) | B38: Q4 3-month D&A in the Q4 2024 and Q4 2025 releases does not equal FY minus 9M D&A (differences 16 and 58 USD thousands). No explanation. (Checks FAIL with explanation.)
A39: D4 June 30, 2025 RPO | B39: 767,789 USD thousands (H1 2025 interim FS) vs $699 million (Q2 2026 release comparative). No explanation. Current: $699M on the release basis. (Quarterly_Actuals; Checks FAIL.)
A40: D5 Q4 2022 NDR >10 users | B40: Q4 2022 release and FY2022/FY2023 20-Fs: "over 130%"; FY2024 20-F: exactly 130%. Both kept; flagged.
A41: D6 D&A in notes vs cash flow | B41: FY2023 D&A: 9,023 (cash flow) vs 8,961 (PP&E note); FY2022: 8,567 vs 5,913. Not necessarily the same scope (note covers property and equipment only); not reconciled in the filings. Cash-flow figure used for cash-flow D&A. (Annual notes.)
...

Sheet Sources
A1: Source ID | B1: Document Type | C1: Title | D1: Reporting Period | E1: Publication Date (SEC filing date) | F1: URL | G1: SEC Accession Number | H1: Exhibit Number | I1: Source Location / Section | J1: Notes
A2: ER-2021Q2 | B2: 6-K, Exhibit 99.1 (earnings press release) | C2: monday.com Announces Second Quarter 2021 Results | D2: Q2 2021 | E2: 44425 | F2: https://www.sec.gov/Archives/edgar/data/1845338/000117891321002746/exhibit_99-1.htm | G2: 0001178913-21-002746 | H2: 99.1 | I2: Whole document: highlights, outlook, KPI definitions, financial tables | J2: Earnings release furnished on Form 6-K. Prior-period comparative columns also used for Q1 2021 values, first-time KPI comparatives and restatement review.
A3: ER-2021Q3 | B3: 6-K, Exhibit 99.1 (earnings press release) | C3: monday.com Announces Third Quarter 2021 Results | D3: Q3 2021 | E3: 44510 | F3: https://www.sec.gov/Archives/edgar/data/1845338/000117891321003446/exhibit_99-1.htm | G3: 0001178913-21-003446 | H3: 99.1 | I3: Whole document: highlights, outlook, KPI definitions, financial tables | J3: Earnings release furnished on Form 6-K. Prior-period comparative columns also used for Q1 2021 values, first-time KPI comparatives and restatement review.
A4: ER-2021Q4 | B4: 6-K, Exhibit 99.1 (earnings press release) | C4: monday.com Announces Fourth Quarter and Fiscal Year 2021 Results | D4: Q4 2021 | E4: 44615 | F4: https://www.sec.gov/Archives/edgar/data/1845338/000117891322000771/exhibit_99-1.htm | G4: 0001178913-22-000771 | H4: 99.1 | I4: Whole document: highlights, outlook, KPI definitions, financial tables | J4: Earnings release furnished on Form 6-K. Prior-period comparative columns also used for Q1 2021 values, first-time KPI comparatives and restatement review.
A5: ER-2022Q1 | B5: 6-K, Exhibit 99.1 (earnings press release) | C5: monday.com Announces First Quarter 2022 Results | D5: Q1 2022 | E5: 44697 | F5: https://www.sec.gov/Archives/edgar/data/1845338/000117891322001962/exhibit_99-1.htm | G5: 0001178913-22-001962 | H5: 99.1 | I5: Whole document: highlights, outlook, KPI definitions, financial tables | J5: Earnings release furnished on Form 6-K. Prior-period comparative columns also used for Q1 2021 values, first-time KPI comparatives and restatement review.
A6: ER-2022Q2 | B6: 6-K, Exhibit 99.1 (earnings press release) | C6: monday.com Announces Second Quarter 2022 Results | D6: Q2 2022 | E6: 44781 | F6: https://www.sec.gov/Archives/edgar/data/1845338/000117891322002948/exhibit_99-1.htm | G6: 0001178913-22-002948 | H6: 99.1 | I6: Whole document: highlights, outlook, KPI definitions, financial tables | J6: Earnings release furnished on Form 6-K. Prior-period comparative columns also used for Q1 2021 values, first-time KPI comparatives and restatement review.
A7: ER-2022Q3 | B7: 6-K, Exhibit 99.1 (earnings press release) | C7: monday.com Announces Third Quarter 2022 Results | D7: Q3 2022 | E7: 44879 | F7: https://www.sec.gov/Archives/edgar/data/1845338/000117891322003976/exhibit_99-1.htm | G7: 0001178913-22-003976 | H7: 99.1 | I7: Whole document: highlights, outlook, KPI definitions, financial tables | J7: Earnings release furnished on Form 6-K. Prior-period comparative columns also used for Q1 2021 values, first-time KPI comparatives and restatement review.
A8: ER-2022Q4 | B8: 6-K, Exhibit 99.1 (earnings press release) | C8: monday.com Announces Fourth Quarter and Fiscal Year 2022 Results | D8: Q4 2022 | E8: 44970 | F8: https://www.sec.gov/Archives/edgar/data/1845338/000117891323000506/exhibit_99-1.htm | G8: 0001178913-23-000506 | H8: 99.1 | I8: Whole document: highlights, outlook, KPI definitions, financial tables | J8: Earnings release furnished on Form 6-K. Prior-period comparative columns also used for Q1 2021 values, first-time KPI comparatives and restatement review.
A9: ER-2023Q1 | B9: 6-K, Exhibit 99.1 (earnings press release) | C9: monday.com Announces First Quarter 2023 Results | D9: Q1 2023 | E9: 45061 | F9: https://www.sec.gov/Archives/edgar/data/1845338/000117891323001870/exhibit_99-1.htm | G9: 0001178913-23-001870 | H9: 99.1 | I9: Whole document: highlights, outlook, KPI definitions, financial tables | J9: Earnings release furnished on Form 6-K. Prior-period comparative columns also used for Q1 2021 values, first-time KPI comparatives and restatement review.
A10: ER-2023Q2 | B10: 6-K, Exhibit 99.1 (earnings press release) | C10: monday.com Announces Second Quarter 2023 Results | D10: Q2 2023 | E10: 45152 | F10: https://www.sec.gov/Archives/edgar/data/1845338/000117891323002848/exhibit_99-1.htm | G10: 0001178913-23-002848 | H10: 99.1 | I10: Whole document: highlights, outlook, KPI definitions, financial tables | J10: Earnings release furnished on Form 6-K. Prior-period comparative columns also used for Q1 2021 values, first-time KPI comparatives and restatement review.
A11: ER-2023Q3 | B11: 6-K, Exhibit 99.1 (earnings press release) | C11: monday.com Announces Third Quarter 2023 Results | D11: Q3 2023 | E11: 45243 | F11: https://www.sec.gov/Archives/edgar/data/1845338/000117891323003627/exhibit_99-1.htm | G11: 0001178913-23-003627 | H11: 99.1 | I11: Whole document: highlights, outlook, KPI definitions, financial tables | J11: Earnings release furnished on Form 6-K. Prior-period comparative columns also used for Q1 2021 values, first-time KPI comparatives and restatement review.
A12: ER-2023Q4 | B12: 6-K, Exhibit 99.1 (earnings press release) | C12: monday.com Announces Fourth Quarter and Fiscal Year 2023 Results | D12: Q4 2023 | E12: 45334 | F12: https://www.sec.gov/Archives/edgar/data/1845338/000117891324000445/exhibit_99-1.htm | G12: 0001178913-24-000445 | H12: 99.1 | I12: Whole document: highlights, outlook, KPI definitions, financial tables | J12: Earnings release furnished on Form 6-K. Prior-period comparative columns also used for Q1 2021 values, first-time KPI comparatives and restatement review.
A13: ER-2024Q1 | B13: 6-K, Exhibit 99.1 (earnings press release) | C13: monday.com Announces First Quarter 2024 Results | D13: Q1 2024 | E13: 45427 | F13: https://www.sec.gov/Archives/edgar/data/1845338/000117891324001720/exhibit_99-1.htm | G13: 0001178913-24-001720 | H13: 99.1 | I13: Whole document: highlights, outlook, KPI definitions, financial tables | J13: Earnings release furnished on Form 6-K. Prior-period comparative columns also used for Q1 2021 values, first-time KPI comparatives and restatement review.
... A33: H1MDA-2026 | B33: 6-K, Exhibit 99.3 (interim MD&A) | C33: Management's discussion and analysis for the six months ended June 30, 2026 | D33: 6M 2026 | E33: 46244 | F33: https://www.sec.gov/Archives/edgar/data/1845338/000117891326003971/exhibit_99-3.htm | G33: 0001178913-26-003971 | H33: 99.3 | I33: MD&A | J33: Furnished with the Q2 earnings 6-K.
A34: 6K-20250829-CORR | B34: 6-K (correction of H1 2025 geographic revenue table) | C34: Correction to geographic revenue table in H1 2025 interim financial statements | D34: 6M 2025 | E34: 45898 | F34: https://www.sec.gov/Archives/edgar/data/1845338/000117891325003195/zk2533737.htm | G34: 0001178913-25-003195 | H34: Cover | I34: Whole document
A35: 6K-20250917-BUYBACK | B35: 6-K (Investor Day notice; repurchase authorization) | C35: Investor Day notice and $870 million share repurchase program approval | D35: Sep 2025 | E35: 45917 | F35: https://www.sec.gov/Archives/edgar/data/1845338/000117891325003352/zk2533791.htm | G35: 0001178913-25-003352 | H35: Cover | I35: Whole document
A36: 6K-20260722-RESTR | B36: 6-K (restructuring plan) | C36: Restructuring plan initiated July 22, 2026 | D36: Q3 2026 event | E36: 46225 | F36: https://www.sec.gov/Archives/edgar/data/1845338/000117891326003553/zk2635715.htm | G36: 0001178913-26-003553 | H36: Cover | I36: Whole document
A37: 6K-20250403 | B37: 6-K, Exhibit 99.1 (press release) | C37: Press release dated April 3, 2025 | D37: Apr 2025 | E37: 45750 | F37: https://www.sec.gov/Archives/edgar/data/1845338/000117891325001186/exhibit_99-1.htm | G37: 0001178913-25-001186 | H37: 99.1 | I37: Whole document
A38: 6K-20240826-ARR | B38: 6-K, Exhibit 99.1 (press release) | C38: monday.com Achieves ... $1 Billion in Annual Recurring Revenue | D38: Aug 2024 | E38: 45530 | F38: https://www.sec.gov/Archives/edgar/data/1845338/000117891324002760/exhibit_99-1.htm | G38: 0001178913-24-002760 | H38: 99.1 | I38: Whole document
A39: 6K-20240829 | B39: 6-K (Foundation share resale prospectus supplement) | C39: Prospectus supplement: resale of up to 68,000 shares by monday.com Foundation | D39: Aug 2024 | E39: 45533 | F39: https://www.sec.gov/Archives/edgar/data/1845338/000117891324002901/zk2431932.htm | G39: 0001178913-24-002901 | H39: Cover + Ex. 5.1 | I39: Whole document
A40: 6K-20210902 | B40: 6-K (lock-up notice) | C40: IPO lock-up release notice | D40: Sep 2021 | E40: 44441 | F40: https://www.sec.gov/Archives/edgar/data/1845338/000117891321002884/zk2126530.htm | G40: 0001178913-21-002884 | H40: Cover | I40: Whole document
A41: PXY-2026 | B41: 6-K, Exhibit 99.1 (proxy statement) | C41: 2026 annual general meeting proxy statement | D41: 2026 AGM | E41: 46205 | F41: https://www.sec.gov/Archives/edgar/data/1845338/000117891326003403/exhibit_99-1.htm | G41: 0001178913-26-003403 | H41: 99.1 | I41: Whole document
A42: PXY-2026-SUPP | B42: 6-K, Exhibit 99.1 (proxy supplement) | C42: Supplement to 2026 proxy statement | D42: 2026 AGM | E42: 46220 | F42: https://www.sec.gov/Archives/edgar/data/1845338/000117891326003514/exhibit_99-1.htm | G42: 0001178913-26-003514 | H42: 99.1 | I42: Whole document
A43: AGM-2026 | B43: 6-K (AGM results) | C43: Results of 2026 annual general meeting | D43: 2026 AGM | E43: 46240 | F43: https://www.sec.gov/Archives/edgar/data/1845338/000117891326003915/zk2635889.htm | G43: 0001178913-26-003915 | H43: Cover | I43: Whole document
A44: PXY-2025 | B44: 6-K, Exhibit 99.1 (proxy statement) | C44: 2025 AGM proxy statement | D44: 2025 AGM | E44: 45834 | F44: https://www.sec.gov/Archives/edgar/data/1845338/000117891325002240/exhibit_99-1.htm | G44: 0001178913-25-002240 | H44: 99.1 | I44: Whole document
A45: PXY-2024 | B45: 6-K, Exhibit 99.1 (proxy statement) | C45: 2024 AGM proxy statement | D45: 2024 AGM | E45: 45469 | F45: https://www.sec.gov/Archives/edgar/data/1845338/000117891324002085/exhibit_99-1.htm | G45: 0001178913-24-002085 | H45: 99.1 | I45: Whole document
... A48: PXY-2021 | B48: 6-K, Exhibit 99.1 (proxy statement) | C48: 2021 special meeting proxy statement | D48: 2021 SGM | E48: 44369 | F48: https://www.sec.gov/Archives/edgar/data/1845338/000117891321002122/exhibit_99-1.htm | G48: 0001178913-21-002122 | H48: 99.1 | I48: Whole document
A49: SEC-INDEX | B49: SEC EDGAR submissions index (JSON) | C49: EDGAR filing index for monday.com Ltd. (CIK 0001845338) | D49: All filings | E49: n/a (index retrieved 2026-10-28) | F49: https://data.sec.gov/submissions/CIK0001845338.json | I49: filings.recent | J49: Used only to enumerate 6-K and 20-F filings (latest filing in index before cutoff: 2026-08-10). Not a data source for any value.
A50: IR-WEB | B50: Company investor relations website | C50: ir.monday.com | D50: n/a | E50: n/a | F50: https://ir.monday.com/ | I50: n/a | J50: UNAVAILABLE: direct access returned HTTP 403 (Cloudflare bot challenge, "cf-mitigated: challenge") on 2026-10-28. Not used; no secondary source substituted and no attempt made to bypass the block. Consequence: investor presentations, Investor Day (Sept 17, 2025) materials, webcast transcripts and any IR-only KPI supplements are not in this source book.

Sheet Quarterly_Actuals
A1: Row ID | B1: Reporting Period | C1: Period End | D1: Period Basis | E1: Category | F1: Metric | G1: As Reported | H1: Normalized Value | I1: Normalized Low | J1: Normalized High | K1: Unit | L1: Classification | M1: Source ID | N1: Source Reference (document / table / section) | O1: Formula (if Derived) | P1: Notes
A2: QA-0001 | B2: Q1 2021 | C2: 44286 | D2: Quarterly (3 months) | E2: P&L (GAAP) | F2: Revenue | G2: 58,972 | H2: 58972 | K2: USD thousands | L2: Sourced | M2: ER-2022Q1 | N2: Exhibit 99.1, Condensed Consolidated Statements of Operations; row 'Revenue'; column 'Three months ended March 31, 2021' | P2: Q1 2021 preceded the June 2021 IPO; no Q1 2021 release exists. Value is the prior-year comparative column in the Q1 2022 earnings release.
A3: QA-0002 | B3: Q2 2021 | C3: 44377 | D3: Quarterly (3 months) | E3: P&L (GAAP) | F3: Revenue | G3: 70,615 | H3: 70615 | K3: USD thousands | L3: Sourced | M3: ER-2021Q2 | N3: Exhibit 99.1, Condensed Consolidated Statements of Operations; row 'Revenue'; column 'Three months ended June 30, 2021'
A4: QA-0003 | B4: 6M 2021 | C4: 44377 | D4: Year-to-date (6 months) | E4: P&L (GAAP) | F4: Revenue | G4: 129,587 | H4: 129587 | K4: USD thousands | L4: Sourced | M4: ER-2021Q2 | N4: Exhibit 99.1, Condensed Consolidated Statements of Operations; row 'Revenue'; column 'Six months ended June 30, 2021'
A5: QA-0004 | B5: Q3 2021 | C5: 44469 | D5: Quarterly (3 months) | E5: P&L (GAAP) | F5: Revenue | G5: 83,018 | H5: 83018 | K5: USD thousands | L5: Sourced | M5: ER-2021Q3 | N5: Exhibit 99.1, Condensed Consolidated Statements of Operations; row 'Revenue'; column 'Three months ended September 30, 2021'
A6: QA-0005 | B6: 9M 2021 | C6: 44469 | D6: Year-to-date (9 months) | E6: P&L (GAAP) | F6: Revenue | G6: 212,605 | H6: 212605 | K6: USD thousands | L6: Sourced | M6: ER-2021Q3 | N6: Exhibit 99.1, Condensed Consolidated Statements of Operations; row 'Revenue'; column 'Nine months ended September 30, 2021'
A7: QA-0006 | B7: Q4 2021 | C7: 44561 | D7: Quarterly (3 months) | E7: P&L (GAAP) | F7: Revenue | G7: 95,545 | H7: 95545 | K7: USD thousands | L7: Sourced | M7: ER-2021Q4 | N7: Exhibit 99.1, Condensed Consolidated Statements of Operations; row 'Revenue'; column 'Three months ended December 31, 2021'
A8: QA-0007 | B8: FY 2021 | C8: 44561 | D8: Annual (12 months) | E8: P&L (GAAP) | F8: Revenue | G8: 308,150 | H8: 308150 | K8: USD thousands | L8: Sourced | M8: ER-2021Q4 | N8: Exhibit 99.1, Condensed Consolidated Statements of Operations; row 'Revenue'; column 'Year ended December 31, 2021'
A9: QA-0008 | B9: Q1 2022 | C9: 44651 | D9: Quarterly (3 months) | E9: P&L (GAAP) | F9: Revenue | G9: 108,497 | H9: 108497 | K9: USD thousands | L9: Sourced | M9: ER-2022Q1 | N9: Exhibit 99.1, Condensed Consolidated Statements of Operations; row 'Revenue'; column 'Three months ended March 31, 2022'
A10: QA-0009 | B10: Q2 2022 | C10: 44742 | D10: Quarterly (3 months) | E10: P&L (GAAP) | F10: Revenue | G10: 123,718 | H10: 123718 | K10: USD thousands | L10: Sourced | M10: ER-2022Q2 | N10: Exhibit 99.1, Condensed Consolidated Statements of Operations; row 'Revenue'; column 'Three months ended June 30, 2022'
A11: QA-0010 | B11: 6M 2022 | C11: 44742 | D11: Year-to-date (6 months) | E11: P&L (GAAP) | F11: Revenue | G11: 232,215 | H11: 232215 | K11: USD thousands | L11: Sourced | M11: ER-2022Q2 | N11: Exhibit 99.1, Condensed Consolidated Statements of Operations; row 'Revenue'; column 'Six months ended June 30, 2022'
A12: QA-0011 | B12: Q3 2022 | C12: 44834 | D12: Quarterly (3 months) | E12: P&L (GAAP) | F12: Revenue | G12: 136,893 | H12: 136893 | K12: USD thousands | L12: Sourced | M12: ER-2022Q3 | N12: Exhibit 99.1, Condensed Consolidated Statements of Operations; row 'Revenue'; column 'Three months ended September 30, 2022'
A13: QA-0012 | B13: 9M 2022 | C13: 44834 | D13: Year-to-date (9 months) | E13: P&L (GAAP) | F13: Revenue | G13: 369,108 | H13: 369108 | K13: USD thousands | L13: Sourced | M13: ER-2022Q3 | N13: Exhibit 99.1, Condensed Consolidated Statements of Operations; row 'Revenue'; column 'Nine months ended September 30, 2022'
A14: QA-0013 | B14: Q4 2022 | C14: 44926 | D14: Quarterly (3 months) | E14: P&L (GAAP) | F14: Revenue | G14: 149,921 | H14: 149921 | K14: USD thousands | L14: Sourced | M14: ER-2022Q4 | N14: Exhibit 99.1, Condensed Consolidated Statements of Operations; row 'Revenue'; column 'Three months ended December 31, 2022'
... A39: QA-0038 | B39: 6M 2026 | C39: 46203 | D39: Year-to-date (6 months) | E39: P&L (GAAP) | F39: Revenue | G39: 715,886 | H39: 715886 | K39: USD thousands | L39: Sourced | M39: ER-2026Q2 | N39: Exhibit 99.1, Condensed Consolidated Statements of Operations; row 'Revenue'; column 'Six months ended June 30, 2026'
A40: QA-0039 | B40: Q1 2021 | C40: 44286 | D40: Quarterly (3 months) | E40: P&L (GAAP) | F40: Cost of revenue | G40: 7,924 | H40: 7924 | K40: USD thousands | L40: Sourced | M40: ER-2022Q1 | N40: Exhibit 99.1, Condensed Consolidated Statements of Operations; row 'Cost of revenue'; column 'Three months ended March 31, 2021' | P40: Q1 2021 preceded the June 2021 IPO; no Q1 2021 release exists. Value is the prior-year comparative column in the Q1 2022 earnings release.
A41: QA-0040 | B41: Q2 2021 | C41: 44377 | D41: Quarterly (3 months) | E41: P&L (GAAP) | F41: Cost of revenue | G41: 9,108 | H41: 9108 | K41: USD thousands | L41: Sourced | M41: ER-2021Q2 | N41: Exhibit 99.1, Condensed Consolidated Statements of Operations; row 'Cost of revenue'; column 'Three months ended June 30, 2021'
A42: QA-0041 | B42: 6M 2021 | C42: 44377 | D42: Year-to-date (6 months) | E42: P&L (GAAP) | F42: Cost of revenue | G42: 17,032 | H42: 17032 | K42: USD thousands | L42: Sourced | M42: ER-2021Q2 | N42: Exhibit 99.1, Condensed Consolidated Statements of Operations; row 'Cost of revenue'; column 'Six months ended June 30, 2021'
A43: QA-0042 | B43: Q3 2021 | C43: 44469 | D43: Quarterly (3 months) | E43: P&L (GAAP) | F43: Cost of revenue | G43: 10,213 | H43: 10213 | K43: USD thousands | L43: Sourced | M43: ER-2021Q3 | N43: Exhibit 99.1, Condensed Consolidated Statements of Operations; row 'Cost of revenue'; column 'Three months ended September 30, 2021'
A44: QA-0043 | B44: 9M 2021 | C44: 44469 | D44: Year-to-date (9 months) | E44: P&L (GAAP) | F44: Cost of revenue | G44: 27,245 | H44: 27245 | K44: USD thousands | L44: Sourced | M44: ER-2021Q3 | N44: Exhibit 99.1, Condensed Consolidated Statements of Operations; row 'Cost of revenue'; column 'Nine months ended September 30, 2021'
A45: QA-0044 | B45: Q4 2021 | C45: 44561 | D45: Quarterly (3 months) | E45: P&L (GAAP) | F45: Cost of revenue | G45: 11,768 | H45: 11768 | K45: USD thousands | L45: Sourced | M45: ER-2021Q4 | N45: Exhibit 99.1, Condensed Consolidated Statements of Operations; row 'Cost of revenue'; column 'Three months ended December 31, 2021'
A46: QA-0045 | B46: FY 2021 | C46: 44561 | D46: Annual (12 months) | E46: P&L (GAAP) | F46: Cost of revenue | G46: 39,013 | H46: 39013 | K46: USD thousands | L46: Sourced | M46: ER-2021Q4 | N46: Exhibit 99.1, Condensed Consolidated Statements of Operations; row 'Cost of revenue'; column 'Year ended December 31, 2021'
A47: QA-0046 | B47: Q1 2022 | C47: 44651 | D47: Quarterly (3 months) | E47: P&L (GAAP) | F47: Cost of revenue | G47: 14,609 | H47: 14609 | K47: USD thousands | L47: Sourced | M47: ER-2022Q1 | N47: Exhibit 99.1, Condensed Consolidated Statements of Operations; row 'Cost of revenue'; column 'Three months ended March 31, 2022'
A48: QA-0047 | B48: Q2 2022 | C48: 44742 | D48: Quarterly (3 months) | E48: P&L (GAAP) | F48: Cost of revenue | G48: 16,730 | H48: 16730 | K48: USD thousands | L48: Sourced | M48: ER-2022Q2 | N48: Exhibit 99.1, Condensed Consolidated Statements of Operations; row 'Cost of revenue'; column 'Three months ended June 30, 2022'
A49: QA-0048 | B49: 6M 2022 | C49: 44742 | D49: Year-to-date (6 months) | E49: P&L (GAAP) | F49: Cost of revenue | G49: 31,339 | H49: 31339 | K49: USD thousands | L49: Sourced | M49: ER-2022Q2 | N49: Exhibit 99.1, Condensed Consolidated Statements of Operations; row 'Cost of revenue'; column 'Six months ended June 30, 2022'
A50: QA-0049 | B50: Q3 2022 | C50: 44834 | D50: Quarterly (3 months) | E50: P&L (GAAP) | F50: Cost of revenue | G50: 17,830 | H50: 17830 | K50: USD thousands | L50: Sourced | M50: ER-2022Q3 | N50: Exhibit 99.1, Condensed Consolidated Statements of Operations; row 'Cost of revenue'; column 'Three months ended September 30, 2022'
A51: QA-0050 | B51: 9M 2022 | C51: 44834 | D51: Year-to-date (9 months) | E51: P&L (GAAP) | F51: Cost of revenue | G51: 49,169 | H51: 49169 | K51: USD thousands | L51: Sourced | M51: ER-2022Q3 | N51: Exhibit 99.1, Condensed Consolidated Statements of Operations; row 'Cost of revenue'; column 'Nine months ended September 30, 2022'
A52: QA-0051 | B52: Q4 2022 | C52: 44926 | D52: Quarterly (3 months) | E52: P&L (GAAP) | F52: Cost of revenue | G52: 17,359 | H52: 17359 | K52: USD thousands | L52: Sourced | M52: ER-2022Q4 | N52: Exhibit 99.1, Condensed Consolidated Statements of Operations; row 'Cost of revenue'; column 'Three months ended December 31, 2022'
... A77: QA-0076 | B77: 6M 2026 | C77: 46203 | D77: Year-to-date (6 months) | E77: P&L (GAAP) | F77: Cost of revenue | G77: 80,785 | H77: 80785 | K77: USD thousands | L77: Sourced | M77: ER-2026Q2 | N77: Exhibit 99.1, Condensed Consolidated Statements of Operations; row 'Cost of revenue'; column 'Six months ended June 30, 2026'
A78: QA-0077 | B78: Q1 2021 | C78: 44286 | D78: Quarterly (3 months) | E78: P&L (GAAP) | F78: Gross profit (GAAP) | G78: 51,048 | H78: 51048 | K78: USD thousands | L78: Sourced | M78: ER-2022Q1 | N78: Exhibit 99.1, Condensed Consolidated Statements of Operations; row 'Gross profit'; column 'Three months ended March 31, 2021' | P78: Q1 2021 preceded the June 2021 IPO; no Q1 2021 release exists. Value is the prior-year comparative column in the Q1 2022 earnings release.
A79: QA-0078 | B79: Q2 2021 | C79: 44377 | D79: Quarterly (3 months) | E79: P&L (GAAP) | F79: Gross profit (GAAP) | G79: 61,507 | H79: 61507 | K79: USD thousands | L79: Sourced | M79: ER-2021Q2 | N79: Exhibit 99.1, Condensed Consolidated Statements of Operations; row 'Gross profit'; column 'Three months ended June 30, 2021'
A80: QA-0079 | B80: 6M 2021 | C80: 44377 | D80: Year-to-date (6 months) | E80: P&L (GAAP) | F80: Gross profit (GAAP) | G80: 112,555 | H80: 112555 | K80: USD thousands | L80: Sourced | M80: ER-2021Q2 | N80: Exhibit 99.1, Condensed Consolidated Statements of Operations; row 'Gross profit'; column 'Six months ended June 30, 2021'
A81: QA-0080 | B81: Q3 2021 | C81: 44469 | D81: Quarterly (3 months) | E81: P&L (GAAP) | F81: Gross profit (GAAP) | G81: 72,805 | H81: 72805 | K81: USD thousands | L81: Sourced | M81: ER-2021Q3 | N81: Exhibit 99.1, Condensed Consolidated Statements of Operations; row 'Gross profit'; column 'Three months ended September 30, 2021'
A82: QA-0081 | B82: 9M 2021 | C82: 44469 | D82: Year-to-date (9 months) | E82: P&L (GAAP) | F82: Gross profit (GAAP) | G82: 185,360 | H82: 185360 | K82: USD thousands | L82: Sourced | M82: ER-2021Q3 | N82: Exhibit 99.1, Condensed Consolidated Statements of Operations; row 'Gross profit'; column 'Nine months ended September 30, 2021'
A83: QA-0082 | B83: Q4 2021 | C83: 44561 | D83: Quarterly (3 months) | E83: P&L (GAAP) | F83: Gross profit (GAAP) | G83: 83,777 | H83: 83777 | K83: USD thousands | L83: Sourced | M83: ER-2021Q4 | N83: Exhibit 99.1, Condensed Consolidated Statements of Operations; row 'Gross profit'; column 'Three months ended December 31, 2021'
A84: QA-0083 | B84: FY 2021 | C84: 44561 | D84: Annual (12 months) | E84: P&L (GAAP) | F84: Gross profit (GAAP) | G84: 269,137 | H84: 269137 | K84: USD thousands | L84: Sourced | M84: ER-2021Q4 | N84: Exhibit 99.1, Condensed Consolidated Statements of Operations; row 'Gross profit'; column 'Year ended December 31, 2021'
A85: QA-0084 | B85: Q1 2022 | C85: 44651 | D85: Quarterly (3 months) | E85: P&L (GAAP) | F85: Gross profit (GAAP) | G85: 93,888 | H85: 93888 | K85: USD thousands | L85: Sourced | M85: ER-2022Q1 | N85: Exhibit 99.1, Condensed Consolidated Statements of Operations; row 'Gross profit'; column 'Three months ended March 31, 2022'
A86: QA-0085 | B86: Q2 2022 | C86: 44742 | D86: Quarterly (3 months) | E86: P&L (GAAP) | F86: Gross profit (GAAP) | G86: 106,988 | H86: 106988 | K86: USD thousands | L86: Sourced | M86: ER-2022Q2 | N86: Exhibit 99.1, Condensed Consolidated Statements of Operations; row 'Gross profit'; column 'Three months ended June 30, 2022'
A87: QA-0086 | B87: 6M 2022 | C87: 44742 | D87: Year-to-date (6 months) | E87: P&L (GAAP) | F87: Gross profit (GAAP) | G87: 200,876 | H87: 200876 | K87: USD thousands | L87: Sourced | M87: ER-2022Q2 | N87: Exhibit 99.1, Condensed Consolidated Statements of Operations; row 'Gross profit'; column 'Six months ended June 30, 2022'
A88: QA-0087 | B88: Q3 2022 | C88: 44834 | D88: Quarterly (3 months) | E88: P&L (GAAP) | F88: Gross profit (GAAP) | G88: 119,063 | H88: 119063 | K88: USD thousands | L88: Sourced | M88: ER-2022Q3 | N88: Exhibit 99.1, Condensed Consolidated Statements of Operations; row 'Gross profit'; column 'Three months ended September 30, 2022'
...

Sheet Guidance_History
A1: Row ID | B1: Release Date | C1: Issued With (results period) | D1: Period Covered | E1: Metric | F1: As Reported - Prior Guidance | G1: Prior Low | H1: Prior High | I1: Prior Midpoint | J1: As Reported - New Guidance | K1: New Low | L1: New High | M1: New Midpoint | N1: Midpoint Change | O1: Unit | P1: Management's Stated Reason for Change (only if explicit) | Q1: FX Assumption (as stated) | R1: Classification | S1: Source ID | T1: Source Location | U1: Notes
A2: GH-0001 | B2: 44425 | C2: Q2 2021 | D2: FY 2021 | E2: Non-GAAP operating income (loss) | J2: Non-GAAP operating loss of $93 million to $91 million and negative operating margin of between 33% and 32%. | K2: -93 | L2: -91 | M2: =(K2+L2)/2 -> -92 | O2: USD millions | R2: Low/High: Sourced; Prior columns: links to prior vintage row; Midpoints and change: Derived | S2: ER-2021Q2 | T2: Exhibit 99.1, 'Financial Outlook' - For the full year 2021 | U2: Initial full-year guidance vintage. Guided as an operating LOSS; normalized as negative operating income (low = larger loss).
A3: GH-0002 | B3: 44425 | C3: Q2 2021 | D3: FY 2021 | E3: Revenue | J3: Total revenue of $280 million to $282 million, representing year-over-year growth of 74% to 75%. | K3: 280 | L3: 282 | M3: =(K3+L3)/2 -> 281 | O3: USD millions | R3: Low/High: Sourced; Prior columns: links to prior vintage row; Midpoints and change: Derived | S3: ER-2021Q2 | T3: Exhibit 99.1, 'Financial Outlook' - For the full year 2021 | U3: Initial full-year guidance vintage.
A4: GH-0003 | B4: 44425 | C4: Q2 2021 | D4: Q3 2021 | E4: Non-GAAP operating income (loss) | J4: Non-GAAP operating loss of $26 million to $25 million. | K4: -26 | L4: -25 | M4: =(K4+L4)/2 -> -25.5 | O4: USD millions | R4: Low/High: Sourced; Prior columns: links to prior vintage row; Midpoints and change: Derived | S4: ER-2021Q2 | T4: Exhibit 99.1, 'Financial Outlook' - next-quarter outlook (Q3 2021) | U4: Next-quarter guidance (issued once; no prior vintage for the same quarter). Guided as an operating LOSS; normalized as negative operating income (low = larger loss).
A5: GH-0004 | B5: 44425 | C5: Q2 2021 | D5: Q3 2021 | E5: Revenue | J5: Total revenue of $74 to $75 million, representing year-over-year growth of 74% to 76%. | K5: 74 | L5: 75 | M5: =(K5+L5)/2 -> 74.5 | O5: USD millions | R5: Low/High: Sourced; Prior columns: links to prior vintage row; Midpoints and change: Derived | S5: ER-2021Q2 | T5: Exhibit 99.1, 'Financial Outlook' - next-quarter outlook (Q3 2021) | U5: Next-quarter guidance (issued once; no prior vintage for the same quarter).
A6: GH-0005 | B6: 44510 | C6: Q3 2021 | D6: FY 2021 | E6: Non-GAAP operating income (loss) | F6: =J2 -> Non-GAAP operating loss of $93 million to $91 million and negative operating margin of between 33% and 32%. | G6: =K2 -> -93 | H6: =L2 -> -91 | I6: =M2 -> -92 | J6: Non-GAAP operating loss of $65 million to $64 million and negative operating margin of 22% to 21%. | K6: -65 | L6: -64 | M6: =(K6+L6)/2 -> -64.5 | N6: =M6-I6 -> 27.5 | O6: USD millions | R6: Low/High: Sourced; Prior columns: links to prior vintage row; Midpoints and change: Derived | S6: ER-2021Q3 | T6: Exhibit 99.1, 'Financial Outlook' - For the full year 2021 | U6: Guided as an operating LOSS; normalized as negative operating income (low = larger loss).
A7: GH-0006 | B7: 44510 | C7: Q3 2021 | D7: FY 2021 | E7: Revenue | F7: =J3 -> Total revenue of $280 million to $282 million, representing year-over-year growth of 74% to 75%. | G7: =K3 -> 280 | H7: =L3 -> 282 | I7: =M3 -> 281 | J7: Total revenue of $300 million to $301 million, representing year-over-year growth of 86% to 87%. | K7: 300 | L7: 301 | M7: =(K7+L7)/2 -> 300.5 | N7: =M7-I7 -> 19.5 | O7: USD millions | R7: Low/High: Sourced; Prior columns: links to prior vintage row; Midpoints and change: Derived | S7: ER-2021Q3 | T7: Exhibit 99.1, 'Financial Outlook' - For the full year 2021
A8: GH-0007 | B8: 44510 | C8: Q3 2021 | D8: Q4 2021 | E8: Non-GAAP operating income (loss) | J8: Non-GAAP operating loss of $23 million to $22 million. | K8: -23 | L8: -22 | M8: =(K8+L8)/2 -> -22.5 | O8: USD millions | R8: Low/High: Sourced; Prior columns: links to prior vintage row; Midpoints and change: Derived | S8: ER-2021Q3 | T8: Exhibit 99.1, 'Financial Outlook' - next-quarter outlook (Q4 2021) | U8: Next-quarter guidance (issued once; no prior vintage for the same quarter). Guided as an operating LOSS; normalized as negative operating income (low = larger loss).
A9: GH-0008 | B9: 44510 | C9: Q3 2021 | D9: Q4 2021 | E9: Revenue | J9: Total revenue of $87 to $88 million, representing year-over-year growth of 74% to 75%. | K9: 87 | L9: 88 | M9: =(K9+L9)/2 -> 87.5 | O9: USD millions | R9: Low/High: Sourced; Prior columns: links to prior vintage row; Midpoints and change: Derived | S9: ER-2021Q3 | T9: Exhibit 99.1, 'Financial Outlook' - next-quarter outlook (Q4 2021) | U9: Next-quarter guidance (issued once; no prior vintage for the same quarter).
A10: GH-0009 | B10: 44615 | C10: Q4 2021 | D10: FY 2022 | E10: Non-GAAP operating income (loss) | J10: Non-GAAP operating loss of $147 million to $142 million and negative operating margin of 31% to 30%. | K10: -147 | L10: -142 | M10: =(K10+L10)/2 -> -144.5 | O10: USD millions | R10: Low/High: Sourced; Prior columns: links to prior vintage row; Midpoints and change: Derived | S10: ER-2021Q4 | T10: Exhibit 99.1, 'Financial Outlook' - For the full year 2022 | U10: Initial full-year guidance vintage. Guided as an operating LOSS; normalized as negative operating income (low = larger loss).
A11: GH-0010 | B11: 44615 | C11: Q4 2021 | D11: FY 2022 | E11: Revenue | J11: Total revenue of $470 million to $475 million, representing year-over-year growth of 53% to 54%. | K11: 470 | L11: 475 | M11: =(K11+L11)/2 -> 472.5 | O11: USD millions | R11: Low/High: Sourced; Prior columns: links to prior vintage row; Midpoints and change: Derived | S11: ER-2021Q4 | T11: Exhibit 99.1, 'Financial Outlook' - For the full year 2022 | U11: Initial full-year guidance vintage.
A12: GH-0011 | B12: 44615 | C12: Q4 2021 | D12: Q1 2022 | E12: Non-GAAP operating income (loss) | J12: Non-GAAP operating loss of $47 million to $45 million. | K12: -47 | L12: -45 | M12: =(K12+L12)/2 -> -46 | O12: USD millions | R12: Low/High: Sourced; Prior columns: links to prior vintage row; Midpoints and change: Derived | S12: ER-2021Q4 | T12: Exhibit 99.1, 'Financial Outlook' - next-quarter outlook (Q1 2022) | U12: Next-quarter guidance (issued once; no prior vintage for the same quarter). Guided as an operating LOSS; normalized as negative operating income (low = larger loss).
A13: GH-0012 | B13: 44615 | C13: Q4 2021 | D13: Q1 2022 | E13: Revenue | J13: Total revenue of $100 to $102 million, representing year-over-year growth of 70% to 73%. | K13: 100 | L13: 102 | M13: =(K13+L13)/2 -> 101 | O13: USD millions | R13: Low/High: Sourced; Prior columns: links to prior vintage row; Midpoints and change: Derived | S13: ER-2021Q4 | T13: Exhibit 99.1, 'Financial Outlook' - next-quarter outlook (Q1 2022) | U13: Next-quarter guidance (issued once; no prior vintage for the same quarter).
A14: GH-0013 | B14: 44697 | C14: Q1 2022 | D14: FY 2022 | E14: Non-GAAP operating income (loss) | F14: =J10 -> Non-GAAP operating loss of $147 million to $142 million and negative operating margin of 31% to 30%. | G14: =K10 -> -147 | H14: =L10 -> -142 | I14: =M10 -> -144.5 | J14: Non-GAAP operating loss of $139 million to $135 million and negative operating margin of 28% to 27%. | K14: -139 | L14: -135 | M14: =(K14+L14)/2 -> -137 | N14: =M14-I14 -> 7.5 | O14: USD millions | R14: Low/High: Sourced; Prior columns: links to prior vintage row; Midpoints and change: Derived | S14: ER-2022Q1 | T14: Exhibit 99.1, 'Financial Outlook' - For the full year 2022 | U14: Guided as an operating LOSS; normalized as negative operating income (low = larger loss).
A15: GH-0014 | B15: 44697 | C15: Q1 2022 | D15: FY 2022 | E15: Revenue | F15: =J11 -> Total revenue of $470 million to $475 million, representing year-over-year growth of 53% to 54%. | G15: =K11 -> 470 | H15: =L11 -> 475 | I15: =M11 -> 472.5 | J15: Total revenue of $488 million to $492 million, representing year-over-year growth of 58% to 60%. | K15: 488 | L15: 492 | M15: =(K15+L15)/2 -> 490 | N15: =M15-I15 -> 17.5 | O15: USD millions | R15: Low/High: Sourced; Prior columns: links to prior vintage row; Midpoints and change: Derived | S15: ER-2022Q1 | T15: Exhibit 99.1, 'Financial Outlook' - For the full year 2022
A16: GH-0015 | B16: 44697 | C16: Q1 2022 | D16: Q2 2022 | E16: Non-GAAP operating income (loss) | J16: Non-GAAP operating loss of $35 million to $33 million and negative operating margin of 30% to 28%. | K16: -35 | L16: -33 | M16: =(K16+L16)/2 -> -34 | O16: USD millions | R16: Low/High: Sourced; Prior columns: links to prior vintage row; Midpoints and change: Derived | S16: ER-2022Q1 | T16: Exhibit 99.1, 'Financial Outlook' - next-quarter outlook (Q2 2022) | U16: Next-quarter guidance (issued once; no prior vintage for the same quarter). Guided as an operating LOSS; normalized as negative operating income (low = larger loss).
A17: GH-0016 | B17: 44697 | C17: Q1 2022 | D17: Q2 2022 | E17: Revenue | J17: Total revenue of $117 million to $119 million, representing year-over-year growth of 66% to 69%. | K17: 117 | L17: 119 | M17: =(K17+L17)/2 -> 118 | O17: USD millions | R17: Low/High: Sourced; Prior columns: links to prior vintage row; Midpoints and change: Derived | S17: ER-2022Q1 | T17: Exhibit 99.1, 'Financial Outlook' - next-quarter outlook (Q2 2022) | U17: Next-quarter guidance (issued once; no prior vintage for the same quarter).
A18: GH-0017 | B18: 44781 | C18: Q2 2022 | D18: FY 2022 | E18: Non-GAAP operating income (loss) | F18: =J14 -> Non-GAAP operating loss of $139 million to $135 million and negative operating margin of 28% to 27%. | G18: =K14 -> -139 | H18: =L14 -> -135 | I18: =M14 -> -137 | J18: Non-GAAP operating loss of $112 million to $108 million and negative operating margin of 22% to 21%. | K18: -112 | L18: -108 | M18: =(K18+L18)/2 -> -110 | N18: =M18-I18 -> 27 | O18: USD millions | R18: Low/High: Sourced; Prior columns: links to prior vintage row; Midpoints and change: Derived | S18: ER-2022Q2 | T18: Exhibit 99.1, 'Financial Outlook' - For the full year 2022 | U18: Guided as an operating LOSS; normalized as negative operating income (low = larger loss).
A19: GH-0018 | B19: 44781 | C19: Q2 2022 | D19: FY 2022 | E19: Revenue | F19: =J15 -> Total revenue of $488 million to $492 million, representing year-over-year growth of 58% to 60%. | G19: =K15 -> 488 | H19: =L15 -> 492 | I19: =M15 -> 490 | J19: Total revenue of $498 million to $502 million, representing year-over-year growth of 62% to 63%. | K19: 498 | L19: 502 | M19: =(K19+L19)/2 -> 500 | N19: =M19-I19 -> 10 | O19: USD millions | P19: Given the concerns about the macro economy and the market, we have provided prudent yet achievable forward-looking guidance. It should be noted that we did see some softness in demand in Europe at the end of Q2. And while one month is not enough data to extrapolate a larger trend, we are closely monitoring the demand environment across all areas of our business and will be transparent with our investors about our expectations. | Q19: With the recent strengthening of the US dollar, we now expect FX to negatively impact our full year revenue growth estimates by approximately 300 basis points. | R19: Low/High: Sourced; Prior columns: links to prior vintage row; Midpoints and change: Derived | S19: ER-2022Q2 | T19: Exhibit 99.1, 'Financial Outlook' - For the full year 2022
A20: GH-0019 | B20: 44781 | C20: Q2 2022 | D20: Q3 2022 | E20: Non-GAAP operating income (loss) | J20: Non-GAAP operating loss of $25 million to $24 million and negative operating margin of 19% to 18%. | K20: -25 | L20: -24 | M20: =(K20+L20)/2 -> -24.5 | O20: USD millions | R20: Low/High: Sourced; Prior columns: links to prior vintage row; Midpoints and change: Derived | S20: ER-2022Q2 | T20: Exhibit 99.1, 'Financial Outlook' - next-quarter outlook (Q3 2022) | U20: Next-quarter guidance (issued once; no prior vintage for the same quarter). Guided as an operating LOSS; normalized as negative operating income (low = larger loss).
A21: GH-0020 | B21: 44781 | C21: Q2 2022 | D21: Q3 2022 | E21: Revenue | J21: Total revenue of $130 million to $131 million, representing year-over-year growth of 57% to 58%. | K21: 130 | L21: 131 | M21: =(K21+L21)/2 -> 130.5 | O21: USD millions | R21: Low/High: Sourced; Prior columns: links to prior vintage row; Midpoints and change: Derived | S21: ER-2022Q2 | T21: Exhibit 99.1, 'Financial Outlook' - next-quarter outlook (Q3 2022) | U21: Next-quarter guidance (issued once; no prior vintage for the same quarter).
A22: GH-0021 | B22: 44879 | C22: Q3 2022 | D22: FY 2022 | E22: Non-GAAP operating income (loss) | F22: =J18 -> Non-GAAP operating loss of $112 million to $108 million and negative operating margin of 22% to 21%. | G22: =K18 -> -112 | H22: =L18 -> -108 | I22: =M18 -> -110 | J22: Non-GAAP operating loss of $83 million to $81 million and negative operating margin of approximately 16%. | K22: -83 | L22: -81 | M22: =(K22+L22)/2 -> -82 | N22: =M22-I22 -> 28 | O22: USD millions | R22: Low/High: Sourced; Prior columns: links to prior vintage row; Midpoints and change: Derived | S22: ER-2022Q3 | T22: Exhibit 99.1, 'Financial Outlook' - For the full year 2022 | U22: Guided as an operating LOSS; normalized as negative operating income (low = larger loss).
A23: GH-0022 | B23: 44879 | C23: Q3 2022 | D23: FY 2022 | E23: Revenue | F23: =J19 -> Total revenue of $498 million to $502 million, representing year-over-year growth of 62% to 63%. | G23: =K19 -> 498 | H23: =L19 -> 502 | I23: =M19 -> 500 | J23: Total revenue of $509 million to $511 million, representing year-over-year growth of 65% to 66%. | K23: 509 | L23: 511 | M23: =(K23+L23)/2 -> 510 | N23: =M23-I23 -> 10 | O23: USD millions | Q23: Due to the recent strengthening of the US dollar, monday.com now expects FX to negatively impact our full year revenue growth estimates by approximately 300 basis points. | R23: Low/High: Sourced; Prior columns: links to prior vintage row; Midpoints and change: Derived | S23: ER-2022Q3 | T23: Exhibit 99.1, 'Financial Outlook' - For the full year 2022
A24: GH-0023 | B24: 44879 | C24: Q3 2022 | D24: Q4 2022 | E24: Non-GAAP operating income (loss) | J24: Non-GAAP operating loss of $22 million to $20 million and negative operating margin of 15% to 14%. | K24: -22 | L24: -20 | M24: =(K24+L24)/2 -> -21 | O24: USD millions | R24: Low/High: Sourced; Prior columns: links to prior vintage row; Midpoints and change: Derived | S24: ER-2022Q3 | T24: Exhibit 99.1, 'Financial Outlook' - next-quarter outlook (Q4 2022) | U24: Next-quarter guidance (issued once; no prior vintage for the same quarter). Guided as an operating LOSS; normalized as negative operating income (low = larger loss).
A25: GH-0024 | B25: 44879 | C25: Q3 2022 | D25: Q4 2022 | E25: Revenue | J25: Total revenue of $140 million to $142 million, representing year-over-year growth of 47% to 49%. | K25: 140 | L25: 142 | M25: =(K25+L25)/2 -> 141 | O25: USD millions | R25: Low/High: Sourced; Prior columns: links to prior vintage row; Midpoints and change: Derived | S25: ER-2022Q3 | T25: Exhibit 99.1, 'Financial Outlook' - next-quarter outlook (Q4 2022) | U25: Next-quarter guidance (issued once; no prior vintage for the same quarter).
A26: GH-0025 | B26: 44970 | C26: Q4 2022 | D26: FY 2023 | E26: Non-GAAP operating income (loss) | J26: Non-GAAP operating loss of $36 million to $32 million and negative operating margin of approximately 5%. | K26: -36 | L26: -32 | M26: =(K26+L26)/2 -> -34 | O26: USD millions | R26: Low/High: Sourced; Prior columns: links to prior vintage row; Midpoints and change: Derived | S26: ER-2022Q4 | T26: Exhibit 99.1, 'Financial Outlook' - For the full year 2023 | U26: Initial full-year guidance vintage. Guided as an operating LOSS; normalized as negative operating income (low = larger loss).
A27: GH-0026 | B27: 44970 | C27: Q4 2022 | D27: FY 2023 | E27: Revenue | J27: Total revenue of $688 million to $693 million, representing year-over-year growth of 33% to 34%. | K27: 688 | L27: 693 | M27: =(K27+L27)/2 -> 690.5 | O27: USD millions | R27: Low/High: Sourced; Prior columns: links to prior vintage row; Midpoints and change: Derived | S27: ER-2022Q4 | T27: Exhibit 99.1, 'Financial Outlook' - For the full year 2023 | U27: Initial full-year guidance vintage.
A28: GH-0027 | B28: 44970 | C28: Q4 2022 | D28: Q1 2023 | E28: Non-GAAP operating income (loss) | J28: Non-GAAP operating loss of $19 million to $17 million and negative operating margin of 13% to 12%. | K28: -19 | L28: -17 | M28: =(K28+L28)/2 -> -18 | O28: USD millions | R28: Low/High: Sourced; Prior columns: links to prior vintage row; Midpoints and change: Derived | S28: ER-2022Q4 | T28: Exhibit 99.1, 'Financial Outlook' - next-quarter outlook (Q1 2023) | U28: Next-quarter guidance (issued once; no prior vintage for the same quarter). Guided as an operating LOSS; normalized as negative operating income (low = larger loss).
A29: GH-0028 | B29: 44970 | C29: Q4 2022 | D29: Q1 2023 | E29: Revenue | J29: Total revenue of $154 million to $156 million, representing year-over-year growth of 42% to 44%. | K29: 154 | L29: 156 | M29: =(K29+L29)/2 -> 155 | O29: USD millions | R29: Low/High: Sourced; Prior columns: links to prior vintage row; Midpoints and change: Derived | S29: ER-2022Q4 | T29: Exhibit 99.1, 'Financial Outlook' - next-quarter outlook (Q1 2023) | U29: Next-quarter guidance (issued once; no prior vintage for the same quarter).
A30: GH-0029 | B30: 45061 | C30: Q1 2023 | D30: FY 2023 | E30: Non-GAAP operating income (loss) | F30: =J26 -> Non-GAAP operating loss of $36 million to $32 million and negative operating margin of approximately 5%. | G30: =K26 -> -36 | H30: =L26 -> -32 | I30: =M26 -> -34 | J30: Non-GAAP operating income of $8 million to $12 million and operating margin of approximately 1%. | K30: 8 | L30: 12 | M30: =(K30+L30)/2 -> 10 | N30: =M30-I30 -> 44 | O30: USD millions | R30: Low/High: Sourced; Prior columns: links to prior vintage row; Midpoints and change: Derived | S30: ER-2023Q1 | T30: Exhibit 99.1, 'Financial Outlook' - For the full year 2023
A31: GH-0030 | B31: 45061 | C31: Q1 2023 | D31: FY 2023 | E31: Revenue | F31: =J27 -> Total revenue of $688 million to $693 million, representing year-over-year growth of 33% to 34%. | G31: =K27 -> 688 | H31: =L27 -> 693 | I31: =M27 -> 690.5 | J31: Total revenue of $702 million to $706 million, representing year-over-year growth of 35% to 36%. | K31: 702 | L31: 706 | M31: =(K31+L31)/2 -> 704 | N31: =M31-I31 -> 13.5 | O31: USD millions | R31: Low/High: Sourced; Prior columns: links to prior vintage row; Midpoints and change: Derived | S31: ER-2023Q1 | T31: Exhibit 99.1, 'Financial Outlook' - For the full year 2023
A32: GH-0031 | B32: 45061 | C32: Q1 2023 | D32: Q2 2023 | E32: Non-GAAP operating income (loss) | J32: Non-GAAP operating income of $2 million to $4 million and operating margin of 1% to 2%. | K32: 2 | L32: 4 | M32: =(K32+L32)/2 -> 3 | O32: USD millions | R32: Low/High: Sourced; Prior columns: links to prior vintage row; Midpoints and change: Derived | S32: ER-2023Q1 | T32: Exhibit 99.1, 'Financial Outlook' - next-quarter outlook (Q2 2023) | U32: Next-quarter guidance (issued once; no prior vintage for the same quarter).
A33: GH-0032 | B33: 45061 | C33: Q1 2023 | D33: Q2 2023 | E33: Revenue | J33: Total revenue of $168 million to $170 million, representing year-over-year growth of 36% to 37%. | K33: 168 | L33: 170 | M33: =(K33+L33)/2 -> 169 | O33: USD millions | R33: Low/High: Sourced; Prior columns: links to prior vintage row; Midpoints and change: Derived | S33: ER-2023Q1 | T33: Exhibit 99.1, 'Financial Outlook' - next-quarter outlook (Q2 2023) | U33: Next-quarter guidance (issued once; no prior vintage for the same quarter).
A34: GH-0033 | B34: 45152 | C34: Q2 2023 | D34: FY 2023 | E34: Non-GAAP operating income (loss) | F34: =J30 -> Non-GAAP operating income of $8 million to $12 million and operating margin of approximately 1%. | G34: =K30 -> 8 | H34: =L30 -> 12 | I34: =M30 -> 10 | J34: Non-GAAP operating income of $24 million to $28 million and operating margin of 3% to 4%. | K34: 24 | L34: 28 | M34: =(K34+L34)/2 -> 26 | N34: =M34-I34 -> 16 | O34: USD millions | R34: Low/High: Sourced; Prior columns: links to prior vintage row; Midpoints and change: Derived | S34: ER-2023Q2 | T34: Exhibit 99.1, 'Financial Outlook' - For the full year 2023
A35: GH-0034 | B35: 45152 | C35: Q2 2023 | D35: FY 2023 | E35: Revenue | F35: =J31 -> Total revenue of $702 million to $706 million, representing year-over-year growth of 35% to 36%. | G35: =K31 -> 702 | H35: =L31 -> 706 | I35: =M31 -> 704 | J35: Total revenue of $713 million to $717 million, representing year-over-year growth of 37% to 38%. | K35: 713 | L35: 717 | M35: =(K35+L35)/2 -> 715 | N35: =M35-I35 -> 11 | O35: USD millions | R35: Low/High: Sourced; Prior columns: links to prior vintage row; Midpoints and change: Derived | S35: ER-2023Q2 | T35: Exhibit 99.1, 'Financial Outlook' - For the full year 2023
A36: GH-0035 | B36: 45152 | C36: Q2 2023 | D36: Q3 2023 | E36: Non-GAAP operating income (loss) | J36: Non-GAAP operating income of $4 million to $6 million and operating margin of 2% to 3%. | K36: 4 | L36: 6 | M36: =(K36+L36)/2 -> 5 | O36: USD millions | R36: Low/High: Sourced; Prior columns: links to prior vintage row; Midpoints and change: Derived | S36: ER-2023Q2 | T36: Exhibit 99.1, 'Financial Outlook' - next-quarter outlook (Q3 2023) | U36: Next-quarter guidance (issued once; no prior vintage for the same quarter).
A37: GH-0036 | B37: 45152 | C37: Q2 2023 | D37: Q3 2023 | E37: Revenue | J37: Total revenue of $181 million to $183 million, representing year-over-year growth of 32% to 34%. | K37: 181 | L37: 183 | M37: =(K37+L37)/2 -> 182 | O37: USD millions | R37: Low/High: Sourced; Prior columns: links to prior vintage row; Midpoints and change: Derived | S37: ER-2023Q2 | T37: Exhibit 99.1, 'Financial Outlook' - next-quarter outlook (Q3 2023) | U37: Next-quarter guidance (issued once; no prior vintage for the same quarter).
A38: GH-0037 | B38: 45243 | C38: Q3 2023 | D38: FY 2023 | E38: Non-GAAP operating income (loss) | F38: =J34 -> Non-GAAP operating income of $24 million to $28 million and operating margin of 3% to 4%. | G38: =K34 -> 24 | H38: =L34 -> 28 | I38: =M34 -> 26 | J38: Non-GAAP operating income of $47 million to $49 million and operating margin of approximately 7%. | K38: 47 | L38: 49 | M38: =(K38+L38)/2 -> 48 | N38: =M38-I38 -> 22 | O38: USD millions | R38: Low/High: Sourced; Prior columns: links to prior vintage row; Midpoints and change: Derived | S38: ER-2023Q3 | T38: Exhibit 99.1, 'Financial Outlook' - For the full year 2023
A39: GH-0038 | B39: 45243 | C39: Q3 2023 | D39: FY 2023 | E39: Revenue | F39: =J35 -> Total revenue of $713 million to $717 million, representing year-over-year growth of 37% to 38%. | G39: =K35 -> 713 | H39: =L35 -> 717 | I39: =M35 -> 715 | J39: Total revenue of $723 million to $725 million, representing year-over-year growth of 39% to 40%. | K39: 723 | L39: 725 | M39: =(K39+L39)/2 -> 724 | N39: =M39-I39 -> 9 | O39: USD millions | R39: Low/High: Sourced; Prior columns: links to prior vintage row; Midpoints and change: Derived | S39: ER-2023Q3 | T39: Exhibit 99.1, 'Financial Outlook' - For the full year 2023
A40: GH-0039 | B40: 45243 | C40: Q3 2023 | D40: Q4 2023 | E40: Non-GAAP operating income (loss) | J40: Non-GAAP operating income of $7 million to $9 million and operating margin of 4% to 5%. | K40: 7 | L40: 9 | M40: =(K40+L40)/2 -> 8 | O40: USD millions | R40: Low/High: Sourced; Prior columns: links to prior vintage row; Midpoints and change: Derived | S40: ER-2023Q3 | T40: Exhibit 99.1, 'Financial Outlook' - next-quarter outlook (Q4 2023) | U40: Next-quarter guidance (issued once; no prior vintage for the same quarter).
...

Sheet Annual
A1: Row ID | B1: Period / Date | C1: Period Basis | D1: Category | E1: Metric | F1: As Reported | G1: Normalized Value | H1: Unit | I1: Classification | J1: Source ID | K1: Source Location | L1: Formula (if Derived) | M1: Notes
A2: AN-0001 | B2: FY 2021 | C2: FY | D2: audited_statements | E2: Revenue (audited, 20-F) | F2: 308,150 | G2: 308150 | H2: USD thousands | I2: Sourced | J2: 20F-FY2021 | K2: Form 20-F FY2021, Item 18 - Consolidated Statements of Operations, row "Revenue", column year ended December 31, 2021 | M2: Used for release-vs-audited cross-checks.
A3: AN-0002 | B3: FY 2021 | C3: FY | D3: audited_statements | E3: Total operating expenses (audited, 20-F) | F3: 395,262 | G3: 395262 | H3: USD thousands | I3: Sourced | J3: 20F-FY2021 | K3: Form 20-F FY2021, Item 18 - Consolidated Statements of Operations, row "Total operating expenses", column year ended December 31, 2021 | M3: Used for release-vs-audited cross-checks.
A4: AN-0003 | B4: FY 2021 | C4: FY | D4: audited_statements | E4: Operating income (loss) (audited, 20-F) | F4: (126,125) | G4: -126125 | H4: USD thousands | I4: Sourced | J4: 20F-FY2021 | K4: Form 20-F FY2021, Item 18 - Consolidated Statements of Operations, row "Operating loss", column year ended December 31, 2021 | M4: Used for release-vs-audited cross-checks.
